Workbook

Sheet DASHBOARD
A1: Date | B1: TC Réceptionnés | C1: TC Sortis | D1: Total Mouvements | F1: TC Sortis VIDE
A2: 46266 | B2: ='01-09'!H1 -> 1 | C2: ='01-09'!H2 -> 3 | D2: =SUM(B2:C2) -> 4
A3: 46267 | B3: ='02-09'!H1 -> 2 | C3: ='02-09'!H2 -> 2 | D3: =SUM(B3:C3) -> 4
A4: 46268 | B4: ='03-09'!H1 -> 2 | C4: ='03-09'!H2 -> 3 | D4: =SUM(B4:C4) -> 5
A5: 46271 | B5: ='06-09'!H1 -> 1 | C5: ='06-09'!H2 -> 0 | D5: =SUM(B5:C5) -> 1
A6: 46272 | B6: ='07-09'!H1 -> 1 | C6: ='07-09'!H2 -> 7 | D6: =SUM(B6:C6) -> 8
A7: 46274 | B7: ='09-09'!H1 -> 11 | C7: ='09-09'!H2 -> 0 | D7: =SUM(B7:C7) -> 11
A8: 46275 | B8: ='10-09'!H1 -> 7 | C8: ='10-09'!H2 -> 1 | D8: =SUM(B8:C8) -> 8
A9: 46278 | B9: ='13-09'!H1 -> 0 | C9: ='13-09'!H2 -> 2 | D9: =SUM(B9:C9) -> 2
A10: 46279 | B10: ='14-09'!H1 -> 1 | C10: ='14-09'!H2 -> 0 | D10: =SUM(B10:C10) -> 1
A11: 46280 | B11: ='15-09'!H1 -> 4 | C11: ='15-09'!H2 -> 0 | D11: =SUM(B11:C11) -> 4
A12: 46281 | B12: ='16-09'!H1 -> 0 | C12: ='16-09'!H2 -> 12 | D12: =SUM(B12:C12) -> 12
A13: 46282 | B13: ='17-09'!H1 -> 0 | C13: ='17-09'!H2 -> 8 | D13: =SUM(B13:C13) -> 8
A14: 46285 | B14: ='20-09'!H1 -> 0 | C14: ='20-09'!H2 -> 2 | D14: =SUM(B14:C14) -> 2
A15: 46286 | B15: ='21-09'!H1 -> 0 | C15: ='21-09'!H2 -> 4 | D15: =SUM(B15:C15) -> 4
A16: 46287 | B16: ='22-09'!H1 -> 0 | C16: ='22-09'!H2 -> 8 | D16: =SUM(B16:C16) -> 8
A17: 46288 | B17: ='23-09'!H1 -> 0 | C17: ='23-09'!H2 -> 1 | D17: =SUM(B17:C17) -> 1
A18: 46289 | B18: ='24-09'!H1 -> 0 | C18: ='24-09'!H2 -> 1 | D18: =SUM(B18:C18) -> 1
A19: 46291 | B19: ='26-09'!H1 -> 9 | C19: ='26-09'!H2 -> 0 | D19: =SUM(B19:C19) -> 9
A20: 46292 | B20: ='27-09'!H1 -> 11 | C20: ='27-09'!H2 -> 2 | D20: =SUM(B20:C20) -> 13
A21: 46293 | B21: ='28-09'!H1 -> 2 | C21: ='28-09'!H2 -> 0 | D21: =SUM(B21:C21) -> 2
A22: 46294 | B22: ='29-09'!H1 -> 0 | C22: ='29-09'!H2 -> 6 | D22: =SUM(B22:C22) -> 6
A23: 46295 | B23: ='30-09'!H1 -> 0 | C23: ='30-09'!H2 -> 2 | D23: =SUM(B23:C23) -> 2
A24: Total | B24: =SUM(B2:B23) -> 52 | C24: =SUM(C2:C23) -> 64 | D24: =SUM(D2:D19) -> 93

Sheet 01-09
H1: =COUNTIF(C8:C15,"<>") -> 1 | I1: TC
F2: =COUNTIFS(B20:B29,"<>",C20:C29,"VH") -> 7 | G2: VH | H2: =COUNTA(C20:C29)-F2 -> 3 | I2: TC | J2: =COUNTIF(E20:E29,"VIDE") -> 0
A3: FICHE DE MOUVEMENT
B5: RECEPTION | G5: 46266
A7: N° | B7: N° CRN | C7: Date R | D7: N° Conteneur | E7: N° Scellé | F7: Vol
A8: 1 | B8: 0723ICS0013 | C8: 1092026 | D8: CAIU634538 /3 | E8: J1803692 | F8: 20
A9: 2
A10: 3
A11: 4
A12: 5
A13: 6
A14: 7
A15: 8
B17: SORTIE
A19: N° | B19: Date S | C19: IMM | D19: N° Conteneur | E19: N° Scellé | F19: Vol
A20: 1 | B20: 1092026 | C20: 000204-598-31 | D20: ECMU512820/2 | E20: 3579 | F20: 40
A21: 2 | B21: 1092026 | C21: 00327-510-31 | D21: TRLU948903 /4 | E21: 3571 | F21: 40
A22: 3 | B22: 1092026 | C22: VH | D22: LSJ--SZ782970 | E22: ROWEI I5 | F22: VH
A23: 4 | B23: 1092026 | C23: VH | D23: LSJ--SZ782961 | E23: ROWEI I5 | F23: VH
A24: 5 | B24: 1092026 | C24: VH | D24: LSJ--SZ783783 | E24: ROWEI I5 | F24: VH
A25: 6 | B25: 1092026 | C25: VH | D25: LSJ--SZ754980 | E25: ROWEI I5 | F25: VH
A26: 7 | B26: 1092026 | C26: VH | D26: LSJ--SZ754107 | E26: ROWEI I5 | F26: VH
A27: 8 | B27: 1092026 | C27: VH | D27: LSJ--SZ754982 | E27: ROWEI I5 | F27: VH
A28: 9 | B28: 1092026 | C28: VH | D28: LSJ--SZ754109 | E28: ROWEI I5 | F28: VH
A29: 10 | B29: 1092026 | C29: 0073-512-31 | D29: TCLU331996 /2 | E29: 3572 | F29: 40
A30: 11
B32: VISITE
A34: N° | B34: Date V | C34: N° Conteneur | D34: AN° Scellé | E34: NO° Scellé | F34: Vol
A35: 1
A36: 2
A37: 3
A38: 4
A39: 5
A40: 6
A41: 7

Sheet 02-09
H1: =COUNTIF(C8:C15,"<>") -> 2 | I1: TC
F2: =COUNTIFS(B20:B29,"<>",C20:C29,"VH") -> 0 | G2: VH | H2: =COUNTA(C20:C29)-F2 -> 2 | I2: TC | J2: =COUNTIF(E20:E29,"VIDE") -> 2
A3: FICHE DE MOUVEMENT
B5: RECEPTION | G5: 46267
A7: N° | B7: N° CRN | C7: Date R | D7: N° Conteneur | E7: N° Scellé | F7: Vol
A8: 1 | B8: 0157ICS0016 | C8: 2092026 | D8: TGBU749046 /1 | E8: FX48662628 | F8: 40
A9: 2 | B9: 0157ICS0083 | C9: 2092026 | D9: FDCU031798 /9 | E9: FJ27558901 | F9: 40
A10: 3
A11: 4
A12: 5
A13: 6
A14: 7
A15: 8
B17: SORTIE
A19: N° | B19: Date S | C19: IMM | D19: N° Conteneur | E19: N° Scellé | F19: Vol
A20: 1 | B20: 2092026 | C20: 02177-588-31 | D20: TIIU811908 /0 | E20: VIDE | F20: 40
A21: 2 | B21: 2092026 | C21: 02177-588-31 | D21: TIIU811819 /1 | E21: VIDE | F21: 40
A22: 3
A23: 4
A24: 5
A25: 6
A26: 7
A27: 8
A28: 9
A29: 10
A30: 11
B32: VISITE
A34: N° | B34: Date V | C34: N° Conteneur | D34: AN° Scellé | E34: NO° Scellé | F34: Vol
A35: 1 | B35: 2092026 | C35: DRYU939251 /7 | D35: LG00557484 | E35: 3575 | F35: 40
A36: 2 | B36: 2092026 | C36: FDCU009891 /5 | D36: LG00557480 | E36: 3576 | F36: 40
A37: 3
A38: 4
A39: 5
A40: 6
A41: 7

Sheet 03-09
H1: =COUNTIF(C8:C15,"<>") -> 2 | I1: TC
F2: =COUNTIFS(B20:B29,"<>",C20:C29,"VH") -> 0 | G2: VH | H2: =COUNTA(C20:C29)-F2 -> 3 | I2: TC | J2: =COUNTIF(E20:E29,"VIDE") -> 0
A3: FICHE DE MOUVEMENT
B5: RECEPTION | G5: 46268
A7: N° | B7: N° CRN | C7: Date R | D7: N° Conteneur | E7: N° Scellé | F7: Vol
A8: 1 | B8: 0156ICS0112 | C8: 3092026 | D8: FBIU026728 /0 | E8: FX48618480 | F8: 20
A9: 2 | B9: 0156ICS0112 | C9: 3092026 | D9: MSMU769241 /6 | E9: FX48648827 | F9: 40
A10: 3
A11: 4
A12: 5
A13: 6
A14: 7
A15: 8
B17: SORTIE
A19: N° | B19: Date S | C19: IMM | D19: N° Conteneur | E19: N° Scellé | F19: Vol
A20: 1 | B20: 3092026 | C20: 00563-510-31 | D20: MSMU924819 /1 | E20: 3578 | F20: 45
A21: 2 | B21: 3092026 | C21: 02197-585-31 | D21: CAIU873171 /8 | E21: 3573 | F21: 40
A22: 3 | B22: 3092026 | C22: 02148-588-31 | D22: MEDU733219 /1 | E22: 3574 | F22: 40
A23: 4
A24: 5
A25: 6
A26: 7
A27: 8
A28: 9
A29: 10
A30: 11
B32: VISITE
A34: N° | B34: Date V | C34: N° Conteneur | D34: AN° Scellé | E34: NO° Scellé | F34: Vol
A35: 1
A36: 2
A37: 3
A38: 4
A39: 5
A40: 6
A41: 7

Sheet 06-09
H1: =COUNTIF(C8:C15,"<>") -> 1 | I1: TC
F2: =COUNTIFS(B20:B29,"<>",C20:C29,"VH") -> 0 | G2: VH | H2: =COUNTA(C20:C29)-F2 -> 0 | I2: TC | J2: =COUNTIF(E20:E29,"VIDE") -> 0
A3: FICHE DE MOUVEMENT
B5: RECEPTION | G5: 46271
A7: N° | B7: N° CRN | C7: Date R | D7: N° Conteneur | E7: N° Scellé | F7: Vol
A8: 1 | B8: 0754ICS0033 | C8: 6092026 | D8: TIIU809713 /9 | E8: M1726190 | F8: 40
A9: 2 | B9: 0754ICS0069 | D9: DRYU455945 /3 | E9: ANNULL | F9: 45
A10: 3
A11: 4
A12: 5
A13: 6
A14: 7
A15: 8
B17: SORTIE
A19: N° | B19: Date S | C19: IMM | D19: N° Conteneur | E19: N° Scellé | F19: Vol
A20: 1
A21: 2
A22: 3
A23: 4
A24: 5
A25: 6
A26: 7
A27: 8
A28: 9
A29: 10
A30: 11
B32: VISITE
A34: N° | B34: Date V | C34: N° Conteneur | D34: AN° Scellé | E34: NO° Scellé | F34: Vol
A35: 1
A36: 2
A37: 3
A38: 4
A39: 5
A40: 6
A41: 7

Sheet 07-09
H1: =COUNTIF(C8:C15,"<>") -> 1 | I1: TC
F2: =COUNTIFS(B20:B29,"<>",C20:C29,"VH") -> 0 | G2: VH | H2: =COUNTA(C20:C29)-F2 -> 7 | I2: TC | J2: =COUNTIF(E20:E29,"VIDE") -> 0
A3: FICHE DE MOUVEMENT
B5: RECEPTION | G5: 46272
A7: N° | B7: N° CRN | C7: Date R | D7: N° Conteneur | E7: N° Scellé | F7: Vol
A8: 1 | B8: 0754ICS0106 | C8: 7092026 | D8: HGTU261674 /4 | E8: 184912 | F8: 20 | G8: TANK
A9: 2
A10: 3
A11: 4
A12: 5
A13: 6
A14: 7
A15: 8
B17: SORTIE
A19: N° | B19: Date S | C19: IMM | D19: N° Conteneur | E19: N° Scellé | F19: Vol
A20: 1 | B20: 7092026 | C20: 006533-508-31 | D20: MEDU744845 /3 | E20: 3994 | F20: 40
A21: 2 | B21: 7092026 | C21: 00121-517-31 | D21: CMAU225333 /7 | E21: 00168 | F21: 20
A22: 3 | B22: 7092026 | C22: 00124-517-31 | D22: CMAU265891 /0 | E22: 00183 | F22: 20
A23: 4 | B23: 7092026 | C23: 00121-517-31 | D23: CMAU326542 /0 | E23: 001577 | F23: 20
A24: 5 | B24: 7092026 | C24: 00121-517-31 | D24: SEKU160562 /2 | E24: 00163 | F24: 20
A25: 6 | B25: 7092026 | C25: 00124-517-31 | D25: TCLU734251 /2 | E25: 005369 | F25: 20
A26: 7 | B26: 7092026 | C26: 00121-517-31 | D26: TLLU313561 /8 | E26: 005370 | F26: 20
A27: 8
A28: 9
A29: 10
A30: 11
B32: VISITE
A34: N° | B34: Date V | C34: N° Conteneur | D34: AN° Scellé | E34: NO° Scellé | F34: Vol
A35: 1
A36: 2
A37: 3
A38: 4
A39: 5
A40: 6
A41: 7

Sheet 08-09
H1: =COUNTIF(C8:C15,"<>") -> 0 | I1: TC
F2: =COUNTIFS(B20:B29,"<>",C20:C29,"VH") -> 0 | G2: VH | H2: =COUNTA(C20:C29)-F2 -> 0 | I2: TC | J2: =COUNTIF(E20:E29,"VIDE") -> 0
A3: FICHE DE MOUVEMENT
B5: RECEPTION | G5: 46273
A7: N° | B7: N° CRN | C7: Date R | D7: N° Conteneur | E7: N° Scellé | F7: Vol
A8: 1
A9: 2
A10: 3
A11: 4
A12: 5
A13: 6
A14: 7
A15: 8
B17: SORTIE
A19: N° | B19: Date S | C19: IMM | D19: N° Conteneur | E19: N° Scellé | F19: Vol
A20: 1
A21: 2
A22: 3
A23: 4
A24: 5
A25: 6
A26: 7
A27: 8
A28: 9
A29: 10
A30: 11
B32: VISITE
A34: N° | B34: Date V | C34: N° Conteneur | D34: AN° Scellé | E34: NO° Scellé | F34: Vol
A35: 1 | B35: 9092026 | C35: CMAU995757 /7 | D35: M2002559 | E35: 3577 | F35: 40
A36: 2
A37: 3
A38: 4
A39: 5
A40: 6
A41: 7

Sheet 09-09
H1: =COUNTIF(C8:C24,"<>") -> 11 | I1: TC
F2: =COUNTIFS(B29:B30,"<>",C29:C30,"VH") -> 0 | G2: VH | H2: =COUNTA(C29:C30)-F2 -> 0 | I2: TC | J2: =COUNTIF(E29:E30,"VIDE") -> 0
A3: FICHE DE MOUVEMENT
B5: RECEPTION | G5: 46274
A7: N° | B7: N° CRN | C7: Date R | D7: N° Conteneur | E7: N° Scellé | F7: Vol | G7: Date ACC
A8: 1 | B8: 0765ICS0037 | C8: 9092026 | D8: ECMU753339 /6 | E8: J1979281 | F8: 40
A9: 2 | B9: 0083ICS0038 | C9: 9092026 | D9: MRSU491361 /6 | E9: CN6436798 | F9: 40
A10: 3 | B10: 0083ICS0014 | C10: 9092026 | D10: GCXU573668 /2 | E10: CN6536328 | F10: 40
A11: 4 | B11: 0765ICS0233 | C11: 9092026 | E11: M9168709 | F11: 45 | G11: 46262
A12: 5 | B12: 0765ICS0116 | C12: 9092026 | D12: ECMU814116 /8 | E12: J0695804 | F12: 45
A13: 6 | B13: 0083ICS0144 | D13: TGHU805347 /3 | E13: 313157 | F13: 40
A14: 7 | B14: 0083ICS0079 | C14: 9092026 | D14: MRSU215858 /4 | E14: CN8343648 | F14: 40
A15: 8 | B15: 0671ICS0026 | D15: HDMU321504 /6 | E15: 25H1013125 | F15: 20
A16: 9 | D16: HDMU341436 /7 | E16: 25H1041732 | F16: 40
A17: 10 | D17: HDMU342017 /0 | E17: 25H1175272 | F17: 40
A18: 11 | D18: HDMU342266 /0 | E18: 25H1175275 | F18: 40
A19: 12 | C19: 9092026 | D19: KOCU430655 /1 | E19: 26H0234922 | F19: 45
A20: 13 | C20: 9092026 | D20: TIIU600821 /4 | E20: 26H0236033 | F20: 40
A21: 14 | B21: 0159ICS0027 | C21: 9092026 | D21: FFAU811399 /0 | E21: 18233786 | F21: 40
A22: 15 | B22: 0159ICS0010 | C22: 9092026 | D22: CSNU688630 /2 | E22: CX185022 | F22: 40
A23: 16 | B23: 0159ICS0008 | C23: 9092026 | D23: ARKU855448 /4 | E23: 239388 | F23: 40
A24: 17 | B24: 0159ICS0007 | D24: ARKU150130 /6 | E24: 1441385 | F24: 20
B26: SORTIE
A28: N° | B28: Date S | C28: IMM | D28: N° Conteneur | E28: N° Scellé | F28: Vol
A29: 1
A30: 2
B32: VISITE
A34: N° | B34: Date V | C34: N° Conteneur | D34: AN° Scellé | E34: NO° Scellé | F34: Vol
A35: 1 | B35: 9092026 | C35: CMAU995757 /7 | D35: M2002559 | E35: 3577 | F35: 40
A36: 2
A37: 3
A38: 4
A39: 5
A40: 6
A41: 7

Sheet 10-09
H1: =COUNTIF(C8:C17,"<>") -> 7 | I1: TC
F2: =COUNTIFS(B22:B31,"<>",C22:C31,"VH") -> 0 | G2: VH | H2: =COUNTA(C22:C31)-F2 -> 1 | I2: TC | J2: =COUNTIF(E22:E31,"VIDE") -> 0
A3: FICHE DE MOUVEMENT
B5: RECEPTION | G5: 46275
A7: N° | B7: N° CRN | C7: Date R | D7: N° Conteneur | E7: N° Scellé | F7: Vol | G7: Date ACC
A8: 1 | B8: 0159ICS0007 | C8: 10092026 | D8: ARKU150130 /6 | E8: 1441385 | F8: 20 | G8: OPT
A9: 2 | B9: 0683ICS0020 | C9: 10092026 | D9: HMMU433444 /9 | E9: 26H0108168 | F9: 40
A10: 3 | C10: 10092026 | D10: SEGU585325 /8 | E10: 26H0108169 | F10: 40
A11: 4 | B11: 0671ICS0026 | C11: 10092026 | D11: HDMU321504 /6 | E11: 25H1013125 | F11: 20 | G11: OPT
A12: 5 | C12: 10092026 | D12: HDMU341436 /7 | E12: 25H1041732 | F12: 40 | G12: OPT
A13: 6 | C13: 10092026 | D13: HDMU342017 /0 | E13: 25H1175272 | F13: 40 | G13: OPT
A14: 7 | C14: 10092026 | D14: HDMU342266 /0 | E14: 25H1175275 | F14: 40 | G14: OPT
A17: 8
B19: SORTIE
A21: N° | B21: Date S | C21: IMM | D21: N° Conteneur | E21: N° Scellé | F21: Vol
A22: 1 | B22: 10092026 | C22: 00017-511-31 | D22: CMAU995757 /7 | E22: 3577 | F22: 40
A23: 2
A24: 3
A25: 4
A26: 5
A27: 6
A28: 7
A29: 8
A30: 9
A31: 10
A32: 11
B34: VISITE
A36: N° | B36: Date V | C36: N° Conteneur | D36: AN° Scellé | E36: NO° Scellé | F36: Vol
A37: 1 | B37: 10092026 | C37: MEDU760577 /9 | D37: MA526075 | E37: 3552 | F37: 40
A38: 2 | B38: 10092026 | C38: MSDU787252 /0 | D38: MA526074 | E38: 3551 | F38: 40
A39: 3
A40: 4
A41: 5
A42: 6
A43: 7

Sheet 13-09
H1: =COUNTIF(C8:C17,"<>") -> 0 | I1: TC
F2: =COUNTIFS(B22:B31,"<>",C22:C31,"VH") -> 0 | G2: VH | H2: =COUNTA(C22:C31)-F2 -> 2 | I2: TC | J2: =COUNTIF(E22:E31,"VIDE") -> 0
A3: FICHE DE MOUVEMENT
B5: RECEPTION | G5: 46278
A7: N° | B7: N° CRN | C7: Date R | D7: N° Conteneur | E7: N° Scellé | F7: Vol
A8: 1
A9: 2
A10: 3
A11: 4
A12: 5
A13: 6
A14: 7
A17: 8
B19: SORTIE
A21: N° | B21: Date S | C21: IMM | D21: N° Conteneur | E21: N° Scellé | F21: Vol
A22: 1 | B22: 13092026 | C22: 00183-524-31 | D22: DRYU939251 /7 | E22: 3575 | F22: 40
A23: 2 | B23: 13092026 | C23: 00426-510-31 | D23: FDCU009891 /5 | E23: 3576 | F23: 40
A24: 3
A25: 4
A26: 5
A27: 6
A28: 7
A29: 8
A30: 9
A31: 10
A32: 11
B34: VISITE
A36: N° | B36: Date V | C36: N° Conteneur | D36: AN° Scellé | E36: NO° Scellé | F36: Vol
A37: 1 | B37: 13092026 | C37: BMOU213576 /9 | D37: 2134430 | E37: 3554 | F37: 20
A38: 2 | B38: 13092026 | C38: CXSU114000 /6 | D38: 0 | E38: 0 | F38: FLAT
A39: 3 | B39: 13092026 | C39: TCLU600602 /5 | D39: 0 | E39: 0 | F39: FLAT
A40: 4
A41: 5
A42: 6
A43: 7

Sheet 14-09
H1: =COUNTIF(C8:C17,"<>") -> 1 | I1: TC
F2: =COUNTIFS(B22:B31,"<>",C22:C31,"VH") -> 0 | G2: VH | H2: =COUNTA(C22:C31)-F2 -> 0 | I2: TC | J2: =COUNTIF(E22:E31,"VIDE") -> 0
A3: FICHE DE MOUVEMENT
B5: RECEPTION | G5: 46279
A7: N° | B7: N° CRN | C7: Date R | D7: N° Conteneur | E7: N° Scellé | F7: Vol
A8: 1 | B8: 0083ICS0144 | C8: 14092026 | D8: TGHU805347 /3 | E8: 313157 | F8: 40
A9: 2
A10: 3
A11: 4
A12: 5
A13: 6
A14: 7
A17: 8
B19: SORTIE
A21: N° | B21: Date S | C21: IMM | D21: N° Conteneur | E21: N° Scellé | F21: Vol
A22: 1 | B22: 13092026 | D22: MEDU760577 /9 | E22: 3552 | F22: 40
A23: 2 | B23: 13092026 | D23: MSDU787252 /0 | E23: 3551 | F23: 40
A24: 3
A25: 4
A26: 5
A27: 6
A28: 7
A29: 8
A30: 9
A31: 10
A32: 11
B34: VISITE
A36: N° | B36: Date V | C36: N° Conteneur | D36: AN° Scellé | E36: NO° Scellé | F36: Vol
A37: 1
A38: 2
A39: 3
A40: 4
A41: 5
A42: 6
A43: 7

Sheet 15-09
H1: =COUNTIF(C8:C17,"<>") -> 4 | I1: TC
F2: =COUNTIFS(B22:B31,"<>",C22:C31,"VH") -> 0 | G2: VH | H2: =COUNTA(C22:C31)-F2 -> 0 | I2: TC | J2: =COUNTIF(E22:E31,"VIDE") -> 0
A3: FICHE DE MOUVEMENT
B5: RECEPTION | G5: 46280
A7: N° | B7: N° CRN | C7: Date R | D7: N° Conteneur | E7: N° Scellé | F7: Vol
A8: 1 | B8: 0246ICS0005 | C8: 15092026 | D8: TCNU628382 /9 | E8: M9768365 | F8: 40
A9: 2 | B9: 0165ICS0071 | C9: 15092026 | D9: MSNU975917 /4 | E9: 5055347 | F9: 40
A10: 3 | B10: 0165ICS0016 | C10: 15092026 | D10: MSDU612394 /9 | E10: 2139541 | F10: 40
A11: 4 | B11: 0038ICS0013 | C11: 15092026 | D11: XXXU459750 /8 | E11: LB0268891 | F11: 45
A12: 5
A13: 6
A14: 7
A17: 8
B19: SORTIE
A21: N° | B21: Date S | C21: IMM | D21: N° Conteneur | E21: N° Scellé | F21: Vol
A22: 1
A23: 2
A24: 3
A25: 4
A26: 5
A27: 6
A28: 7
A29: 8
A30: 9
A31: 10
A32: 11
B34: VISITE
A36: N° | B36: Date V | C36: N° Conteneur | D36: AN° Scellé | E36: NO° Scellé | F36: Vol
A37: 1 | B37: 15092026 | C37: APZU213305 /9 | E37: 3602 | F37: 20 | G37: HUISSIER +RECETTE+DOUANE
A38: 2 | B38: 15092026 | C38: CMAU194208 /0 | E38: 3603 | F38: 20
A39: 3 | B39: 15092026 | C39: TEMU387154 /1 | E39: 3601 | F39: 20
A40: 4 | B40: 15092026 | C40: MRKU714747 /1 | E40: 3609 | F40: 20
A41: 5 | B41: 15092026 | C41: MRKU776760 /0 | D41: 3606 | E41: 3553 | F41: 20
A42: 6 | B42: 15092026 | C42: MRKU862304 /2 | E42: 3607 | F42: 20
A43: 7 | B43: 15092026 | C43: MSKU561006 /4 | E43: 3605 | F43: 20
A44: 8 | B44: 15092026 | C44: SUDU747145 /0 | E44: 3610 | F44: 20
A45: 9 | B45: 15092026 | C45: TCKU302077 /9 | E45: 3608 | F45: 20
A46: 10 | B46: 15092026 | C46: TEMU342001 /8 | E46: 3604 | F46: 20

Sheet 16-09
H1: =COUNTIF(C8:C17,"<>") -> 0 | I1: TC
F2: =COUNTIFS(B22:B29,"<>",C22:C29,"VH") -> 0 | G2: VH | H2: =COUNTA(C22:C33)-F2 -> 12 | I2: TC | J2: =COUNTIF(E22:E29,"VIDE") -> 0
A3: FICHE DE MOUVEMENT
B5: RECEPTION | G5: 46281
A7: N° | B7: N° CRN | C7: Date R | D7: N° Conteneur | E7: N° Scellé | F7: Vol
A8: 1
A9: 2
A10: 3
A11: 4
A12: 5
A13: 6
A14: 7
A17: 8
B19: SORTIE
A21: N° | B21: Date S | C21: IMM | D21: N° Conteneur | E21: N° Scellé | F21: Vol
A22: 1 | B22: 16092026 | C22: 500114-519-16 | D22: CAIU818783 /6 | E22: 3561 | F22: 40
A23: 2 | B23: 16092026 | C23: 000355-524-16 | D23: CAIU819501 /9 | E23: 3562 | F23: 40
A24: 3 | B24: 16092026 | C24: 000710-525-16 | D24: CXDU134311 /3 | E24: 3565 | F24: 40
A25: 4 | B25: 16092026 | C25: 500058-519-16 | D25: FCGU198565 /0 | E25: 3567 | F25: 40
A26: 5 | B26: 16092026 | C26: 500132-519-16 | D26: GESU575475 /4 | E26: 3568 | F26: 40
A27: 6 | B27: 16092026 | C27: 00539-508-31 | D27: HJMU133346 /2 | E27: 3570 | F27: 40
A28: 7 | B28: 16092026 | C28: 000679-525-16 | D28: SEGU466432 /6 | E28: 3502 | F28: 40
A29: 8 | B29: 16092026 | C29: 00704-525-16 | D29: TGHU694661 /0 | E29: 3580 | F29: 40
A30: 9 | B30: 16092026 | C30: 00112-510-31 | D30: BMOU213576 /9 | E30: 3554 | F30: 20
A31: 10 | B31: 16092026 | C31: 00692-509-31 | D31: CXSU114000 /6 | E31: 0 | F31: FLAT
A32: 11 | B32: 16092026 | C32: 00358-510-31 | D32: TCLU600602 /5 | E32: 0 | F32: FLAT
A33: 12 | B33: 16092026 | C33: 00164-513-31 | D33: ECMU266869 /7 | E33: 3943 | F33: 20
B35: VISITE
A37: N° | B37: Date V | C37: N° Conteneur | D37: AN° Scellé | E37: NO° Scellé | F37: Vol
A38: 1 | B38: 16092026 | C38: MRSU491361 /6 | D38: CN6436798 | E38: 3556 | F38: 40
A39: 2 | B39: 16092026 | C39: FDCU031798 /9 | D39: FJ27558901 | E39: 3555 | F39: 40
A40: 3 | B40: 16092026 | C40: FFAU811399 /0 | D40: 18233786 | E40: 3558 | F40: 40
A41: 4
A42: 5
A43: 6
A44: 7
A45: 8
A46: 9
A47: 10

Sheet 17-09
H1: =COUNTIF(C8:C17,"<>") -> 0 | I1: TC
F2: =COUNTIFS(B22:B31,"<>",C22:C31,"VH") -> 0 | G2: VH | H2: =COUNTA(C22:C31)-F2 -> 8 | I2: TC | J2: =COUNTIF(E22:E31,"VIDE") -> 0
A3: FICHE DE MOUVEMENT
B5: RECEPTION | G5: 46282
A7: N° | B7: N° CRN | C7: Date R | D7: N° Conteneur | E7: N° Scellé | F7: Vol
A8: 1
A9: 2
A10: 3
A11: 4
A12: 5
A13: 6
A14: 7
A17: 8
B19: SORTIE
A21: N° | B21: Date S | C21: IMM | D21: N° Conteneur | E21: N° Scellé | F21: Vol
A22: 1 | B22: 17092026 | C22: 000354-524-16 | D22: CAXU959721 /0 | E22: 3564 | F22: 40
A23: 2 | B23: 17092026 | C23: 500058-519-16 | D23: CRSU928503 /0 | E23: 3563 | F23: 40
A24: 3 | B24: 17092026 | C24: 000677-525-16 | D24: CXDU168050 /0 | E24: 3566 | F24: 40
A25: 4 | B25: 17092026 | C25: 000704-525-16 | D25: GESU661177 /9 | E25: 3569 | F25: 40
A26: 5 | B26: 17092026 | C26: 00539-508-31 | D26: HJMU152689 /9 | E26: 3503 | F26: 40
A27: 6 | B27: 17092026 | C27: 000710-525-16 | D27: TCNU646691 /7 | E27: 3501 | F27: 40
A28: 7 | B28: 17092026 | C28: 500054 et 00679-525 | D28: TEXU895077 /6 | E28: FLAT | F28: 40
A29: 8 | B29: 17092026 | C29: 500114 et 00355-524 | D29: TOLU878955 /6 | E29: FLAT | F29: 40
A30: 9
A31: 10
A32: 11
B34: VISITE
A36: N° | B36: Date V | C36: N° Conteneur | D36: AN° Scellé | E36: NO° Scellé | F36: Vol
A37: 1 | B37: 17092026 | C37: FBIU026728 /0 | D37: FX48618480 | E37: 3560 | F37: 20
A38: 2 | B38: 17092026 | C38: MSMU769241 /6 | D38: FX48648827 | E38: 3557 | F38: 40
A39: 3
A40: 4
A41: 5
A42: 6
A43: 7
A44: 8
A45: 9
A46: 10

Sheet 20-09
H1: =COUNTIF(C8:C17,"<>") -> 0 | I1: TC
F2: =COUNTIFS(B22:B31,"<>",C22:C31,"VH") -> 0 | G2: VH | H2: =COUNTA(C22:C31)-F2 -> 2 | I2: TC | J2: =COUNTIF(E22:E31,"VIDE") -> 0
A3: FICHE DE MOUVEMENT
B5: RECEPTION | G5: 46285
A7: N° | B7: N° CRN | C7: Date R | D7: N° Conteneur | E7: N° Scellé | F7: Vol
A8: 1
A9: 2
A10: 3
A11: 4
A12: 5
A13: 6
A14: 7
A17: 8
B19: SORTIE
A21: N° | B21: Date S | C21: IMM | D21: N° Conteneur | E21: N° Scellé | F21: Vol
A22: 1 | B22: 20092026 | C22: 00533-508-31 | D22: MRSU491361 /6 | E22: 3556 | F22: 40
A23: 2 | B23: 20092026 | C23: 018432-511-28 | D23: FDCU031798 /9 | E23: 3555 | F23: 40
A24: 3
A25: 4
A26: 5
A27: 6
A28: 7
A29: 8
A30: 9
A31: 10
A32: 11
B34: VISITE
A36: N° | B36: Date V | C36: N° Conteneur | D36: AN° Scellé | E36: NO° Scellé | F36: Vol
A37: 1 | B37: 20092026 | C37: ECMU753339 /6 | D37: J1979281 | E37: 3656 | F37: 40
A38: 2 | B38: 20092026 | C38: ARKU855648 /7 | D38: B1779962 | E38: 3657 | F38: 40
A39: 3 | B39: 20092026 | C39: MSBU721115 /8 | E39: 3660 | F39: 40
A40: 4 | B40: 20092026 | C40: MSMU504541 /0 | E40: 3659 | F40: 40
A41: 5 | B41: 20092026 | C41: TCLU786835 /9 | E41: 3658 | F41: 40
A42: 6
A43: 7
A44: 8
A45: 9
A46: 10

Sheet 21-09
H1: =COUNTIF(C8:C15,"<>") -> 0 | I1: TC
F2: =COUNTIFS(B20:B29,"<>",C20:C29,"VH") -> 0 | G2: VH | H2: =COUNTA(C20:C29)-F2 -> 4 | I2: TC | J2: =COUNTIF(E20:E29,"VIDE") -> 0
A3: FICHE DE MOUVEMENT
B5: RECEPTION | G5: 46286
A7: N° | B7: N° CRN | C7: Date R | D7: N° Conteneur | E7: N° Scellé | F7: Vol
A8: 1
A9: 2
A10: 3
A11: 4
A12: 5
A13: 6
A14: 7
A15: 8
B17: SORTIE
A19: N° | B19: Date S | C19: IMM | D19: N° Conteneur | E19: N° Scellé | F19: Vol
A20: 1 | B20: 21092026 | C20: 00327-510-31 | D20: FFAU811399 /0 | E20: 3558 | F20: 40
A21: 2 | B21: 21092026 | C21: 00099-509-31 | D21: MSBU721115 /8 | E21: 3660 | F21: 40
A22: 3 | B22: 21092026 | C22: 00328-507-31 | D22: MSMU504541 /0 | E22: 3659 | F22: 40
A23: 4 | B23: 21092026 | C23: 00018-506-31 | D23: TCLU786835 /9 | E23: 3658 | F23: 40
A24: 5
A25: 6
A26: 7
A27: 8
A28: 9
A29: 10
A30: 11
B32: VISITE
A34: N° | B34: Date V | C34: N° Conteneur | D34: AN° Scellé | E34: NO° Scellé | F34: Vol
A35: 1 | B35: 21092026 | C35: MBSU281340 /6 | D35: LB0263265 | E35: 3655 | F35: 20
A36: 2 | B36: 21092026 | C36: ARKU855448 /4 | D36: 239388 | E36: 3559 | F36: 40
A37: 3
A38: 4
A39: 5
A40: 6
A41: 7
A42: 8
A43: 9
A44: 10

Sheet 22-09
H1: =COUNTIF(C8:C15,"<>") -> 0 | I1: TC
F2: =COUNTIFS(B20:B29,"<>",C20:C29,"VH") -> 0 | G2: VH | H2: =COUNTA(C20:C29)-F2 -> 8 | I2: TC | J2: =COUNTIF(E20:E29,"VIDE") -> 0
A3: FICHE DE MOUVEMENT
B5: RECEPTION | G5: 46287
A7: N° | B7: N° CRN | C7: Date R | D7: N° Conteneur | E7: N° Scellé | F7: Vol
A8: 1
A9: 2
A10: 3
A11: 4
A12: 5
A13: 6
A14: 7
A15: 8
B17: SORTIE
A19: N° | B19: Date S | C19: IMM | D19: N° Conteneur | E19: N° Scellé | F19: Vol
A20: 1 | B20: 22092026 | C20: 00117-523-31 | D20: MRKU753756 /7 | E20: ML-IN2987561 | F20: 20
A21: 2 | B21: 22092026 | C21: 500017-525-31 | D21: MRKU772089 /7 | E21: ML-IN2987565 | F21: 20
A22: 3 | B22: 22092026 | C22: 00117-523-31 | D22: MRKU905919 /5 | E22: ML-IN2987562 | F22: 20
A23: 4 | B23: 22092026 | C23: 00139-525-31 | D23: MRSU023326 /7 | E23: ML-IN2987566 | F23: 20
A24: 5 | B24: 22092026 | C24: 00139-525-31 | D24: MSKU704341 /6 | E24: ML-IN2987564 | F24: 20
A25: 6 | B25: 22092026 | C25: 500017-525-31 | D25: MSKU730475 /7 | E25: ML-IN2987563 | F25: 20
A26: 7 | B26: 22092026 | C26: 000164-513-31 | D26: ARKU855448 /4 | E26: 3559 | F26: 40
A27: 8 | B27: 22092026 | C27: 00378-516-31 | D27: ARKU855648 /7 | E27: 3657 | F27: 40
A28: 9
A29: 10
A30: 11
B32: VISITE
A34: N° | B34: Date V | C34: N° Conteneur | D34: AN° Scellé | E34: NO° Scellé | F34: Vol
A35: 1 | B35: 22092026 | C35: FSCU873148 /5 | E35: 3701 | F35: 40
A36: 2 | B36: 22092026 | C36: HASU512425 /3 | E36: 3702 | F36: 40
A37: 3 | B37: 22092026 | C37: CMAU789256 /2 | E37: 3703 | F37: 40
A38: 4 | B38: 22092026 | C38: ARKU241132 /0 | D38: B1758829 | E38: 3652 | F38: 20
A39: 5 | B39: 22092026 | C39: TRHU307416 /1 | D39: B1758825 | E39: 3653 | F39: 20
A40: 6 | B40: 22092026 | C40: MSNU191236 /9 | D40: SK360769 | E40: 3654 | F40: 20
A41: 7 | B41: 22092026 | C41: GCXU573668 /2 | D41: CN6536328 | E41: 3651 | F41: 40
A42: 8 | B42: 22092026 | C42: HLXU629565 /7 | E42: 3711 | F42: 20
A43: 9
A44: 10

Sheet 23-09
H1: =COUNTIF(C8:C15,"<>") -> 0 | I1: TC
F2: =COUNTIFS(B20:B29,"<>",C20:C29,"VH") -> 0 | G2: VH | H2: =COUNTA(C20:C29)-F2 -> 1 | I2: TC | J2: =COUNTIF(E20:E29,"VIDE") -> 0
A3: FICHE DE MOUVEMENT
B5: RECEPTION | G5: 46288
A7: N° | B7: N° CRN | C7: Date R | D7: N° Conteneur | E7: N° Scellé | F7: Vol
A8: 1
A9: 2
A10: 3
A11: 4
A12: 5
A13: 6
A14: 7
A15: 8
B17: SORTIE
A19: N° | B19: Date S | C19: IMM | D19: N° Conteneur | E19: N° Scellé | F19: Vol
A20: 1 | B20: 23092026 | C20: 00582-510-31 | D20: MBSU281340 /6 | E20: 3655 | F20: 20
A21: 2
A22: 3
A23: 4
A24: 5
A25: 6
A26: 7
A27: 8
A28: 9
A29: 10
A30: 11
B32: VISITE
A34: N° | B34: Date V | C34: N° Conteneur | D34: AN° Scellé | E34: NO° Scellé | F34: Vol
A35: 1 | B35: 23092026 | C35: APHU463551 /5 | D35: M9168709 | E35: 3704 | F35: 45
A36: 2
A37: 3
A38: 4
A39: 5
A40: 6
A41: 7
A42: 8
A43: 9
A44: 10

Sheet 24-09
H1: =COUNTIF(C8:C15,"<>") -> 0 | I1: TC
F2: =COUNTIFS(B20:B29,"<>",C20:C29,"VH") -> 0 | G2: VH | H2: =COUNTA(C20:C29)-F2 -> 1 | I2: TC | J2: =COUNTIF(E20:E29,"VIDE") -> 0
A3: FICHE DE MOUVEMENT
B5: RECEPTION | G5: 46289
A7: N° | B7: N° CRN | C7: Date R | D7: N° Conteneur | E7: N° Scellé | F7: Vol
A8: 1
A9: 2
A10: 3
A11: 4
A12: 5
A13: 6
A14: 7
A15: 8
B17: SORTIE
A19: N° | B19: Date S | C19: IMM | D19: N° Conteneur | E19: N° Scellé | F19: Vol
A20: 1 | B20: 23092026 | C20: 00053-517-31 | D20: APHU463551 /5 | E20: 3704 | F20: 45
A21: 2
A22: 3
A23: 4
A24: 5
A25: 6
A26: 7
A27: 8
A28: 9
A29: 10
A30: 11
B32: VISITE
A34: N° | B34: Date V | C34: N° Conteneur | D34: AN° Scellé | E34: NO° Scellé | F34: Vol
A35: 1 | B35: 24092026 | C35: XXXU459750 /8 | D35: LB0268891 | E35: 3708 | F35: 45
A36: 2 | B36: 24092026 | C36: MEDU951011 /6 | D36: FX46629585 | E36: 3709 | F36: 45
A37: 3 | B37: 24092026 | C37: MEDU958286 /2 | D37: FX46635083 | E37: 3710 | F37: 45
A38: 4 | B38: 24092026 | C38: OOCU976350 /8 | E38: 3717 | F38: 40
A39: 5 | B39: 24092026 | C39: TCKU704466 /0 | E39: 3718 | F39: 40
A40: 6 | B40: 24092026 | C40: FSCU805157 /5 | E40: 3719 | F40: 40
A41: 7 | B41: 24092026 | C41: MSNU975917 /4 | D41: 5055347 | E41: 3705 | F41: 40
A42: 8 | B42: 24092026 | C42: TCNU628382 /9 | D42: M9768365 | E42: 3720 | F42: 40
A43: 9
A44: 10

Sheet 26-09
H1: =COUNTIF(C8:C20,"<>") -> 9 | I1: TC
F2: =COUNTIFS(B27:B35,"<>",C27:C35,"VH") -> 0 | G2: VH | H2: =COUNTA(C27:C35)-F2 -> 0 | I2: TC | J2: =COUNTIF(E27:E35,"VIDE") -> 0
A3: FICHE DE MOUVEMENT
B5: RECEPTION | G5: 46291
A7: N° | B7: N° CRN | C7: Date R | D7: N° Conteneur | E7: N° Scellé | F7: Vol
A8: 1 | B8: 0167ICS0129 | C8: 26092026 | D8: MSBU796594 /4 | E8: FJ26597592 | F8: 40
A9: 2 | C9: 26092026 | D9: MSNU921194 /0 | E9: FJ26597361 | F9: 40
A10: 3 | C10: 26092026 | D10: TIIU443725 /1 | E10: FJ26597473 | F10: 40
A11: 4 | C11: 26092026 | D11: UETU778883 /2 | E11: FJ26597436 | F11: 40
A12: 5 | B12: 0168ICS0007 | C12: 26092026 | D12: MSDU997113 /6 | E12: 0 | F12: FLAT
A13: 6 | C13: 26092026 | D13: MSMU661001 /2 | E13: 0674611 | F13: 40
A14: 7 | C14: 26092026 | D14: UETU703460 /0 | E14: 0674567 | F14: 40
A15: 8 | B15: 0092ICS0100 | D15: MRKU588631 /7 | E15: ANNULL | F15: 40
A16: 9 | D16: UETU682895 /1 | F16: 40
A17: 10 | D17: UETU818706 /0 | F17: 40
A18: 11 | B18: 0092ICS0106 | C18: 26092026 | D18: SUDU850406 /0 | E18: CN6499593 | F18: 40
A19: 12 | B19: 0092ICS0025 | C19: 26092026 | D19: CAAU692306 /7 | E19: CN6229789 | F19: 40
A20: 13 | B20: 0092ICS0061 | D20: MRSU415138 /3 | E20: ANNULL | F20: 40
B24: SORTIE
A26: N° | B26: Date S | C26: IMM | D26: N° Conteneur | E26: N° Scellé | F26: Vol
A27: 1
A28: 2
A29: 3
A30: 4
A31: 5
A32: 6
A33: 7
A34: 8
A35: 9
B37: VISITE
A39: N° | B39: Date V | C39: N° Conteneur | D39: AN° Scellé | E39: NO° Scellé | F39: Vol
A40: 1
A41: 2
A42: 3
A43: 4
A44: 5
A45: 6
A46: 7
A47: 8
A48: 9
...

Sheet 27-09
H1: =COUNTIF(C8:C20,"<>") -> 11 | I1: TC
F2: =COUNTIFS(B27:B33,"<>",C27:C33,"VH") -> 0 | G2: VH | H2: =COUNTA(C27:C33)-F2 -> 2 | I2: TC | J2: =COUNTIF(E27:E33,"VIDE") -> 0
A3: FICHE DE MOUVEMENT
B5: RECEPTION | G5: 46292
A7: N° | B7: N° CRN | C7: Date R | D7: N° Conteneur | E7: N° Scellé | F7: Vol
A8: 1 | B8: 0169ICS0028 | C8: 27092026 | D8: OOCU568279 /5 | E8: 32460820 | F8: 40
A9: 2 | B9: 0167ICS0020 | C9: 27092026 | D9: MSMU923966 /7 | E9: FX48593058 | F9: 45
A10: 3 | B10: 0169ICS0018 | C10: 27092026 | D10: FBLU420928 /6 | E10: A584769 | F10: 40
A11: 4 | C11: 27092026 | D11: TEXU151862 /6 | E11: A584615 | F11: 40
A12: 5 | C12: 27092026 | D12: TRIU057483 /0 | E12: A584616 | F12: 40
A13: 6 | B13: 0808ICS0023 | C13: 27092026 | D13: CMAU220385 /0 | E13: 1730449 | F13: 20
A14: 7 | C14: 27092026 | D14: CMAU455459 /8 | E14: 1730443 | F14: 40
A15: 8 | C15: 27092026 | D15: CMAU480173 /8 | E15: 1730445 | F15: 40
A16: 9 | C16: 27092026 | D16: CMAU573921 /4 | E16: 1730441 | F16: 40
A17: 10 | C17: 27092026 | D17: CMAU786292 /7 | E17: 1730447 | F17: 40
A18: 11 | C18: 27092026 | D18: TCNU415361 /5 | E18: 1730400 | F18: 40
A19: 12
A20: 13
B24: SORTIE
A26: N° | B26: Date S | C26: IMM | D26: N° Conteneur | E26: N° Scellé | F26: Vol
A27: 1 | B27: 27092026 | C27: 500089-513-31 | D27: FBIU026728 /0 | E27: 3560 | F27: 20
A28: 2 | B28: 27092026 | C28: 500096-511-31 | D28: MSMU769241 /6 | E28: 3557 | F28: 40
A29: 3
A30: 4
A31: 5
A32: 6
A33: 7
B35: VISITE
A37: N° | B37: Date V | C37: N° Conteneur | D37: AN° Scellé | E37: NO° Scellé | F37: Vol
A38: 1 | B38: 27092026 | C38: TCNU628382 /9 | D38: 3720 | E38: 3712 | F38: 40
A39: 2 | C39: HASU492916 /6 | D39: 3707 | E39: 3715
A40: 3 | C40: HASU5156746 /8 | D40: 3706 | E40: 3713
A41: 4 | C41: MRSU698006 /4 | E41: 3716
A42: 5 | C42: HJCU111021 /6 | E42: 3662
A43: 6 | C43: YMLU822002 /6 | E43: 3663
A44: 7 | C44: GTSU885207 /7 | E44: 3661
A45: 8 | C45: GLDU072442 /9 | E45: 3664
A46: 9
A47: 10

Sheet 28-09
H1: =COUNTIF(C8:C15,"<>") -> 2 | I1: TC
F2: =COUNTIFS(B21:B29,"<>",C21:C29,"VH") -> 0 | G2: VH | H2: =COUNTA(C21:C29)-F2 -> 0 | I2: TC | J2: =COUNTIF(E21:E29,"VIDE") -> 0
A3: FICHE DE MOUVEMENT
B5: RECEPTION | G5: 46293
A7: N° | B7: N° CRN | C7: Date R | D7: N° Conteneur | E7: N° Scellé | F7: Vol
A8: 1 | B8: 0170ICS0190 | C8: 28092026 | D8: MSMU933118 /2 | E8: FJ28349555 | F8: 45
A9: 2 | B9: 0170ICS0215 | C9: 28092026 | D9: MSMU932960 /5 | E9: FJ28511677 | F9: 45
A10: 3
A11: 4
A12: 5
A13: 6
A14: 7
A15: 8
B18: SORTIE
A20: N° | B20: Date S | C20: IMM | D20: N° Conteneur | E20: N° Scellé | F20: Vol
A21: 1
A22: 2
A23: 3
A24: 4
A25: 5
A26: 6
A27: 7
A28: 8
A29: 9
B31: VISITE
A33: N° | B33: Date V | C33: N° Conteneur | D33: AN° Scellé | E33: NO° Scellé | F33: Vol
A34: 1 | B34: 28092026 | C34: FFAU501814 /0 | E34: 3669 | F34: 40
A35: 2 | B35: 28092026 | C35: CAAU640372 /2 | E35: 3666 | F35: 40
A36: 3 | B36: 28092026 | C36: MSKU148879 /1 | D36: ML-CN6337956 | E36: 3667 | F36: 40
A37: 4 | B37: 28092026 | C37: MSKU100022 /7 | D37: ML-CN6309165 | E37: 3668 | F37: 40
A38: 5 | B38: 28092026 | C38: HJCU111021 /6 | D38: 3662 | E38: 3670 | F38: 40
A39: 6 | B39: 28092026 | C39: YMLU822002 /6 | D39: 3663 | E39: 3714 | F39: 40
A40: 7 | B40: 28092026 | C40: GTSU885207 /7 | D40: 3661 | E40: 3612 | F40: 40
A41: 8 | B41: 28092026 | C41: GLDU072442 /9 | D41: 3664 | E41: 3665 | F41: 40
A42: 9
A43: 10

Sheet 29-09
H1: =COUNTIF(C8:C16,"<>") -> 0 | I1: TC
F2: =COUNTIFS(B21:B29,"<>",C21:C29,"VH") -> 0 | G2: VH | H2: =COUNTA(C21:C29)-F2 -> 6 | I2: TC | J2: =COUNTIF(E21:E29,"VIDE") -> 0
A3: FICHE DE MOUVEMENT
B5: RECEPTION | G5: 46294
A7: N° | B7: N° CRN | C7: Date R | D7: N° Conteneur | E7: N° Scellé | F7: Vol
A8: 1
A9: 2
A10: 3
A11: 4
A12: 5
A13: 6
A14: 7
A15: 8
A16: 9
B18: SORTIE
A20: N° | B20: Date S | C20: IMM | D20: N° Conteneur | E20: N° Scellé | F20: Vol
A21: 1 | B21: 29092026 | C21: 00359-515-31 | D21: XXXU459750 /8 | E21: 3708 | F21: 45
A22: 2 | B22: 29092026 | C22: 00378-505-31 | D22: MSNU191236 /9 | E22: 3654 | F22: 20
A23: 3 | B23: 29092026 | C23: 00217-507-31 | D23: MSKU148879 /1 | E23: 3667 | F23: 40
A24: 4 | B24: 29092026 | C24: 00235-509-31 | D24: MSKU100022 /7 | E24: 3668 | F24: 40
A25: 5 | B25: 29092026 | C25: 00426-510-31 | D25: ECMU753339 /6 | E25: 3665 | F25: 40
A26: 6 | B26: 29092026 | C26: 0036-510-31 | D26: GCXU573668 /2 | E26: 3651 | F26: 40
A27: 7
A28: 8
A29: 9
B31: VISITE
A33: N° | B33: Date V | C33: N° Conteneur | D33: AN° Scellé | E33: NO° Scellé | F33: Vol
A34: 1 | B34: 29092026 | C34: ECMU809447 /2 | D34: M4936024 | E34: 3611 | F34: 40
A35: 2 | B35: 29092026 | C35: TCNU628382 /9 | D35: 3712 | E35: 3613 | F35: 45
A36: 3
A37: 4
A38: 5
A39: 6
A40: 7
A41: 8
A42: 9
A43: 10

Sheet 30-09
H1: =COUNTIF(C8:C15,"<>") -> 0 | I1: TC
F2: =COUNTIFS(B20:B29,"<>",C20:C29,"VH") -> 0 | G2: VH | H2: =COUNTA(C20:C29)-F2 -> 2 | I2: TC | J2: =COUNTIF(E20:E29,"VIDE") -> 0
A3: FICHE DE MOUVEMENT
B5: RECEPTION | G5: 46295
A7: N° | B7: N° CRN | C7: Date R | D7: N° Conteneur | E7: N° Scellé | F7: Vol
A8: 1
A9: 2
A10: 3
A11: 4
A12: 5
A13: 6
A14: 7
A15: 8
B17: SORTIE
A19: N° | B19: Date S | C19: IMM | D19: N° Conteneur | E19: N° Scellé | F19: Vol
A20: 1 | B20: 30092026 | C20: 00547-592-31 | D20: MEDU951011 /6 | E20: 3709 | F20: 45
A21: 2 | B21: 30092026 | C21: 00224-596-31 | D21: MEDU958286 /2 | E21: 3710 | F21: 45
A22: 3
A23: 4
A24: 5
A25: 6
A26: 7
A27: 8
A28: 9
A29: 10
A30: 11
B32: VISITE
A34: N° | B34: Date V | C34: N° Conteneur | D34: AN° Scellé | E34: NO° Scellé | F34: Vol
A35: 1
A36: 2
A37: 3
A38: 4
A39: 5
A40: 6
A41: 7
