Workbook

Sheet DASHBOARD
A1: Date | B1: TC Réceptionnés | C1: TC Sortis | D1: Total Mouvements | F1: TC Sortis VIDE
A2: 44712 | B2: ='01-06'!H1 -> 0 | C2: ='01-06'!H2 -> 4 | D2: =SUM(B2:C2) -> 4 | F2: =INDIRECT("'"&A2&"'!J2") -> #REF!
A3: 44713 | B3: ='02-06'!H1 -> 3 | C3: ='02-06'!H2 -> 2 | D3: =SUM(B3:C3) -> 5 | F3: =INDIRECT("'"&A3&"'!J2") -> #REF!
A4: 44714 | B4: ='03-06'!H1 -> 31 | C4: ='03-06'!H2 -> 2 | D4: =SUM(B4:C4) -> 33 | F4: =INDIRECT("'"&A4&"'!J2") -> #REF!
A5: 44715 | B5: ='04-06'!H1 -> 4 | C5: ='04-06'!H2 -> 1 | D5: =SUM(B5:C5) -> 5 | F5: =INDIRECT("'"&A5&"'!J2") -> #REF!
A6: 44718 | B6: ='07-06'!H1 -> 10 | C6: ='07-06'!H2 -> 3 | D6: =SUM(B6:C6) -> 13 | F6: =INDIRECT("'"&A6&"'!J2") -> #REF!
A7: 44719 | B7: ='08-06'!H1 -> 2 | C7: ='08-06'!H2 -> 1 | D7: =SUM(B7:C7) -> 3 | F7: =INDIRECT("'"&A7&"'!J2") -> #REF!
A8: 44720 | B8: ='09-06'!H1 -> 36 | C8: ='09-06'!H2 -> 0 | D8: =SUM(B8:C8) -> 36 | F8: =INDIRECT("'"&A8&"'!J2") -> #REF!
A9: 44721 | B9: ='10-06'!H1 -> 5 | C9: ='10-06'!H2 -> 5 | D9: =SUM(B9:C9) -> 10 | F9: =INDIRECT("'"&A9&"'!J2") -> #REF!
A10: 44722 | B10: ='11-06'!H1 -> 0 | C10: ='11-06'!H2 -> 9 | D10: =SUM(B10:C10) -> 9 | F10: =INDIRECT("'"&A10&"'!J2") -> #REF!
A11: 44725 | B11: ='14-06'!H1 -> 3 | C11: ='14-06'!H2 -> 13 | D11: =SUM(B11:C11) -> 16 | F11: =INDIRECT("'"&A11&"'!J2") -> #REF!
A12: 44726 | B12: ='15-06'!H1 -> 2 | C12: ='15-06'!H2 -> 21 | D12: =SUM(B12:C12) -> 23 | F12: =INDIRECT("'"&A12&"'!J2") -> #REF!
A13: 44728 | B13: ='17-06'!H1 -> 0 | C13: ='17-06'!H2 -> 12 | D13: =SUM(B13:C13) -> 12 | F13: =INDIRECT("'" &#REF! &"'!J2") -> #REF!
A14: 44729 | B14: ='18-06'!H1 -> 10 | C14: ='18-06'!H2 -> 1 | D14: =SUM(B14:C14) -> 11 | F14: =INDIRECT("'"& A13 &"'!J2") -> #REF!
A15: 44732 | B15: ='21-06'!H1 -> 2 | C15: ='21-06'!H2 -> 6 | D15: =SUM(B15:C15) -> 8 | F15: =INDIRECT("'"& A14 &"'!J2") -> #REF!
A16: 44733 | B16: ='22-06'!H1 -> 0 | C16: ='22-06'!H2 -> 0 | D16: =SUM(B16:C16) -> 0 | F16: =INDIRECT("'"& A15 &"'!J2") -> #REF!
A17: 44734 | B17: ='23-06'!H1 -> 1 | C17: ='22-06'!H2 -> 0 | D17: =SUM(B17:C17) -> 1 | F17: =INDIRECT("'"& A16 &"'!J2") -> #REF!
A18: 44735 | B18: ='24-06'!H1 -> 0 | C18: ='24-06'!H2 -> 8 | D18: =SUM(B18:C18) -> 8 | F18: =INDIRECT("'"& A17 &"'!J2") -> #REF!
A19: 44739 | B19: ='28-06'!H1 -> 3 | C19: ='28-06'!H2 -> 1 | D19: =SUM(B19:C19) -> 4 | F19: =INDIRECT("'"& A18 &"'!J2") -> #REF!
A20: 44740 | B20: ='29-06'!H1 -> 14 | C20: ='29-06'!H2 -> 10 | D20: =SUM(B20:C20) -> 24 | F20: =INDIRECT("'"& A19 &"'!J2") -> #REF!
A21: 44741 | B21: ='30-06'!H1 -> 0 | C21: ='30-06'!H2 -> 2 | D21: =SUM(B21:C21) -> 2
A24: Total | B24: =SUM(B2:B22) -> 126 | C24: =SUM(C2:C22) -> 101 | D24: =SUM(D2:D21) -> 227 | F24: =INDIRECT("'"& A21 &"'!J2") -> #REF!
D25: VIDE
D26: VH | F26: ='01-06'!J2+'02-06'!J2+'03-06'!J2+'04-06'!J2+'07-06'!J2+'08-06'!J2+'09-06'!J2+'10-06'!J2+'11-06'!J2+'14-06'!J2+'15-06'!J2+'17-06'!J2+'18-06'!J2+'21-06'!J2+'23-06'!J2+'24-06'!J2+'28-06'!J2+'29-06'!J2+'30-06'!J2 -> 6
F27: ='01-06'!F2+'02-06'!F2+'03-06'!F2+'04-06'!F2+'07-06'!F2+'08-06'!F2+'09-06'!F2+'10-06'!F2+'11-06'!F2+'14-06'!F2+'15-06'!F2+'17-06'!F2+'18-06'!F2+'21-06'!F2+'22-06'!F2+'23-06'!F2+'24-06'!F2+'28-06'!F2+'29-06'!F2+'30-06'!F2 -> 19

Sheet 01-06
H1: =COUNTIF(B9:B16,"<>") -> 0 | I1: TC
F2: =COUNTIFS(B21:B34,"<>",C21:C34,"VH") -> 1 | G2: VH | H2: =COUNTA(C21:C27)-F2 -> 4 | I2: TC | J2: =COUNTIF(E19:E27,"VIDE") -> 0
A3: FICHE DE MOUVEMENT
B6: RECEPTION | G6: 44713
A8: N° | B8: N° CRN | C8: Date R | D8: N° Conteneur | E8: N° Scellé | F8: Vol
A9: 1
A10: 2
A11: 3
A12: 4
A13: 5
A14: 6
A15: 7
A16: 8
B18: SORTIE
A20: N° | B20: Date S | C20: IMM | D20: N° Conteneur | E20: N° Scellé | F20: Vol
A21: 1 | B21: 46174 | C21: 000193-511-02 | D21: MSNU864526 /4 | E21: 0259875 | F21: 40
A22: 2 | B22: 46174 | C22: VH | D22: LB37-SX841523 | E22: GEELY | F22: VH
A23: 3 | B23: 46174 | C23: 00125-523-31 | D23: TCKU822040 /4 | E23: 3823 | F23: 40
A24: 4 | B24: 46174 | C24: 00142-523-31 | D24: TLLU466410 /6 | E24: 3824 | F24: 40
A25: 5 | B25: 46174 | C25: 00122-523-31 | D25: TCNU471329 /0 | E25: 3822 | F25: 40
B32: VISITE
A34: N° | B34: Date V | C34: N° Conteneur | D34: AN° Scellé | E34: NO° Scellé | F34: Vol
A35: 1 | B35: 1062026 | C35: TCNU 999465 /1 | D35: M9561776 | E35: 3787 | F35: 45
A36: 2 | B36: 1062026 | C36: TCKU 693680 /5 | D36: CN4082328 | E36: 3786 | F36: 40
A37: 3 | B37: 1062026 | C37: MSNU865171 /3 | D37: FJ26137054 | E37: 3785 | F37: 40
A38: 4 | B38: 1062026 | C38: MEDU718149 /6 | D38: 1013343 | E38: 3783 | F38: 40

Sheet 02-06
H1: =COUNTIF(C9:C16,"<>") -> 3 | I1: TC
F2: =COUNTIFS(B21:B34,"<>",C21:C34,"VH") -> 0 | G2: VH | H2: =COUNTA(C21:C30)-F2 -> 2 | I2: TC | J2: =COUNTIF(E19:E27,"VIDE") -> 0
A3: FICHE DE MOUVEMENT
B6: RECEPTION | G6: 46174
A8: N° | B8: N° CRN | C8: Date R | D8: N° Conteneur | E8: N° Scellé | F8: Vol | G8: Depotage
A9: 1 | B9: 0090ICS0221 /3 | C9: 44713 | D9: MSMU666679 /4 | E9: FJ27554163 | F9: GROUPAGE | G9: 44715
A10: 2 | B10: 0090ICS0180 /4 | C10: 44713 | D10: MSDU854545 /5 | E10: FJ27476918 | F10: GROUPAGE | G10: 44715
A11: 3 | B11: 0090ICS0179 /4 | C11: 44713 | D11: MSNU557983 /1 | E11: FJ27476913 | F11: GROUPAGE | G11: 44715
A12: 4
A13: 5
A14: 6
A15: 7
A16: 8
B18: SORTIE
A20: N° | B20: Date S | C20: IMM | D20: N° Conteneur | E20: N° Scellé | F20: Vol
A21: 1 | B21: 2062026 | C21: 00238-518-31 | D21: MEDU718149 /6 | E21: 3783 | F21: 40
A22: 2 | B22: 2062026 | C22: 00453-512-31 | D22: MSMU928197 /0 | E22: 3790 | F22: 45
B32: VISITE
A34: N° | B34: Date V | C34: N° Conteneur | D34: AN° Scellé | E34: NO° Scellé | F34: Vol
A35: 1 | B35: 2062026 | C35: CAAU860798 /3 | D35: ML-CN6237504 | E35: 3717 | F35: 40
A36: 2 | B36: 2062026 | C36: WTLU500068 /8 | D36: 17732 | E36: 3811 | F36: 40
A37: 3 | B37: 2062026 | C37: CMAU752750 /7 | D37: R9838651 | E37: 3812 | F37: 40
A38: 4 | B38: 2062026 | C38: CMAU983077 /0 | D38: R9803693 | E38: 3813 | F38: 40
A39: 5 | B39: 2062026 | C39: CMAU983583 /3 | D39: R9799274 | E39: 3814 | F39: 40
A40: 6 | B40: 2062026 | C40: CMAU983624 /9 | D40: R9799137 | E40: 3815 | F40: 40
A41: 7 | B41: 2062026 | C41: ECMU545635 /1 | D41: R9803797 | E41: 3816 | F41: 40
A42: 8 | B42: 2062026 | C42: TCNU331174 /2 | D42: R9803796 | E42: 3819 | F42: 40

Sheet 03-06
H1: =COUNTIF(C9:C48,"<>") -> 31 | I1: TC
F2: =COUNTIFS(B56:B69,"<>",C56:C69,"VH") -> 0 | G2: VH | H2: =COUNTA(C56:C65)-F2 -> 2 | I2: TC | J2: =COUNTIF(E56:E63,"VIDE") -> 0
A3: FICHE DE MOUVEMENT
B6: RECEPTION | G6: 44714
A8: N° | B8: N° CRN | C8: Date R | D8: N° Conteneur | E8: N° Scellé | F8: Vol
A9: 1 | B9: 369ICS0145 | C9: 46176 | D9: SUDU866062 /7 | E9: CN6284860 | F9: 40
A10: 2 | B10: 3691CS0095 | C10: 46176 | D10: CAAU845506 /8 | E10: CN5024551 | F10: 40
A11: 3 | B11: 0081 ICS0057 | C11: 46176 | D11: CAIU904854 /2 | E11: B3916841 | F11: 40
A12: 4
A13: 5 | C13: 46176 | D13: FFAU378505 /5 | E13: B3916714 | F13: 40
A14: 6 | C14: 46176 | D14: MSDU782251 /3 | E14: B3916633 | F14: 40
A15: 7 | C15: 46176 | D15: MSDU875862 /0 | E15: B3916713 | F15: 40
A16: 8 | C16: 46176 | D16: MSMU897335 /7 | E16: B3916631 | F16: 40
A17: 9 | C17: 46176 | D17: TCNU892435 /1 | E17: B3915842 | F17: 40
A18: 10 | C18: 46176 | D18: UETU568729 /4 | E18: B3916712 | F18: 40
A19: 11 | B19: 0041ICS0032 | C19: 46176 | D19: MSKU100022 /7 | E19: ML-CN6309165 | F19: 40
A20: 12 | B20: 0041ICS0062 | C20: 46176 | D20: TCNU262349 /5 | E20: ML-CN3700782 | F20: 40
A21: 13 | B21: 0041ICS0042 | C21: 46176 | D21: MRSU345476 /5 | E21: ML-CN37700789 | F21: 40
A22: 14 | B22: 0041ICS0055 | C22: 46176 | D22: MSKU148879 /1 | E22: ML-CN6337956 | F22: 40
A23: 15 | B23: 0081ICS0123 | C23: 46176 | D23: CAIU986982 /5 | E23: FX45999499 | F23: 40
A24: 16 | C24: 46176 | D24: MSDU652953 /7 | E24: FX45999474 | F24: 40
A25: 17 | C25: 46176 | D25: MSNU593133 /0 | E25: FX46020281 | F25: 40
A26: 18 | B26: 0086ICS0002 | C26: 46176 | D26: ARKU833224 /0 | E26: 065254 | F26: 40
A27: 19 | C27: 46176 | D27: ARKU854822 /3 | E27: 015868 | F27: 40
A28: 20 | C28: 46176 | D28: ARKU858731 /7 | E28: B2176368 | F28: 40
A29: 21 | B29: 0083ICS0020 | C29: 46176 | D29: MSBU516228 /6 | E29: KG685093 | F29: 40
A30: 22 | C30: 46176 | D30: MSMU545978 /7 | E30: KG685094 | F30: 40
A31: 23
A32: 24 | C32: 46176 | D32: TRHU 864 899 /8 | E32: KG685091 | F32: 40
A33: 25 | B33: 0380ICS0031 | C33: 46176 | D33: HMMU437539 /2 | E33: 25H1381151 | F33: 40
A34: 26 | B34: 0081ICS0119 | C34: 46176 | D34: MSCU548664 /8 | E34: 89913 | F34: 40
A35: 27 | B35: 0081ICS0155 | C35: 46176 | D35: MSMU922668 /0 | E35: FJ27211605 | F35: 40
A36: 28 | B36: 00402ICS0115
A37: 29 | B37: 0369ICS0043
A38: 30 | B38: 0072ICS0051 | D38: MSNU371507 /6 | E38: LG00206277 | F38: 40
A39: 31 | B39: 00402ICS0030 | C39: 46176 | D39: ECMU663924 /9 | E39: FLAT | F39: 40
A40: 32
A41: 33
A42: 34
A43: 35 | B43: 0083ICS0012 | C43: 46176 | D43: BMOU480435 /4 | E43: 2729853 | F43: 40
...

Sheet 04-06
H1: =COUNTIF(C9:C16,"<>") -> 4 | I1: TC
F2: =COUNTIFS(B21:B34,"<>",C21:C34,"VH") -> 0 | G2: VH | H2: =COUNTA(C21:C30)-F2 -> 1 | I2: TC | J2: =COUNTIF(E19:E27,"VIDE") -> 0
A3: FICHE DE MOUVEMENT
B6: RECEPTION | F6: Date | G6: 44715
A8: N° | B8: N° CRN | C8: Date R | D8: N° Conteneur | E8: N° Scellé | F8: Vol
A9: 1
A10: 2 | B10: 0083ICS0020 | C10: 4062026 | D10: TCLU263893 /9 | E10: KG685096 | F10: 20
A11: 3 | B11: 00402ICS0115 | C11: 4062026 | D11: CMAU369780 /3 | E11: ELOGIS000126 | F11: 40
A12: 4 | B12: 0072ICS0051 | C12: 4062026 | D12: FFAU670430 /8 | E12: CN5318408 | F12: 40
A13: 5
A14: 6
A15: 7
A16: 8 | B16: 0106ICS0012 | C16: 4062026 | D16: CAJU522157 /1 | E16: 656800 | F16: 40
B18: SORTIE
A20: N° | B20: Date S | C20: IMM | D20: N° Conteneur | E20: N° Scellé | F20: Vol
A21: 1 | B21: 4062026 | C21: 00634-509-31 | D21: TCNU999465 /1 | E21: 3787 | F21: 40
B32: VISITE
A34: N° | B34: Date V | C34: N° Conteneur | D34: AN° Scellé | E34: NO° Scellé | F34: Vol
A35: 1 | B35: 4062026 | C35: CMAU687016 /8 | E35: 3840 | F35: 40
A36: 2 | B36: 4062026 | C36: SEGU587635 /6 | E36: 3781 | F36: 40
A37: 3 | B37: 4062026 | C37: WTLU500068 /8 | E37: 3782 | F37: 40

Sheet 07-06
H1: =COUNTIF(C9:C18,"<>") -> 10 | I1: TC
F2: =COUNTIFS(B25:B38,"<>",C25:C38,"VH") -> 0 | G2: VH | H2: =COUNTA(C25:C34)-F2 -> 3 | I2: TC | J2: =COUNTIF(E19:E27,"VIDE") -> 1
A3: FICHE DE MOUVEMENT
B6: RECEPTION | F6: Date | G6: 44718
A8: N° | B8: N° CRN | C8: Date R | D8: N° Conteneur | E8: N° Scellé | F8: Vol
A9: 1 | B9: 0085ICS0038 | C9: 46180 | D9: CAIU449713 /4 | E9: FJ19647907 | F9: 40
A10: 2 | C10: 46180 | D10: MSBU680032 /2 | E10: FJ19647909 | F10: 40
A11: 3 | C11: 46180 | D11: MSDU597111 /7 | E11: FJ19647904 | F11: 40
A12: 4 | C12: 46180 | D12: MSMU885191 /3 | E12: FJ19647906 | F12: 40
A13: 5 | C13: 46180 | D13: MSNU913023 /7 | E13: FJ19647910 | F13: 40
A14: 6 | C14: 46180 | D14: TRHU792640 /9 | E14: FJ19647908 | F14: 40
A15: 7 | C15: 46180 | D15: UETU676536 /5 | E15: FJ19647905 | F15: 40
A16: 8 | B16: 0085ICS0014 | C16: 46180 | D16: MSDU807381 /0 | E16: 882399 | F16: 40
A17: 9 | C17: 46180 | D17: MSNU516297 /7 | E17: 886585 | F17: 40
A18: 10 | B18: 0081ICS0057 | C18: 46180 | D18: FFAU252344 /8 | E18: B3916632 | F18: 40
A19: 11
A20: 12
B22: SORTIE
A24: N° | B24: Date S | C24: IMM | D24: N° Conteneur | E24: N° Scellé | F24: Vol
A25: 1 | B25: 7062026 | C25: 00440-504-31 | D25: HMMU605626 /5 | E25: VIDE | F25: 40
A26: 2 | B26: 7062026 | C26: 00139-513-31 | D26: SEGU587835 /6 | E26: 3781 | F26: 45
A27: 3 | B27: 7062026 | C27: 00020-507-31 | D27: TCKU693680 /5 | E27: 3786 | F27: 40
B34: VISITE
A36: N° | B36: Date V | C36: N° Conteneur | D36: AN° Scellé | E36: NO° Scellé | F36: Vol
A37: 1 | B37: 7062026 | C37: SUDU698880 /7 | D37: ML-CN6153428 | E37: 3818 | F37: 40
A38: 2 | B38: 7062026 | C38: TRHU763561 /4 | D38: FX44434489 | E38: 3784 | F38: 40

Sheet 08-06
H1: =COUNTIF(C8:C11,"<>") -> 2 | I1: TC
F2: =COUNTIFS(B16:B29,"<>",C16:C29,"VH") -> 0 | G2: VH | H2: =COUNTA(C16)-F2 -> 1 | I2: TC | J2: =COUNTIF(E19:E27,"VIDE") -> 0
A3: FICHE DE MOUVEMENT
B5: RECEPTION | F5: Date | G5: 44719
A7: N° | B7: N° CRN | C7: Date R | D7: N° Conteneur | E7: N° Scellé | F7: Vol
A8: 1 | B8: 00402ICS0030 | C8: 46181 | D8: ECMU664302 /2 | E8: FLAT | F8: 40
A9: 2 | C9: 46181 | D9: TRIU081904V/3 | E9: FLAT | F9: 40
A10: 3
A11: 4
B13: SORTIE
A15: N° | B15: Date S | C15: IMM | D15: N° Conteneur | E15: N° Scellé | F15: Vol
A16: 1 | B16: 8062026 | C16: 00183-524-31 | D16: MSNU865171 /3 | E16: 3785
B23: VISITE
A25: 0 | B25: Date V | C25: N° Conteneur | D25: AN° Scellé | E25: NO° Scellé | F25: Vol
A26: 1 | B26: 8062026 | C26: TCLU524573 /0 | D26: L7031848 | E26: 3831 | F26: 40
A27: 2 | B27: 8062026 | C27: ARKU836347 /2 | D27: B1817711 | E27: 3834 | F27: 40
A28: 3 | B28: 8062026 | C28: ARKU839751 /2 | D28: B1817720 | E28: 3801 | F28: 40
A29: 4 | B29: 8062026 | C29: ARKU842490 /0 | D29: B1817714 | E29: 3833 | F29: 40
A30: 5 | B30: 8062026 | C30: ARKU844906 /7 | D30: B1817707 | E30: 3756 | F30: 40
A31: 6 | B31: 8062026 | C31: ARKU845462 /8 | D31: B1817608 | E31: 3753 | F31: 40
A32: 7 | B32: 8062026 | C32: ARKU848063 /2 | D32: B1817604 | E32: 3809 | F32: 40
A33: 8 | B33: 8062026 | C33: ARKU848127 /0 | D33: B1817607 | E33: 3754 | F33: 40
A34: 9 | B34: 8062026 | C34: ARKU849386 /1 | D34: B1817710 | E34: 3804 | F34: 40
A35: 10 | B35: 8062026 | C35: ARKU853517 /0 | D35: B1817706 | E35: 3755 | F35: 40
A36: 11 | B36: 8062026 | C36: ARKU854007 /4 | D36: B1817713 | E36: 3803 | F36: 40
A37: 12 | B37: 8062026 | C37: ARKU854125 /5 | D37: B1817603 | E37: 3760 | F37: 40
... A49: 24 | B49: 8062026 | C49: MRKU332531 /7 | D49: ML-CN6153407 | E49: 3820 | F49: 40

Sheet 09-06
H1: =COUNTIF(C8:C47,"<>") -> 36 | I1: TC
F2: =COUNTIFS(B57:B61,"<>",C57:C61,"VH") -> 0 | G2: VH | H2: =COUNTA(C57:C61)-F2 -> 0 | I2: TC | J2: =COUNTIF(E19:E27,"VIDE") -> 0
A3: FICHE DE MOUVEMENT
B5: RECEPTION | G5: 44720
A7: N° | B7: N° CRN | C7: Date R | D7: N° Conteneur | E7: N° Scellé | F7: Vol
A8: 1 | B8: 129ICS0173 | C8: 46182 | D8: CAAU623335 /4 | E8: M5176915 | F8: 40
A9: 2 | B9: 129ICS0053 | C9: 46182 | D9: APHU738346 /4 | E9: M8314725 | F9: 40
A10: 3 | C10: 46182 | D10: APZU445159 /4 | E10: M8098826 | F10: 40
A11: 4 | C11: 46182 | D11: BMOU643970 /7 | E11: M8803623 | F11: 40
A12: 5 | C12: 46182 | D12: CAAU835917 /2 | E12: M8801870 | F12: 40
A13: 6 | C13: 46182 | D13: CMAU360083 /1 | E13: M8803451 | F13: 40
A14: 7
A15: 8 | C15: 46182 | D15: CMAU654785 /4 | E15: M8096110 | F15: 40
A16: 9 | C16: 46182 | D16: FSCU714396 /0 | E16: M8096204 | F16: 40
A17: 10 | C17: 46182 | D17: GAOU683187 /2 | E17: M8096072 | F17: 40
A18: 11 | C18: 46182 | D18: GESU657116 /7 | E18: M8801715 | F18: 40
A19: 12 | C19: 46182 | D19: HPCU472969 /7 | E19: M8096170 | F19: 40
A20: 13
A21: 14 | C21: 46182 | D21: SEGU400772 /2 | E21: M8096063 | F21: 40
A22: 15 | C22: 46182 | D22: SEGU538785 /9 | E22: M8314744 | F22: 40
A23: 16 | C23: 46182 | D23: TCKU411038 /9 | E23: M8098945 | F23: 40
A24: 17 | C24: 46182 | D24: TCLU151445 /0 | E24: M8801677 | F24: 40
A25: 18 | C25: 46182 | D25: TCLU429361 /0 | E25: M8098857 | F25: 40
A26: 19 | C26: 46182 | D26: TCLU978302 /9 | E26: M8096156 | F26: 40
A27: 20 | C27: 46182 | D27: TCNU469131 /2 | E27: M8798566 | F27: 40
A28: 21 | C28: 46182 | D28: TCNU613965 /8 | E28: M8314642 | F28: 40
A29: 22 | C29: 46182 | D29: TRHU720519 /3 | E29: M8803420 | F29: 40
A30: 23 | C30: 46182 | D30: TRHU826611 /0 | E30: M8801885 | F30: 40
A31: 24 | B31: 129ICS0283 | C31: 46182 | D31: CAIU818783 /6 | E31: 403430 | F31: 40
A32: 25 | C32: 46182 | D32: CAIU819501 /9 | E32: 403420 | F32: 40
A33: 26 | C33: 46182 | D33: CAXU959721 /0 | E33: 207502 | F33: 40
A34: 27 | C34: 46182 | D34: CRSU928503 /0 | E34: HLD2681836 | F34: 40
A35: 28 | C35: 46182 | D35: CXDU134311 /3 | E35: 482341 | F35: 40
A36: 29 | C36: 46182 | D36: CXDU168050 /0 | E36: 482345 | F36: 40
A37: 30 | C37: 46182 | D37: FCGU198565 /0 | E37: 403418 | F37: 40
A38: 31
A39: 32 | C39: 46182 | D39: GESU661177 /9 | E39: 534715 | F39: 40
A40: 33 | C40: 46182 | D40: HJMU133346 /2 | E40: 482343 | F40: 40
A41: 34 | C41: 46182 | D41: HJMU152689 /9 | E41: 403415 | F41: 40
A42: 35 | C42: 46182 | D42: SEGU466432 /6 | E42: 403425 | F42: 40
...

Sheet 10-06
H1: =COUNTIF(C8:C12,"<>") -> 5 | I1: TC
F2: =COUNTIFS(B21:B32,"<>",C21:C32,"VH") -> 7 | G2: VH | H2: =COUNTA(C21:C32)-F2 -> 5 | I2: TC | J2: =COUNTIF(E21:E32,"VIDE") -> 2
A3: FICHE DE MOUVEMENT
B5: RECEPTION | F5: Date | G5: 44721
A7: N° | B7: N° CRN | C7: Date R | D7: N° Conteneur | E7: N° Scellé | F7: Vol | G7: Depotage
A8: 1 | B8: 094ICS0138 /4 | C8: 46183 | D8: TGBU754937 /0 | E8: FJ26674934 | F8: GROUPAGE | G8: 44736
A9: 2 | B9: 129ICS0053 | C9: 46183 | D9: CMAU596402 /5 | E9: M8096127 | F9: 40
A10: 3 | C10: 46183 | D10: MAGU572975 /1 | E10: M8096071 | F10: 40
A11: 4 | B11: 129ICS0283 | C11: 46183 | D11: GESU575475 /4 | E11: 403411 | F11: 40
A12: 5 | C12: 46183 | D12: TEXU895077 /6 | E12: FLAT | F12: 40
B18: SORTIE
A20: N° | B20: Date S | C20: IMM | D20: N° Conteneur | E20: N° Scellé | F20: Vol
A21: 1 | B21: 10062026 | C21: 00616-503-46 | D21: CMAU022946 /0 | E21: 3789 | F21: 20
A22: 2 | B22: 10062026 | C22: 00045-506-46 | D22: FCIU306003 /3 | E22: 3781 | F22: 20
A23: 3 | B23: 10062026 | C23: 00397-503-31 | D23: WTLU500068 /8 | E23: 3782 | F23: 40
A24: 4 | B24: 10062026 | C24: 011945-504-34 | D24: HMMU634396 /4 | E24: VIDE | F24: 40
A25: 5 | B25: 10062026 | C25: 00427-504-31 | D25: HMMU462640 /9 | E25: VIDE | F25: 40
A26: 6 | B26: 10062026 | C26: VH | D26: LB3762--841488 | E26: GEELY
A27: 7 | B27: 10062026 | C27: VH | D27: LLV--XS--22543 | E27: LIVAN
A28: 8 | B28: 10062026 | C28: VH | D28: LB3762--841500 | E28: GEELY
A29: 9 | B29: 10062026 | C29: VH | D29: LB3762--800155 | E29: GEELY
A30: 10 | B30: 10062026 | C30: VH | D30: LB3762--800156 | E30: GEELY
A31: 11 | B31: 10062026 | C31: VH | D31: LB3762--800305 | E31: GEELY
A32: 12 | B32: 10062026 | C32: VH | D32: LB3762--800493 | E32: GEELY
B34: VISITE
A36: N° | B36: Date V | C36: N° Conteneur | D36: AN° Scellé | E36: NO° Scellé | F36: Vol
A37: 1 | B37: 10062026 | C37: ARKU833224 /0 | D37: 065254 | E37: 3837 | F37: 40
A38: 2 | B38: 10062026 | C38: ARKU854822 /3 | D38: 015868 | E38: 3838 | F38: 40
A39: 3 | B39: 10062026 | C39: ARKU858731 /7 | D39: B2176368 | E39: 3839 | F39: 40
A40: 4 | B40: 10062026 | C40: CAIU904854 /2 | D40: B3916841 | E40: 3791 | F40: 40
A41: 5 | B41: 10062026 | C41: FFAU252344 /8 | D41: B3916632 | E41: 3792 | F41: 40
A42: 6 | B42: 10062026 | C42: FFAU378505 /5 | D42: B3916714 | E42: 3793 | F42: 40
A43: 7 | B43: 10062026 | C43: MSDU782251 /3 | D43: B3916633 | E43: 3794 | F43: 40
A44: 8 | B44: 10062026 | C44: MSDU875862 /0 | D44: B3916713 | E44: 3795 | F44: 40
A45: 9 | B45: 10062026 | C45: MSMU897335 /7 | D45: B3916631 | E45: 3796 | F45: 40
A46: 10 | B46: 10062026 | C46: TCNU892435 /1 | D46: B3915842 | E46: 3797 | F46: 40
A47: 11 | B47: 10062026 | C47: UETU568729 /4 | D47: B3916712 | E47: 3798 | F47: 40
A48: 11 | B48: 10062026 | C48: ECMU538854 /0 | D48: M5138037 | E48: 3799 | F48: 40

Sheet 11-06
H1: =COUNTIF(C8:C12,"<>") -> 0 | I1: TC
F2: =COUNTIFS(B19:B28,"<>",C19:C28,"VH") -> 0 | G2: VH | H2: =COUNTA(C19:C28)-F2 -> 9 | I2: TC | J2: =COUNTIF(E19:E27,"VIDE") -> 3
A3: FICHE DE MOUVEMENT
B5: RECEPTION | F5: Date | G5: 44722
A7: N° | B7: N° CRN | C7: Date R | D7: N° Conteneur | E7: N° Scellé | F7: Vol
B16: SORTIE
A18: N° | B18: Date S | C18: IMM | D18: N° Conteneur | E18: N° Scellé | F18: Vol
A19: 1 | B19: 11062026 | C19: 00177-512-31 | D19: ARKU858731 /7 | E19: 3839 | F19: 40
A20: 2 | B20: 11062026 | C20: 00634-509-31 | D20: ARKU833224 /0 | E20: 3837 | F20: 40
A21: 3 | B21: 11062026 | C21: 00436-509-31 | D21: ARKU854822 /3 | E21: 3838 | F21: 40
A22: 4 | B22: 10062026 | C22: 01391-590-31 | D22: HMMU905523 /6 | E22: VIDE | F22: 45
A23: 5 | B23: 10062026 | C23: 01391-590-31 | D23: HMMU902388 /2 | E23: VIDE | F23: 45
A24: 6 | B24: 10062026 | C24: 01391-590-31 | D24: HMMU906728 /4 | E24: VIDE | F24: 45
A25: 7 | B25: 10062026 | C25: 50001-505-31 | D25: TRHU763561 /4 | E25: 3784 | F25: 40
A26: 8 | B26: 10062026 | C26: 000103-514-13 | D26: CMAU983583 /3 | E26: 3814 | F26: 40
A27: 9 | B27: 10062026 | C27: 00546-510-31 | D27: CMAU983624 /9 | E27: 3815 | F27: 40
B30: VISITE
A32: N° | B32: Date V | C32: N° Conteneur | D32: AN° Scellé | E32: NO° Scellé | F32: Vol
A33: 1 | B33: 10062026 | C33: VH | D33: LB3762---X612489 | E33: GEELY EMGR
A34: 2 | B34: 10062026 | C34: VH | D34: LB3762---X624174 | E34: GEELY EMGR
A35: 3 | B35: 10062026 | C35: VH | D35: LB3782----RB027979 | E35: GEELY BOY

Sheet 14-06
H1: =COUNTIF(C8:C12,"<>") -> 3 | I1: TC
F2: =COUNTIFS(B16:B28,"<>",C16:C28,"VH") -> 0 | G2: VH | H2: =COUNTA(C16:C29)-F2 -> 13 | I2: TC | J2: =COUNTIF(E19:E27,"VIDE") -> 0
A3: FICHE DE MOUVEMENT
B5: RECEPTION | F5: Date | G5: 44725
A7: N° | B7: N° CRN | C7: Date R | D7: N° Conteneur | E7: N° Scellé | F7: Vol
A8: 1 | B8: 00400ICS0009 | C8: 46187 | D8: KOCU444962 /9 | E8: 25H1283786 | F8: 40
A9: 2 | B9: 0090ICS0255 | C9: 46187 | D9: MSMU709369 /7 | E9: FJ27472011 | F9: 40
A10: 3 | C10: 46187 | D10: MSNU770695 /6 | E10: FJ27188416 | F10: 40
B13: SORTIE
A15: N° | B15: Date S | C15: IMM | D15: N° Conteneur | E15: N° Scellé | F15: Vol
A16: 1 | B16: 14062026 | C16: 002587-510-16 | D16: CMAU752750 /7 | E16: 3812 | F16: 40
A17: 2 | B17: 14062026 | C17: 000355-514-35 | D17: CMAU983077 /0 | E17: 3813 | F17: 40
A18: 3 | B18: 14062026 | C18: 002296-508-16 | D18: ECMU545635 /1 | E18: 3816 | F18: 40
A19: 4 | B19: 14062026 | C19: 00780-508-16 | D19: TCNU331174 /2 | E19: 3819 | F19: 45
A20: 5 | B20: 14062026 | C20: 000349-509-35 | D20: ECMU538854 /0 | E20: 3799 | F20: 45
A21: 6 | B21: 14062026 | C21: 00359-515-31 | D21: TLLU438973 /0 | E21: G0329224 | F21: 45
A22: 7 | B22: 14062026 | C22: 00036-520-31 | D22: TGBU709287 /4 | E22: G0329228 | F22: 40
A23: 8 | B23: 14062026 | C23: 00015-517-31 | D23: CMAU951622 /4 | E23: G0329225 | F23: 40
A24: 9 | B24: 14062026 | C24: 00161-509-31 | D24: SEKU566632 /8 | E24: G0329227
A25: 10 | B25: 14062026 | C25: 00020-520-31 | D25: TCNU111354 /6 | E25: G0329763
A26: 11 | B26: 14062026 | C26: 00426-510-31 | D26: SEKU566988 /3 | E26: G039765
A27: 12 | B27: 14062026 | C27: 00183-524-31 | D27: FFAU494559 /0 | E27: G0329762
A28: 13 | B28: 14062026 | C28: 00303-517-31 | D28: SEGU422145 /7 | E28: G0322498 | F28: 40
B31: VISITE
A33: N° | B33: Date V | C33: N° Conteneur | D33: AN° Scellé | E33: NO° Scellé | F33: Vol
A34: 1 | B34: 14062026 | C34: VH | D34: LSVY460---2089464 | E34: TIGUAN
A35: 2 | B35: 14062026 | C35: TRLU758317 /0 | D35: FX46390025 | E35: 3879
A36: 3 | B36: 14062026 | C36: CAIU449713 /4 | D36: FJ19647907 | E36: 3875
A37: 4 | B37: 14062026 | C37: MSBU680032 /2 | D37: FJ19647909 | E37: 3874
A38: 5 | B38: 14062026 | C38: MSDU597111 /7 | D38: FJ19647904 | E38: 3873
A39: 6 | B39: 14062026 | C39: MSMU85191 /3 | D39: FJ19647906 | E39: 3876
A40: 7 | B40: 14062026 | C40: MSNU913023 /7 | D40: FJ19647910 | E40: 3872
A41: 8 | B41: 14062026 | C41: TRHU792640 /9 | D41: FJ19647908 | E41: 3877
A42: 9 | B42: 14062026 | C42: UETU676536 /5 | D42: FJ19647905 | E42: 3871
A43: 10 | B43: 14062026 | C43: DFSU723583 /9 | D43: M8842227 | E43: 3878
A44: 11 | B44: 14062026 | C44: FCIU409524 /1 | D44: M8097350 | E44: 3880
A45: 12 | B45: 14062026 | C45: MSMU922668 /0 | D45: FJ27211605 | E45: 3800

Sheet 15-06
H1: =COUNTIF(C8:C10,"<>") -> 2 | I1: TC
F2: =COUNTIFS(B16:B44,"<>",C16:C44,"VH") -> 8 | G2: VH | H2: =COUNTA(C16:C44)-F2 -> 21 | I2: TC | J2: =COUNTIF(E16:E44,"VIDE") -> 0
A3: FICHE DE MOUVEMENT
B5: RECEPTION | F5: Date | G5: 44726
A7: N° | B7: N° CRN | C7: Date R | D7: N° Conteneur | E7: N° Scellé | F7: Vol
B8: 0461ICS0222 | C8: 15062026 | D8: ECMU809626 /4 | E8: M8733025
C9: 15062026 | D9: TCKU997977 /6 | E9: M9775850
B13: SORTIE
A15: N° | B15: Date S | C15: IMM | D15: N° Conteneur | E15: N° Scellé | F15: Vol
A16: 1 | B16: 15062026 | C16: 00701-509-31 | D16: ARKU855709 /8 | E16: 3810
A17: 2 | B17: 15062026 | C17: 00177-512-31 | D17: ARKU853517 /0 | E17: 3755
A18: 3 | B18: 15062026 | C18: 02255-585-31 | D18: ARKU848063 /2 | E18: 3809
A19: 4 | B19: 15062026 | C19: 00108-515-31 | D19: TCNU648361 /6 | E19: 3757
A20: 5 | B20: 15062026 | C20: 00068-515-31 | D20: ARKU8306976 | E20: 3807
A21: 6 | B21: 15062026 | C21: 00400-516-31 | D21: ARKU848127 /0 | E21: 3754
A22: 7 | B22: 15062026 | C22: 00066-515-31 | D22: ARKU854125 /5 | E22: 3760
A23: 8 | B23: 15062026 | C23: 00371-511-31 | D23: ARKU836347 /2 | E23: 3834
A24: 9 | B24: 15062026 | C24: 000-91-511-31 | D24: ARKU849386 /1 | E24: 3804
A25: 10 | B25: 15062026 | C25: 00133-515-31 | D25: ARKU854007 /4 | E25: 3803
A26: 11 | B26: 15062026 | C26: 00005-511-31 | D26: ARKU855647 /1 | E26: 3759
A27: 12 | B27: 15062026 | C27: 00546-510-31 | D27: TRLU758317 /0 | E27: 3879
... A35: 20 | B35: 15062026 | C35: 00546-509-31 | D35: UETU568729 /4 | E35: 3798
A36: 21 | B36: 15062026 | C36: 000695-518-16 | D36: CMAU369780 /3 | E36: CV 000126
A37: 22 | B37: 15062026 | C37: VH | D37: LB37---TX803831 | E37: GELLY COOLR
A38: 23 | B38: 15062026 | C38: VH | D38: LB37---SX851686 | E38: GELLY COOLR
A39: 24 | B39: 15062026 | C39: VH | D39: LB37---SX851675 | E39: GELLY COOLR
A40: 25 | B40: 15062026 | C40: VH | D40: LB37---TX804425 | E40: GELLY COOLR
A41: 26 | B41: 15062026 | C41: VH | D41: LB37---TX803549 | E41: GELLY COOLR
A42: 27 | B42: 15062026 | C42: VH | D42: LB37---TX803426 | E42: GELLY COOLR
A43: 28 | B43: 15062026 | C43: VH | D43: LB37---TX803586 | E43: GELLY COOLR
A44: 29 | B44: 15062026 | C44: VH | D44: LB37---TX801556 | E44: GELLY COOLR
B46: VISITE
A48: N° | B48: Date V | C48: N° Conteneur | D48: AN° Scellé | E48: NO° Scellé | F48: Vol
A49: 1 | B49: 15062026 | C49: MSNU371507 /6 | D49: LG00206277 | E49: 3861
A50: 2 | B50: 15062026 | C50: FFAU186123 /8 | D50: 11101 | E50: 3862

Sheet 17-06
H1: =COUNTIF(C9:C11,"<>") -> 0 | I1: TC
F2: =COUNTIFS(B17:B35,"<>",C17:C35,"VH") -> 0 | G2: VH | H2: =COUNTA(C17:C35)-F2 -> 12 | I2: TC | J2: =COUNTIF(E17:E32,"VIDE") -> 0
A4: FICHE DE MOUVEMENT
B6: RECEPTION | F6: Date | G6: 44728
A8: N° | B8: N° CRN | C8: Date R | D8: N° Conteneur | E8: N° Scellé | F8: Vol
B14: SORTIE
A16: N° | B16: Date S | C16: IMM | D16: N° Conteneur | E16: N° Scellé | F16: Vol
A17: 1 | B17: 17062026 | C17: 00701-509-31 | D17: DRYU962778 /2 | E17: 3808 | F17: 40
A18: 2 | B18: 17062026 | C18: 00005-511-31 | D18: ARKU830587 /7 | E18: 3805 | F18: 40
A19: 3 | B19: 17062026 | C19: 02255-585-31 | D19: ARKU845462 /8 | E19: 3753 | F19: 40
A20: 4 | B20: 17062026 | C20: 00108-515-31 | D20: ARKU832040 /2 | E20: 3806 | F20: 40
A21: 5 | B21: 17062026 | C21: 00094-511-31 | D21: ARKU844906 /7 | E21: 3756 | F21: 40
A22: 6 | B22: 17062026 | C22: 00068-515-31 | D22: DRYU913819 /0 | E22: 3802 | F22: 40
A23: 7 | B23: 17062026 | C23: 00066-515-31 | D23: ARKU834573 /5 | E23: 3752 | F23: 40
A24: 8 | B24: 17062026 | C24: 00371-511-31 | D24: TCNU646174 /6 | E24: 3751 | F24: 40
A25: 9 | B25: 17062026 | C25: 00067-515-31 | D25: ARKU839751 /2 | E25: 3801 | F25: 40
A26: 10 | B26: 17062026 | C26: 00385-516-31 | D26: ARKU842490 /0 | E26: 3833 | F26: 40
A27: 11 | B27: 17062026 | C27: 00400-516-31 | D27: ARKU856690 /5 | E27: 3758 | F27: 40
A28: 12 | B28: 17062026 | C28: 00693-509-31 | D28: MSNU371507 /6 | E28: 3861 | F28: 40
A29: 13
A30: 14
A31: 25
A32: 26
A33: 27
A34: 28
A35: 29
B37: VISITE
A39: N° | B39: Date V | C39: N° Conteneur | D39: AN° Scellé | E39: NO° Scellé | F39: Vol
A40: 1 | B40: 17062026 | C40: MSCU548664 /8 | E40: 3866 | F40: 40
A41: 2 | B41: 17062026 | C41: BLTU211 703 /6 | E41: 3864 | F41: 20
A42: 3 | B42: 17062026 | C42: NLLU200463 /9 | E42: 3863 | F42: 20

Sheet 18-06
H1: =COUNTIF(C9:C21,"<>") -> 10 | I1: TC
F2: =COUNTIFS(B27:B35,"<>",C27:C35,"VH") -> 0 | G2: VH | H2: =COUNTA(C27:C35)-F2 -> 1 | I2: TC | J2: =COUNTIF(E27:E35,"VIDE") -> 0
A4: FICHE DE MOUVEMENT
B6: RECEPTION | F6: Date | G6: 44729
A8: N° | B8: N° CRN | C8: Date R | D8: N° Conteneur | E8: N° Scellé | F8: Vol
A9: 1 | B9: 00049ICS0053 | C9: 18062026 | D9: SEKU444471 /1 | E9: ML-CN6393039 | F9: 40
A10: 2 | B10: 0049ICS0062 | C10: 18062026 | D10: MRSU542442 /0 | E10: ML-CN6393033 | F10: 40
A11: 3 | B11: 0091ICS0031 | C11: 18062026 | D11: FFAU305208 /4 | E11: HB368401 | F11: 40
A12: 4 | B12: 0049ICS0106 | C12: 18062026 | D12: MRKU355546 /0 | E12: ML-CN7825456 | F12: 40
A13: 5 | C13: 18062026 | D13: MRSU331904 /5 | E13: ML-CN7825573 | F13: 40
A14: 6 | B14: 00491CS0124 | C14: 18062026 | D14: MRKU503755 /7 | E14: ML-CN6216316 | F14: 40
A15: 7 | B15: 0049ICS0140 | C15: 18062026 | D15: MRKU660441 /8 | E15: ML-CN4852480 | F15: 20
A16: 8 | C16: 18062026 | D16: MRKU719113 /4 | E16: ML-CN4852491 | F16: 20
A17: 9 | B17: 0049ICS0151 | C17: 18062026 | D17: MRSU723163 /0 | E17: ML-CN2470218 | F17: 40
A18: 10 | C18: 18062026 | D18: TGHU692335 /8 | E18: ML-CN3206831 | F18: 40
B24: SORTIE
A26: N° | B26: Date S | C26: IMM | D26: N° Conteneur | E26: N° Scellé | F26: Vol
A27: 1 | B27: 18062026 | C27: 00188-513-31 | D27: TCLU524573 /0 | E27: 3831
A28: 2
A29: 3
A30: 4
A31: 5
A32: 6
A33: 27
A34: 28
A35: 29
B37: VISITE
A39: N° | B39: Date V | C39: N° Conteneur | D39: AN° Scellé | E39: NO° Scellé | F39: Vol

Sheet 21-06
H1: =COUNTIF(C9:C18,"<>") -> 2 | I1: TC
F2: =COUNTIFS(B24:B32,"<>",C24:C32,"VH") -> 0 | G2: VH | H2: =COUNTA(C24:C32)-F2 -> 6 | I2: TC | J2: =COUNTIF(E19:E24,"VIDE") -> 0
A4: FICHE DE MOUVEMENT
B6: RECEPTION | F6: Date | G6: 44732
A8: N° | B8: N° CRN | C8: Date R | D8: N° Conteneur | E8: N° Scellé | F8: Vol
A9: 1 | B9: 0094ICS0164 | C9: 46194 | D9: CAIU763401 /4 | E9: FJ27816923 | F9: 40
A10: 2 | B10: 0094ICS0079 | C10: 46194 | D10: MEDU744845 /3 | E10: FX46376357 | F10: 40
A11: 3
A12: 4
A13: 5
A14: 6
A15: 7
A16: 8
A17: 9
A18: 10
B21: SORTIE
A23: N° | B23: Date S | C23: IMM | D23: N° Conteneur | E23: N° Scellé | F23: Vol
A24: 1 | B24: 21062026 | C24: 00245-514-31 | D24: CMAU687016 /8 | E24: 3840 | F24: 40
A25: 2 | B25: 21062026 | C25: 00296-515-31 | D25: TIIU285146 /8 | E25: M1840507 | F25: 20
A26: 3 | B26: 21062026 | C26: 00296-515-31 | D26: TIIU285215 /0 | E26: M1840510 | F26: 20
A27: 4 | B27: 21062026 | C27: 00020-520-31 | D27: CNEU451134 /3 | E27: 3835 | F27: 45
A28: 5 | B28: 21062026 | C28: 00359-515-31 | D28: CNEU451268 /0 | E28: 3832 | F28: 45
A29: 6 | B29: 21062026 | C29: 00161-509-31 | D29: TDRU102072 /3 | E29: 3836 | F29: 45
A30: 27
A31: 28
A32: 29
B34: VISITE
A36: N° | B36: Date V | C36: AN° Scellé | D36: N° Conteneur | E36: NO° Scellé | F36: Vol

Sheet 22-06
H1: =COUNTIF(C9:C18,"<>") -> 0 | I1: TC
F2: =COUNTIFS(B24:B32,"<>",C24:C32,"VH") -> 0 | G2: VH | H2: =COUNTA(C24:C32)-F2 -> 0 | I2: TC | J2: =COUNTIF(E19:E24,"VIDE") -> 0
A4: FICHE DE MOUVEMENT
B6: RECEPTION | F6: Date | G6: 44733
A8: N° | B8: N° CRN | C8: Date R | D8: N° Conteneur | E8: N° Scellé | F8: Vol
A9: 1
A10: 2
A11: 3
A12: 4
A13: 5
A14: 6
A15: 7
A16: 8
A17: 9
A18: 10
B21: SORTIE
A23: N° | B23: Date V | C23: IMM | D23: N° Conteneur | E23: N° Scellé | F23: Vol
A30: 27
A31: 28
A32: 29
B34: VISITE
A36: N° | B36: Date | C36: N° Conteneur | D36: AN° Scellé | E36: NO° Scellé | F36: Vol
A37: 1 | B37: 22062026 | C37: CAAU845506 /8 | D37: CN5024551 | E37: 3865 | F37: 40

Sheet 23-06
H1: =COUNTIF(C9:C18,"<>") -> 1 | I1: TC
F2: =COUNTIFS(B24:B32,"<>",C24:C32,"VH") -> 0 | G2: VH | H2: =COUNTA(C24:C32)-F2 -> 2 | I2: TC | J2: =COUNTIF(E24:E29,"VIDE") -> 0
A4: FICHE DE MOUVEMENT
B6: RECEPTION | F6: Date | G6: 44734
A8: N° | B8: N° CRN | C8: Date R | D8: N° Conteneur | E8: N° Scellé | F8: Vol | G8: Depotage
A9: 1 | B9: 00515ICS0023 /4 | C9: 46196 | D9: TRHU606329 /0 | E9: M9155713 | F9: GROUPAGE | G9: 44736
A10: 2
A11: 3
A12: 4
A13: 5
A14: 6
A15: 7
A16: 8
A17: 9
A18: 10
B21: SORTIE
A23: N° | B23: Date S | C23: IMM | D23: N° Conteneur | E23: N° Scellé | F23: Vol
A24: 1 | B24: 23062026 | C24: 00554-514-31 | D24: BMOU480435 /4 | E24: 2729853 | F24: 40
A25: 2 | B25: 23062026 | C25: 00299-513-31 | D25: MSNU726467 /0 | E25: 2697175 | F25: 40
A30: y
B34: VISITE
A36: N° | B36: Date V | C36: N° Conteneur | D36: AN° Scellé | E36: NO° Scellé | F36: Vol
A37: 1 | B37: 23062026 | C37: TDRU461667 /6 | D37: LB0232420 | E37: 3867 | F37: 40

Sheet 24-06
H1: =COUNTIF(C9:C16,"<>") -> 0 | I1: TC
F2: =COUNTIFS(B22:B32,"<>",C22:C32,"VH") -> 3 | G2: VH | H2: =COUNTA(C22:C32)-F2 -> 8 | I2: TC | J2: =COUNTIF(E22:E27,"VIDE") -> 0
A4: FICHE DE MOUVEMENT
B6: RECEPTION | F6: Date | G6: 44735
G7: 3
A8: N° | B8: N° CRN | C8: Date R | D8: N° Conteneur | E8: N° Scellé | F8: Vol
A9: 1
A10: 2
A11: 3
A12: 4
A13: 5
A14: 6
A15: 7
A16: 8
B19: SORTIE
A21: N° | B21: Date S | C21: IMM | D21: N° Conteneur | E21: N° Scellé | F21: Vol
A22: 1 | B22: 24062026 | C22: 02053-587-31 | D22: CAAU845506 /8 | E22: 3865 | F22: 40
A23: 2 | B23: 24062026 | C23: 02175-588-31 | D23: CAIU449713 /4 | E23: 3875 | F23: 40
A24: 3 | B24: 24062026 | C24: 03055-586-05 | D24: MSBU680032 /2 | E24: 3874 | F24: 40
A25: 4 | B25: 24062026 | C25: 04510-584-05 | D25: MSDU597111 /7 | E25: 3873 | F25: 40
A26: 5 | B26: 24062026 | C26: 00508-513-31 | D26: MSMU885191 /3 | E26: 3876 | F26: 40
A27: 6 | B27: 24062026 | C27: 00406-505-31 | D27: MSNU913023 /7 | E27: 3872 | F27: 40
A28: 7 | B28: 24062026 | C28: 007711-594-28 | D28: TRHU792640 /9 | E28: 3877 | F28: 40
A29: 8 | B29: 24062026 | C29: 000106-512-05 | D29: UETU676536 /5 | E29: 3871 | F29: 40
B30: 24062026 | C30: VH | D30: LB37-RB027979 | E30: GELLY BOY
B31: 24062026 | C31: VH | D31: LB37-PX624174 | E31: GELLY EMGR
B32: 24062026 | C32: VH | D32: LB37-PX612489 | E32: GELLY EMGR
B34: VISITE
A36: N° | B36: Date V | C36: N° Conteneur | D36: AN° Scellé | E36: NO° Scellé | F36: Vol
A37: 1 | B37: 24062026 | C37: TLLU202937 /6 | D37: M4602286 | E37: 3870
A38: 2 | B38: 24062026 | C38: TTNU529736 /9 | D38: FX45356147 | E38: 3868
A39: 3 | B39: 24062026 | C39: FFAU670430 /8 | D39: CN5318408 | E39: 3869

Sheet 28-06
H1: =COUNTIF(C9:C18,"<>") -> 3 | I1: TC
F2: =COUNTIFS(B24:B34,"<>",C24:C34,"VH") -> 0 | G2: VH | H2: =COUNTA(C24:C34)-F2 -> 1 | I2: TC | J2: =COUNTIF(E24:E29,"VIDE") -> 0
A4: FICHE DE MOUVEMENT
B6: RECEPTION | F6: Date | G6: 44739
A8: N° | B8: N° CRN | C8: Date R | D8: N° Conteneur | E8: N° Scellé | F8: Vol
A9: 1 | B9: 00100ICS0090 | C9: 28062026 | D9: DRYU939251 /7 | E9: LG00557484 | F9: 40
A10: 2 | C10: 28062026 | D10: FDCU009891 /5 | E10: LG00557480 | F10: 40
A11: 3 | B11: 00161ICS0039 | C11: 28062026 | D11: FFAU519002 /0 | E11: 2103860 | F11: 40
A12: 4
B21: SORTIE
A23: N° | B23: Date S | C23: IMM | D23: N° Conteneur | E23: N° Scellé | F23: Vol
A24: 1 | B24: 28062026 | C24: 00037-517-31 | D24: MSCU548664 /8 | E24: 3866 | F24: 40
A25: 2
A26: 3
A27: 4
A28: 5
A29: 6
A30: 7
A31: 8
B36: VISITE
A38: N° | B38: Date V | C38: N° Conteneur | D38: AN° Scellé | E38: NO° Scellé | F38: Vol
A39: 1 | B39: 28062026 | C39: MSBU531205 /1 | D39: 1021713 | E39: 3882
A40: 2 | B40: 28062026 | C40: MSBU642243 /0 | D40: 1021714 | E40: 3881
A41: 3

Sheet 29-06
H1: =COUNTIF(C9:C22,"<>") -> 14 | I1: TC
F2: =COUNTIFS(B28:B38,"<>",C28:C38,"VH") -> 0 | G2: VH | H2: =COUNTA(C28:C38)-F2 -> 10 | I2: TC | J2: =COUNTIF(E28:E33,"VIDE") -> 0
A4: FICHE DE MOUVEMENT
B6: RECEPTION | F6: Date | G6: 44740
A8: N° | B8: N° CRN | C8: Date R | D8: N° Conteneur | E8: N° Scellé | F8: Vol | G8: Depotage
A9: 1 | B9: 0054ICS0048 | C9: 29062026 | D9: INKU631078 /8 | E9: CN4478941 | F9: 40
A10: 2 | B10: 0030ICS0023 | C10: 29062026 | D10: CAXU980455 /4 | E10: LB0263348 | F10: 40
A11: 3 | C11: 29062026 | D11: HPCU401947 /9 | E11: LB0263349 | F11: 40
A12: 4 | C12: 29062026 | D12: LCGU800158 /0 | E12: LB0263393 | F12: 40
A13: 5 | B13: 0054ICS0010 | C13: 29062026 | D13: TRHU306828 /2 | E13: CN2729087 | F13: 40
A14: 6 | B14: 00174ICS0113 /4 | C14: 29062026 | D14: TCLU977933 /2 | E14: M9155713 | F14: GROUPAGE | G14: 44749
A15: 7 | B15: 00174ICS0114 /4 | C15: 29062026 | D15: TCLU188522 /0 | E15: M9147252 | F15: GROUPAGE | G15: 44749
A16: 8 | B16: 00504ICS0073 | C16: 29062026 | D16: BMOU561208 /4 | E16: M2054210 | F16: 40
A17: 9 | C17: 29062026 | D17: ECMU489993 /0 | E17: M1855651 | F17: 40
A18: 10 | C18: 29062026 | D18: SEKU622422 /8 | E18: L7765668 | F18: 40
A19: 11 | C19: 29062026 | D19: TCNU393420 /7 | E19: M1855663 | F19: 40
A20: 12 | C20: 29062026 | D20: TCNU569113 /2 | E20: M1855656 | F20: 40
A21: 13 | C21: 29062026 | D21: TCNU578406 /6 | E21: M1855653 | F21: 40
A22: 14 | C22: 29062026 | D22: TLLU893965 /0 | E22: M1855654 | F22: 40
B25: SORTIE
A27: N° | B27: Date S | C27: IMM | D27: N° Conteneur | E27: N° Scellé | F27: Vol
A28: 1 | B28: 29062026 | C28: 00439-513-31 | D28: MSBU516228 /6 | E28: KG685093 | F28: 40
A29: 2 | B29: 29062026 | C29: 00022-516-46 | D29: MSMU545978 /7 | E29: KG685094 | F29: 40
A30: 3 | B30: 29062026 | C30: 00543-510-31 | D30: TCLU263893 /9 | E30: KG685096 | F30: 20
A31: 4 | B31: 29062026 | C31: 00689-509-31 | D31: TRHU 864 899 /8 | E31: KG685091 | F31: 40
A32: 5 | B32: 29062026 | C32: 00090-508-16 | D32: ECMU663924 /9 | E32: FLAT
A33: 6 | B33: 29062026 | C33: 00206-504-27 | D33: ECMU664302 /2 | E33: FLAT
A34: 7 | B34: 29062026 | C34: 02512-515-27 | D34: TRIU081904V/3 | E34: FLAT
A35: 8 | B35: 29062026 | C35: 01696-504-27 | D35: TRIU083348 /4 | E35: FLAT
A36: 9 | B36: 29062026 | C36: 00356-516-31 | D36: TLUU202937 /6 | E36: 3870 | F36: 20
B37: 29062026 | C37: 00177-512-31 | D37: TTNU529736 /9 | E37: 3868 | F37: 40
B40: VISITE
A42: N° | B42: Date V | C42: N° Conteneur | D42: AN° Scellé | E42: NO° Scellé | F42: Vol
A43: 1 | B43: 29062026 | C43: MRSU426341 /8 | D43: ML-CN4925144 | E43: 3883 | F43: 40

Sheet 30-06
H1: =COUNTIF(C9:C16,"<>") -> 0 | I1: TC
F2: =COUNTIFS(B22:B32,"<>",C22:C32,"VH") -> 0 | G2: VH | H2: =COUNTA(C22:C32)-F2 -> 2 | I2: TC | J2: =COUNTIF(E22:E27,"VIDE") -> 0
A4: FICHE DE MOUVEMENT
B6: RECEPTION | F6: Date | G6: 44741
A8: N° | B8: N° CRN | C8: Date R | D8: N° Conteneur | E8: N° Scellé | F8: Vol
A9: 1
A10: 2
A11: 3
A12: 4
B19: SORTIE
A21: N° | B21: Date S | C21: IMM | D21: N° Conteneur | E21: N° Scellé | F21: Vol
A22: 1 | B22: 30062026 | C22: 00174-516-31 | D22: BLTU2117036 | E22: LB0266283
A23: 2 | B23: 30062026 | C23: 00037-517-31 | D23: NLLU2004639 | E23: LB0266286
A24: 3
A25: 4
A26: 5
A27: 6
A28: 7
A29: 8
B34: VISITE
A36: N° | B36: Date V | C36: N° Conteneur | D36: AN° Scellé | E36: NO° Scellé | F36: Vol
A37: 1 | B37: 30062026 | C37: MSMU625103 /6 | D37: 89828 | E37: 3885
A38: 2 | B38: 30062026 | C38: CMAU877794 /3 | D38: 3402422 | E38: 3887
A39: 3 | B39: 30062026 | C39: ECMU809626 /4 | D39: M8733025 | E39: 3884
A40: 4 | B40: 30062026 | C40: TCKU 997977 /6 | D40: M9775850 | E40: 3886
A41: 5 | B41: 30062026 | C41: TDRU461667 /6 | D41: 3867 | E41: 3889
A42: 6 | B42: 30062026 | C42: TDRU909110 /6 | D42: LB0232359 | E42: 3888
