Workbook

Sheet DASHBOARD
A1: Date | B1: TC Réceptionnés | C1: TC Sortis | D1: Total Mouvements | F1: TC Sortis VIDE
A2: 46236 | B2: ='02-08'!H1 -> 0 | C2: ='02-08'!H2 -> 12 | D2: =SUM(B2:C2) -> 12
A3: 46237 | B3: ='03-08'!H1 -> 0 | C3: ='03-08'!H2 -> 12 | D3: =SUM(B3:C3) -> 12
A4: 46238 | B4: ='04-08'!H1 -> 2 | C4: ='04-08'!H2 -> 2 | D4: =SUM(B4:C4) -> 4
A5: 46239 | B5: ='05-08'!H1 -> 17 | C5: ='05-08'!H2 -> 2 | D5: =SUM(B5:C5) -> 19
A6: 46240 | B6: ='06-08'!H1 -> 6 | C6: ='06-08'!H2 -> 2 | D6: =SUM(B6:C6) -> 8
A7: 46243 | B7: ='09-08'!H1 -> 2 | C7: ='09-08'!H2 -> 0 | D7: =SUM(B7:C7) -> 2
A8: 46244 | B8: ='10-08'!H1 -> 5 | C8: ='10-08'!H2 -> 12 | D8: =SUM(B8:C8) -> 17
A9: 46245 | B9: ='11-08'!H1 -> 3 | C9: ='11-08'!H2 -> 1 | D9: =SUM(B9:C9) -> 4
A10: 46246 | B10: ='12-08'!H1 -> 2 | C10: ='12-08'!H2 -> 1 | D10: =SUM(B10:C10) -> 3
A11: 46247 | B11: ='13-08'!H1 -> 0 | C11: ='13-08'!H2 -> 1 | D11: =SUM(B11:C11) -> 1
A12: 46250 | B12: ='16-08'!H1 -> 0 | C12: ='16-08'!H2 -> 2 | D12: =SUM(B12:C12) -> 2
A13: 46251 | B13: ='17-08'!L1 -> 0 | C13: ='17-08'!L2 -> 0 | D13: =SUM(B13:C13) -> 0
A14: 46252 | B14: ='18-08'!H1 -> 0 | C14: ='18-08'!H2 -> 7 | D14: =SUM(B14:C14) -> 7
A15: 46253 | B15: ='19-08'!H1 -> 5 | C15: ='19-08'!H2 -> 8 | D15: =SUM(B15:C15) -> 13
A16: 46254 | B16: ='20-08'!H1 -> 0 | C16: ='20-08'!H2 -> 4 | D16: =SUM(B16:C16) -> 4
A17: 46257 | B17: ='23-08'!H1 -> 0 | C17: ='23-08'!H2 -> 2 | D17: =SUM(B17:C17) -> 2
A18: 46258 | B18: ='24-08'!H1 -> 3 | C18: ='24-08'!H2 -> 1 | D18: =SUM(B18:C18) -> 4
A19: 46260 | B19: ='26-08'!H1 -> 3 | C19: ='26-08'!H2 -> 0 | D19: =SUM(B19:C19) -> 3
A20: 46260 | B20: ='24-08'!H3 -> 0 | C20: ='24-08'!H4 -> 0 | D20: =SUM(B20:C20) -> 0
A24: Total | B24: =SUM(B2:B23) -> 48 | C24: =SUM(C2:C23) -> 69 | D24: =SUM(D2:D23) -> 117

Sheet 02-08
H1: =COUNTIF(B10:B11,"<>") -> 0 | I1: TC
F2: =COUNTIFS(B16:B33,"<>",C16:C33,"VH") -> 0 | G2: VH | H2: =COUNTA(C16:C28)-F2 -> 12 | I2: TC | J2: =COUNTIF(H16:H21,"VIDE") -> 0
A3: FICHE DE MOUVEMENT
B5: RECEPTION | G5: 46236
A7: N° | B7: N° CRN | C7: Date R | D7: N° Conteneur | E7: N° Scellé | F7: Vol
A10: 1
A11: 8
B13: SORTIE
A15: N° | B15: Date S | C15: IMM | D15: N° Conteneur | E15: N° Scellé | F15: Vol
A16: 1 | B16: 46236 | C16: 01391-590-31 | D16: TCLU188522 /0 | E16: VIDE
A17: 2 | B17: 46236 | C17: 01391-590-31 | D17: TCLU977933 /2 | E17: VIDE
A18: 3 | B18: 46236 | C18: 00647-509-31 | D18: MSBU404538 /8 | E18: 3970 | F18: 40
A19: 4 | B19: 46236 | C19: 00568-509-31 | D19: MSBU107698 /1 | E19: 3969 | F19: 40
A20: 5 | B20: 46236 | C20: 00001-510-46 | D20: CMAU368040 /0 | E20: 3901 | F20: 40
A21: 6 | B21: 46236 | C21: 00010-510-46 | D21: ECMU493389 /2 | E21: 3902 | F21: 40
A22: 7 | B22: 46236 | C22: 0000028-524-13 | D22: ECMU523561 /7 | E22: 3903 | F22: 40
A23: 8 | B23: 46236 | C23: 000150-513-13 | D23: SEGU440329 /8 | E23: 3904 | F23: 40
A24: 9 | B24: 46236 | C24: 00002-515-20 | D24: SEKU609420 /6 | E24: 3905 | F24: 40
A25: 12 | B25: 46236 | C25: 00052-512-31 | D25: TLLU462879 /5 | E25: 3908 | F25: 40
A26: 13 | B26: 46236 | C26: 00349-513-31 | D26: TXGU442737 /0 | E26: 3909 | F26: 40
A27: 14 | B27: 46236 | C27: 000099-514-13 | D27: TXGU846880 /3 | E27: 3910 | F27: 40
A28: 15
A29: 16
B31: VISITE
A33: N° | B33: Date V | C33: N° Conteneur | D33: AN° Scellé | E33: NO° Scellé | F33: Vol
A34: 1
A35: 2
A36: 3
A37: 4
A38: 5
A39: 6
A40: 7

Sheet 03-08
H1: =COUNTIF(B10:B11,"<>") -> 0 | I1: TC
F2: =COUNTIFS(B16:B32,"<>",C16:C32,"VH") -> 0 | G2: VH | H2: =COUNTA(C16:C27)-F2 -> 12 | I2: TC | J2: =COUNTIF(E16:E21,"VIDE") -> 0
A3: FICHE DE MOUVEMENT
B5: RECEPTION | G5: 46237
A7: N° | B7: N° CRN | C7: Date R | D7: N° Conteneur | E7: N° Scellé | F7: Vol
A10: 1
A11: 8
B13: SORTIE
A15: N° | B15: Date S | C15: IMM | D15: N° Conteneur | E15: N° Scellé | F15: Vol
A16: 1 | B16: 46237 | C16: 02386-586-31 | D16: BMOU561208 /4 | E16: M2054210 | F16: 40
A17: 2 | B17: 46237 | C17: 01450-590-31 | D17: ECMU489993 /0 | E17: M1855651 | F17: 40
A18: 3 | B18: 46237 | C18: 00351-506-31 | D18: SEKU622422 /8 | E18: L7765668 | F18: 40
A19: 4 | B19: 46237 | C19: 00629-509-31 | D19: TCNU393420 /7 | E19: M1855663 | F19: 40
A20: 5 | B20: 46237 | C20: 02255-586-31 | D20: TCNU569113 /2 | E20: M1855656 | F20: 40
A21: 6 | B21: 46237 | C21: 00274-514-31 | D21: TCNU578406 /6 | E21: M1855653 | F21: 40
A22: 7 | B22: 46237 | C22: 00403-503-31 | D22: TLLU893965 /0 | E22: M1855654 | F22: 40
A23: 8 | B23: 46237 | C23: 00042-508-46 | D23: TGBU415699 /6 | E23: 3907 | F23: 40
A24: 9 | B24: 46237 | C24: 00006-516-46 | D24: TCNU351908 /4 | E24: 3906 | F24: 40
A25: 10 | B25: 46237 | C25: 00124-523-31 | D25: APZU440364 /1 | E25: 3912 | F25: 40
A26: 11 | B26: 46237 | C26: 00125-523-31 | D26: WFHU415155 /5 | E26: 4000 | F26: 40
A27: 11 | B27: 46237 | C27: 01391-590-31 | D27: SEKU600313 /0 | E27: VIDE | F27: 40
A28: 12 | B28: 46238 | C28: 01391-590-32 | D28: TRHU606329 /0 | E28: VIDE | F28: 40
B30: VISITE
A32: N° | B32: Date V | C32: N° Conteneur | D32: AN° Scellé | E32: NO° Scellé | F32: Vol
A33: 1
A34: 2
A35: 3
A36: 4
A37: 5
A38: 6
A39: 7
A40: 8
A41: 9
A42: 10
A43: 11

Sheet 04-08
H1: =COUNTIF(C8:C11,"<>") -> 2 | I1: TC
F2: =COUNTIFS(B16:B29,"<>",C16:C29,"VH") -> 0 | G2: VH | H2: =COUNTA(C16:C25)-F2 -> 2 | I2: TC | J2: =COUNTIF(E16:E21,"VIDE") -> 0
A3: FICHE DE MOUVEMENT
B5: RECEPTION | G5: 46238
A7: N° | B7: N° CRN | C7: Date R | D7: N° Conteneur | E7: N° Scellé | F7: Vol
A8: 1 | B8: 00132ICS0008 | C8: 46238 | D8: MSMU640873 /7 | E8: 1383717 | F8: 40
A9: 2 | B9: 00132ICS0008 | C9: 46238 | D9: SEKU679530 /9 | E9: 1383734 | F9: 40
A10: 3
A11: 4
B13: SORTIE
A15: N° | B15: Date S | C15: IMM | D15: N° Conteneur | E15: N° Scellé | F15: Vol
A16: 1 | B16: 46238 | C16: 00631-509-31 | D16: MSDU459782 /5 | E16: 3998 | F16: 40
A17: 2 | B17: 46238 | C17: 00375-585-31 | D17: MRKU581407 /1 | E17: 3995 | F17: 40
A18: 3
A19: 4
A20: 5
A21: 6
A22: 7
A23: 8
A24: 9
A25: 10
B27: VISITE
A29: N° | B29: Date V | C29: N° Conteneur | D29: AN° Scellé | E29: NO° Scellé | F29: Vol
A30: 1 | B30: 4082026 | C30: TGCU546808 /2 | D30: L7859611 | E30: 3953 | F30: 40
A31: 2
A32: 3
A33: 4
A34: 5
A35: 6
A36: 7
A37: 8

Sheet 05-08
H1: =COUNTIF(C8:C29,"<>") -> 17 | I1: TC
F2: =COUNTIFS(B34:B40,"<>",C34:C40,"VH") -> 0 | G2: VH | H2: =COUNTA(C34:C36)-F2 -> 2 | I2: TC | J2: =COUNTIF(H34:H36,"VIDE") -> 0
A3: FICHE DE MOUVEMENT
B5: RECEPTION | G5: 46239
A7: N° | B7: N° CRN | C7: Date R | D7: N° Conteneur | E7: N° Scellé | F7: Vol
A8: 1 | B8: 00137ICS0120 | C8: 46239 | D8: MSMU924819 /1 | E8: FJ28373341 | F8: 45
A9: 2 | B9: 00137ICS0047 | C9: 46239 | D9: DRYU249885 /2 | E9: 45022 | F9: 20
A10: 3 | C10: 46239 | D10: MEDU508616 /5 | E10: 45029 | F10: 20
A11: 4 | C11: 46239 | D11: MEDU548200 /0 | E11: 45023 | F11: 20
A12: 5 | C12: 46239 | D12: MSBU194819 /5 | E12: 45113 | F12: 20
A13: 6
A14: 7 | C14: 46239 | D14: MSNU318488 /0 | E14: 45035 | F14: 20
A15: 8 | C15: 46239 | D15: TLLU219321 /9 | E15: 45069 | F15: 20
A16: 9 | B16: 00137ICS0041 | C16: 46239 | D16: MSDU705579 /3 | E16: KG356021 | F16: 40
A17: 10 | C17: 46239 | D17: TRHU598192 /1 | E17: KG356016 | F17: 40
A18: 16 | B18: 00209ICS0098 | D18: APHU462388 /0 | E18: M5051699 | F18: 45 | G18: ANNULLEE
A19: 17 | D19: SEGU589315 /8 | E19: M5050362 | F19: 45
A20: 18 | B20: 00209ICS0084 | C20: 46239 | D20: APHU466065 /2 | E20: M5051742 | F20: 45
A21: 19 | C21: 46239 | D21: CAIU584820 /7 | E21: M5051750 | F21: 45
A22: 20 | B22: 00209ICS0052 | C22: 46239 | D22: CMAU685882 /0 | E22: M7930882 | F22: 40
A23: 21 | D23: FCIU610918 /0 | E23: J0720981 | F23: 20
A24: 22 | C24: 46239 | D24: FDCU015420 /1 | E24: M9742568 | F24: 40
A25: 23 | B25: 00209ICS0051 | D25: ECMU806509 /4 | E25: J0533956 | F25: 20
A26: 24 | C26: 46239 | D26: ECMU806813 /3 | E26: J0533908 | F26: 45
A27: 25 | C27: 46239 | D27: ECMU811432 /6 | E27: J0530888 | F27: 45
A28: 26 | B28: 00137ICS0177 | C28: 46239 | D28: MSMU924754 /9 | E28: FJ27551123 | F28: 45
A29: 27 | C29: 46239 | D29: MSMU925638 /7 | E29: FJ27551129 | F29: 45
B31: SORTIE
A33: N° | B33: Date S | C33: IMM | D33: N° Conteneur | E33: N° Scellé | F33: Vol
A34: 1 | B34: 46239 | C34: 00124-523-31 | D34: KOCU444962/9 | E34: 3961 | F34: 40
A35: 2 | B35: 46239 | C35: 00419-505-31 | D35: BMOU595766/1 | E35: FX44654381 | F35: 40
A36: 3
B38: VISITE
A40: N° | B40: Date V | C40: N° Conteneur | D40: AN° Scellé | E40: NO° Scellé | F40: Vol
A41: 1
A42: 2
A43: 3
A44: 4

Sheet 06-08
H1: =COUNTIF(C8:C15,"<>") -> 6 | I1: TC
F2: =COUNTIFS(B20:B23,"<>",C20:C23,"VH") -> 1 | G2: VH | H2: =COUNTA(C20:C27)-F2 -> 2 | I2: TC | J2: =COUNTIF(H20:H25,"VIDE") -> 0
A3: FICHE DE MOUVEMENT
B5: RECEPTION | G5: 46240
A7: N° | B7: N° CRN | C7: Date R | D7: N° Conteneur | E7: N° Scellé | F7: Vol
A8: 1 | B8: 00137ICS0047 | C8: 46240 | D8: MSNU108559 /5 | E8: 45063 | F8: 20
A9: 2 | B9: 00137ICS0012 | C9: 46240 | D9: CRTU760967 /9 | E9: FLAT | F9: 45
A10: 3 | C10: 46240 | D10: MSCU255953 /0 | E10: FJ25931782 | F10: 20
A11: 4 | D11: MSDU600819 /0 | E11: FJ25931784 | F11: 40
A12: 5 | D12: MSDU749894 /0 | E12: FJ25931785 | F12: 40
A13: 6 | C13: 46240 | D13: TCLU600116 /8 | E13: FLAT | F13: 45
A14: 7 | B14: 00209ICS0052 | C14: 46240 | D14: FCIU610918 /0 | E14: J0720981 | F14: 20
A15: 8 | B15: 00209ICS0051 | C15: 46240 | D15: ECMU806509 /4 | E15: J0533956 | F15: 20
B17: SORTIE
A19: N° | B19: Date S | C19: IMM | D19: N° Conteneur | E19: N° Scellé | F19: Vol
A20: 1 | B20: 46240 | C20: 00124-523-31 | D20: TCLU768371 /4 | E20: VIDE | F20: 20
A21: 2 | B21: 46240 | C21: 00369-512-31 | D21: TGCU546808 /2 | E21: 3953 | F21: 40
A22: 3 | B22: 46240 | C22: VH | D22: LMG--T3241544 | E22: GAC GS3
A23: 4
A24: 5
A25: 6
A26: 7
A27: 8
B29: VISITE
A31: N° | B31: Date V | C31: N° Conteneur | D31: AN° Scellé | E31: NO° Scellé | F31: Vol
A32: 1 | B32: 46240 | C32: CAIU560903 /3 | D32: F118292 | E32: 3531
A33: 2 | B33: 46240 | C33: SEGU737247 /8 | D33: F118251 | E33: 3526
A34: 3 | B34: 46240 | C34: SEGU737263 /1 | D34: F118296 | E34: 3524
A35: 4 | B35: 46240 | C35: SEGU737305 /2 | D35: F118291 | E35: 3522
A36: 5 | B36: 46240 | C36: TCLU707021 /9 | D36: F118286 | E36: 3525
A37: 6 | B37: 46240 | C37: TCLU713118 /7 | D37: F118262 | E37: 3528
A38: 7 | B38: 46240 | C38: TEXU154116 /4 | D38: F118290 | E38: 3527
A39: 8 | B39: 46240 | C39: TEXU157181 /0 | D39: F118263 | E39: 3530
A40: 9 | B40: 46240 | C40: TLLU126525 /3 | D40: F118269 | E40: 3529
A41: 10 | B41: 46240 | C41: TRIU053365 /6 | D41: F118281 | E41: 3523
A42: 11 | B42: 46240 | C42: CSGU699239 /4 | D42: 33046002 | E42: 3955
A43: 12 | B43: 46240 | C43: CSGU700576 /7 | D43: 32447470 | E43: 3956

Sheet 09-08
H1: =COUNTIF(C8:C15,"<>") -> 2 | I1: TC
F2: =COUNTIFS(B20:B23,"<>",C20:C23,"VH") -> 0 | G2: VH | H2: =COUNTA(C20:C27)-F2 -> 0 | I2: TC | J2: =COUNTIF(H20:H25,"VIDE") -> 0
A3: FICHE DE MOUVEMENT
B5: RECEPTION | G5: 46243
A7: N° | B7: N° CRN | C7: Date R | D7: N° Conteneur | E7: N° Scellé | F7: Vol
A8: 1 | B8: 00137ICS0012 | C8: 46243 | D8: MSDU600819 /0 | E8: FJ25931784 | F8: 40
A9: 2 | C9: 46243 | D9: MSDU749894 /0 | E9: FJ25931785 | F9: 40
A10: 3
A11: 4
A12: 5
A13: 6
A14: 7
A15: 8
B17: SORTIE
A19: N° | B19: Date S | C19: IMM | D19: N° Conteneur | E19: N° Scellé | F19: Vol
A20: 1
A21: 2
A22: 3
A23: 4
A24: 5
A25: 6
A26: 7
A27: 8
B29: VISITE
A31: N° | B31: Date V | C31: N° Conteneur | D31: AN° Scellé | E31: NO° Scellé | F31: Vol
A32: 1 | B32: 46243 | C32: TLLU468314 /9 | D32: M8351211 | E32: 3957 | F32: 40
A33: 2
A34: 3
A35: 4
A36: 5
A37: 6
A38: 7
A39: 8
A40: 9
A41: 10
A42: 11
A43: 12

Sheet 10-08
H1: =COUNTIF(C8:C15,"<>") -> 5 | I1: TC
F2: =COUNTIFS(B20:B23,"<>",C20:C23,"VH") -> 0 | G2: VH | H2: =COUNTA(C20:C33)-F2 -> 12 | I2: TC | J2: =COUNTIF(H20:H25,"VIDE") -> 0
A3: FICHE DE MOUVEMENT
B5: RECEPTION | G5: 46244
A7: N° | B7: N° CRN | C7: Date R | D7: N° Conteneur | E7: N° Scellé | F7: Vol
A8: 1 | B8: 0141ICS0097 | C8: 46244 | D8: 3516 | E8: EU31341933 | F8: 40
A9: 2 | D9: 3517 | E9: EU31339590 | F9: 40
A10: 3 | C10: 46244 | D10: 3518 | E10: EU31341924 | F10: 40
A11: 4 | C11: 46244 | D11: 3519 | E11: EU31341890 | F11: 40
A12: 5 | B12: 0034ICS0014 | C12: 46244 | D12: MBSU281340 /6 | E12: LB0263265 | F12: 20
A13: 6 | B13: 0644ICS0046 | C13: 46244 | D13: CMAU995575 /7 | E13: M2002559 | F13: 40
A14: 7
A15: 8
B17: SORTIE
A19: N° | B19: Date S | C19: IMM | D19: N° Conteneur | E19: N° Scellé | F19: Vol
A20: 1 | B20: 46244 | C20: 50004-525-27 | D20: CAIU560903 /3 | E20: 3531 | F20: 40
A21: 2 | B21: 46244 | C21: 239-511- | D21: SEGU737247 /8 | E21: 3526 | F21: 40
A22: 3 | B22: 46244 | C22: 19147-512-27 | D22: SEGU737263 /1 | E22: 3524 | F22: 40
A23: 4 | B23: 46244 | C23: 1900-509-31 | D23: SEGU737305 /2 | E23: 3522 | F23: 40
A24: 5 | B24: 46244 | C24: 03761-507-48 | D24: TCLU713118 /7 | E24: 3528 | F24: 40
A25: 6 | B25: 46244 | C25: 16732-513-27 | D25: TEXU154116 /4 | E25: 3527 | F25: 40
A26: 7 | B26: 46244 | C26: 00965-509-27 | D26: TEXU157181 /0 | E26: 3530 | F26: 40
A27: 8 | B27: 46244 | C27: 50001-512-27 | D27: TLLU126525 /3 | E27: 3529 | F27: 40
A28: 9 | B28: 46244 | C28: 0024-511-27 | D28: TRIU053365 /6 | E28: 3523 | F28: 40
A29: 10 | B29: 46244 | C29: 00208-508-31 | D29: APZU482800 /8 | E29: 3952 | F29: 40
A30: 11 | B30: 46244 | C30: 00152-518-31 | D30: TEMU319824 /0 | E30: 3954 | F30: 20
A31: 12 | B31: 46244 | C31: 00108-515-31 | D31: TCLU197143 /6 | E31: 3954 | F31: 20
A32: 13
A33: 14
B35: VISITE
A37: N° | B37: Date V | C37: N° Conteneur | D37: AN° Scellé | E37: NO° Scellé | F37: Vol
A38: 1 | B38: 46244 | C38: TCNU364693 /6 | D38: 361693 | E38: 3959 | F38: 40
A39: 2
A40: 3
A41: 4
A42: 5
A43: 6
A44: 7
A45: 8
A46: 9
...

Sheet 11-08
H1: =COUNTIF(C8:C14,"<>") -> 3 | I1: TC
F2: =COUNTIFS(B19:B22,"<>",C19:C22,"VH") -> 0 | G2: VH | H2: =COUNTA(C19:C28)-F2 -> 1 | I2: TC | J2: =COUNTIF(H19:H24,"VIDE") -> 0
A3: FICHE DE MOUVEMENT
B5: RECEPTION | G5: 46245
A7: N° | B7: N° CRN | C7: Date R | D7: N° Conteneur | E7: N° Scellé | F7: Vol | G7: Depotage
A8: 2 | B8: 0141ICS0097 | C8: 46245 | D8: MSBU729857 /0 | E8: EU31339590 | F8: 40
A9: 3 | B9: 0221ICS0044/4 | C9: 46245 | D9: TIIU811908 /0 | E9: M8273609 | F9: GROUPAGE | G9: 46254
A10: 4 | B10: 0221ICS0048/4 | C10: 46245 | D10: TIIU811819 /1 | E10: M8273604 | F10: GROUPAGE | G10: 46254
A11: 5
A12: 6
A13: 7
A14: 8
B16: SORTIE
A18: N° | B18: Date S | C18: IMM | D18: N° Conteneur | E18: N° Scellé | F18: Vol
A19: 1 | B19: 46245 | C19: 11082-502-27 | D19: TCLU707021 /9 | E19: 3925 | F19: 40
A20: 2
A21: 3
A22: 4
A23: 5
A24: 6
A25: 7
A26: 8
A27: 9
A28: 10
B30: VISITE
A32: N° | B32: Date V | C32: N° Conteneur | D32: AN° Scellé | E32: NO° Scellé | F32: Vol
A33: 1 | B33: 46245 | C33: MEDU957207 /8 | D33: FX47781171 | E33: 3960 | F33: 40
A34: 2
A35: 3
A36: 4
A37: 5
A38: 6
A39: 7
A40: 8

Sheet 12-08
H1: =COUNTIF(C8:C14,"<>") -> 2 | I1: TC
F2: =COUNTIFS(B19:B22,"<>",C19:C22,"VH") -> 0 | G2: VH | H2: =COUNTA(C19:C28)-F2 -> 1 | I2: TC | J2: =COUNTIF(H19:H24,"VIDE") -> 0
A3: FICHE DE MOUVEMENT
B5: RECEPTION | G5: 46246
A7: N° | B7: N° CRN | C7: Date R | D7: N° Conteneur | E7: N° Scellé | F7: Vol
A8: 2 | B8: 00143ICS0117 | C8: 46246 | D8: MEDU951011 /6 | E8: FX46629585 | F8: 45
A9: 3 | C9: 46246 | D9: MEDU958286 /2 | E9: FX46635083 | F9: 45
A10: 4
A11: 5
A12: 6
A13: 7
A14: 8
B16: SORTIE
A18: N° | B18: Date S | C18: IMM | D18: N° Conteneur | E18: N° Scellé | F18: Vol
A19: 1 | B19: 46246 | C19: 00419-517-31 | D19: TLLU468314 / | E19: 3957
A20: 2
A21: 3
A22: 4
A23: 5
A24: 6
A25: 7
A26: 8
A27: 9
A28: 10
B30: VISITE
A32: N° | B32: Date V | C32: N° Conteneur | D32: AN° Scellé | E32: NO° Scellé | F32: Vol
A33: 1 | B33: 46246 | C33: TRHU194179 /3 | D33: 4250703 | E33: 3958
A34: 2 | B34: 46246 | C34: HMMU437539 /2 | D34: 25H1381151 | E34: 3520
A35: 3
A36: 4
A37: 5
A38: 6
A39: 7
A40: 8

Sheet 13-08
H1: =COUNTIF(C8:C14,"<>") -> 0 | I1: TC
F2: =COUNTIFS(B19:B22,"<>",C19:C22,"VH") -> 0 | G2: VH | H2: =COUNTA(C19:C28)-F2 -> 1 | I2: TC | J2: =COUNTIF(H19:H24,"VIDE") -> 0
A3: FICHE DE MOUVEMENT
B5: RECEPTION | G5: 46247
A7: N° | B7: N° CRN | C7: Date R | D7: N° Conteneur | E7: N° Scellé | F7: Vol
A8: 2
A9: 3
A10: 4
A11: 5
A12: 6
A13: 7
A14: 8
B16: SORTIE
A18: N° | B18: Date S | C18: IMM | D18: N° Conteneur | E18: N° Scellé | F18: Vol
A19: 1 | B19: 46247 | C19: 00207-508-31 | D19: MSMU834901 /6 | E19: B2506030 | F19: 40
A20: 2
A21: 3
A22: 4
A23: 5
A24: 6
A25: 7
A26: 8
A27: 9
A28: 10
B30: VISITE
A32: N° | B32: Date V | C32: N° Conteneur | D32: AN° Scellé | E32: NO° Scellé | F32: Vol
A33: 1 | B33: 46247 | C33: APHU466065 /2 | D33: M5051742 | E33: 3511 | F33: 45
A34: 2 | B34: 46247 | C34: CAIU584820 /7 | D34: M5051750 | E34: 3512 | F34: 45
A35: 3
A36: 4
A37: 5
A38: 6
A39: 7
A40: 8

Sheet 16-08
H1: =COUNTIF(C8:C14,"<>") -> 0 | I1: TC
F2: =COUNTIFS(B19:B22,"<>",C19:C22,"VH") -> 0 | G2: VH | H2: =COUNTA(C19:C28)-F2 -> 2 | I2: TC | J2: =COUNTIF(H19:H24,"VIDE") -> 0
A3: FICHE DE MOUVEMENT
B5: RECEPTION | G5: 46250
A7: N° | B7: N° CRN | C7: Date R | D7: N° Conteneur | E7: N° Scellé | F7: Vol
A8: 2
A9: 3
A10: 4
A11: 5
A12: 6
A13: 7
A14: 8
B16: SORTIE
A18: N° | B18: Date S | C18: IMM | D18: N° Conteneur | E18: N° Scellé | F18: Vol
A19: 1 | B19: 46250 | C19: 002073-588-31 | D19: MSDU705579 /3 | E19: KG356021 | F19: 40
A20: 2 | B20: 46250 | C20: 00384-507-31 | D20: TRHU598192 /1 | E20: KG356016 | F20: 40
A21: 3
A22: 4
A23: 5
A24: 6
A25: 7
A26: 8
A27: 9
A28: 10
B30: VISITE
A32: N° | B32: Date V | C32: N° Conteneur | D32: AN° Scellé | E32: NO° Scellé | F32: Vol
A33: 1 | B33: 46250 | C33: CMAU685882 /0 | D33: M7930882 | E33: 3513 | F33: 40
A34: 2 | B34: 46250 | C34: FCIU610918 /0 | D34: J0720981 | E34: 3514 | F34: 20
A35: 3 | B35: 46250 | C35: FDCU015420 /1 | D35: M9742568 | E35: 3515 | F35: 40
A36: 4 | B36: 46250 | C36: FFAU207203 /9 | D36: EU31341933 | E36: 3516 | F36: 40
A37: 5 | B37: 46250 | C37: MSBU729857 /0 | D37: EU31339590 | E37: 3517 | F37: 40
A38: 6 | B38: 46250 | C38: MSNU575653 /6 | D38: EU31341924 | E38: 3518 | F38: 40
A39: 7 | B39: 46250 | C39: SEGU627118 /5 | D39: EU31341890 | E39: 3519 | F39: 40
A40: 8

Sheet 17-08
L1: =COUNTIF(C8:C14,"<>") -> 0 | M1: TC
J2: =COUNTIFS(B19:B22,"<>",C19:C22,"VH") -> 0 | K2: VH | L2: =COUNTA(C19:C28)-J2 -> 0 | M2: TC | N2: =COUNTIF(H19:H24,"VIDE") -> 0
A3: FICHE DE MOUVEMENT
B5: RECEPTION | G5: 46251
A7: N° | B7: N° CRN | C7: Date R | D7: N° Conteneur | E7: N° Scellé | F7: Vol
A8: 2
A9: 3
A10: 4
A11: 5
A12: 6
A13: 7
A14: 8
B16: SORTIE
A18: N° | B18: Date S | C18: IMM | D18: N° Conteneur | E18: N° Scellé | F18: Vol
A19: 1
A20: 2
A21: 3
A22: 4
A23: 5
A24: 6
A25: 7
A26: 8
A27: 9
A28: 10
B30: VISITE
A32: N° | B32: Date V | C32: N° Conteneur | D32: AN° Scellé | E32: NO° Scellé | F32: Vol
A33: 1 | B33: 46251 | C33: TRHU875969 /3 | D33: 549293 | E33: 3510 | F33: 40
A34: 2
A35: 3
A36: 4
A37: 5
A38: 6
A39: 7
A40: 8

Sheet 18-08
H1: =COUNTIF(C8:C14,"<>") -> 0 | I1: TC
F2: =COUNTIFS(B19:B22,"<>",C19:C22,"VH") -> 0 | G2: VH | H2: =COUNTA(C19:C28)-F2 -> 7 | I2: TC | J2: =COUNTIF(H19:H24,"VIDE") -> 0
A3: FICHE DE MOUVEMENT
B5: RECEPTION | G5: 46252
A7: N° | B7: N° CRN | C7: Date R | D7: N° Conteneur | E7: N° Scellé | F7: Vol
A8: 2
A9: 3
A10: 4
A11: 5
A12: 6
A13: 7
A14: 8
B16: SORTIE
A18: N° | B18: Date S | C18: IMM | D18: N° Conteneur | E18: N° Scellé | F18: Vol
A19: 1 | B19: 46252 | C19: 00385-510-31 | D19: DRYU249885 /2 | E19: 45022 | F19: 20
A20: 2 | B20: 46252 | C20: 00092-518-31 | D20: MEDU508616 /5 | E20: 45029 | F20: 20
A21: 3 | B21: 46252 | C21: 00103-510-31 | D21: MEDU548200 /0 | E21: 45023 | F21: 20
A22: 4 | B22: 46252 | C22: 00089-512-31 | D22: MSBU194819 /5 | E22: 45113 | F22: 20
A23: 5 | B23: 46252 | C23: 00358-511-31 | D23: MSNU108559 /5 | E23: 45063 | F23: 20
A24: 6 | B24: 46252 | C24: 00372-510-31 | D24: MSNU318488 /0 | E24: 45035 | F24: 20
A25: 7 | B25: 46252 | C25: 00092-509-31 | D25: TLLU219321 /9 | E25: 45069 | F25: 20
A26: 8
A27: 9
A28: 10
B30: VISITE
A32: N° | B32: Date V | C32: N° Conteneur | D32: AN° Scellé | E32: NO° Scellé | F32: Vol
A33: 1 | B33: 46252 | C33: TRHU875969 /3 | D33: 549293 | E33: 3510 | F33: 40
A34: 2
A35: 3
A36: 4
A37: 5
A38: 6
A39: 7
A40: 8

Sheet 19-08
H1: =COUNTIF(C8:C14,"<>") -> 5 | I1: TC
F2: =COUNTIFS(B19:B22,"<>",C19:C22,"VH") -> 0 | G2: VH | H2: =COUNTA(C19:C28)-F2 -> 8 | I2: TC | J2: =COUNTIF(H19:H24,"VIDE") -> 0
A3: FICHE DE MOUVEMENT
B5: RECEPTION | G5: 46253
A7: N° | B7: N° CRN | C7: Date R | D7: N° Conteneur | E7: N° Scellé | F7: Vol
A8: 2 | B8: 0149ICS0026 | C8: 46253 | D8: MEDU760577 /9 | E8: MA526075 | F8: 40
A9: 3 | C9: 46253 | D9: MSDU787252 /0 | E9: MA526074 | F9: 40
A10: 4 | B10: 0221ICS0244 | C10: 46253 | D10: ECMU809447 /2 | E10: M4936024 | F10: 45
A11: 5 | B11: 0221ICS0151 | C11: 46253 | D11: TCLU331996 /2 | E11: L7197041 | F11: 20
A12: 6 | B12: 0221ICS0035 | C12: 46253 | D12: TLLU408917 /9 | E12: M1412926 | F12: 40
A13: 7
A14: 8
B16: SORTIE
A18: N° | B18: Date S | C18: IMM | D18: N° Conteneur | E18: N° Scellé | F18: Vol
A19: 1 | B19: 46253 | C19: 00070-505-31 | D19: TRHU194179 /3 | E19: 3958 | F19: 20
A20: 2 | B20: 46253 | C20: 00338-506-31 | D20: TRHU875969 /3 | E20: 3510 | F20: 40
A21: 3 | B21: 46253 | C21: 000028-515-31 | D21: FFAU207203 /9 | E21: 3516 | F21: 40
A22: 4 | B22: 46253 | C22: 00175-516-31 | D22: MSBU729857 /0 | E22: 3517 | F22: 40
A23: 5 | B23: 46253 | C23: 00159-516-31 | D23: MSNU575653 /6 | E23: 3518 | F23: 40
A24: 6 | B24: 46253 | C24: 00172-516-31 | D24: SEGU627118 /5 | E24: 3519 | F24: 40
A25: 7 | B25: 46253 | C25: 00335-510-31 | D25: APHU466065 /2 | E25: 3511 | F25: 45
A26: 8 | B26: 46253 | C26: 16227-513-48 | D26: CAIU584820 /7 | E26: 3512 | F26: 45
A27: 9
A28: 10
B30: VISITE
A32: N° | B32: Date V | C32: N° Conteneur | D32: AN° Scellé | E32: NO° Scellé | F32: Vol
A33: 1 | B33: 46253 | C33: MSMU924754 /9 | D33: FJ27551123 | E33: 3506 | F33: 40
A34: 2 | B34: 46253 | C34: MSMU925638 /7 | D34: FJ27551129 | E34: 3505 | F34: 40
A35: 3 | B35: 46253 | C35: ECMU806813 /3 | D35: J0533908 | E35: 3509 | F35: 40
A36: 4 | B36: 46253 | C36: ECMU811432 /6 | D36: J0530888 | E36: 3508 | F36: 40
A37: 5 | B37: 46253 | C37: ECMU806509 /4 | D37: J0533956 | E37: 3507 | F37: 40
A38: 6
A39: 7
A40: 8

Sheet 20-08
H1: =COUNTIF(C8:C14,"<>") -> 0 | I1: TC
F2: =COUNTIFS(B19:B22,"<>",C19:C22,"VH") -> 0 | G2: VH | H2: =COUNTA(C19:C28)-F2 -> 4 | I2: TC | J2: =COUNTIF(H19:H24,"VIDE") -> 0
A3: FICHE DE MOUVEMENT
B5: RECEPTION | G5: 46254
A7: N° | B7: N° CRN | C7: Date R | D7: N° Conteneur | E7: N° Scellé | F7: Vol
A8: 2
A9: 3
A10: 4
A11: 5
A12: 6
A13: 7
A14: 8
B16: SORTIE
A18: N° | B18: Date S | C18: IMM | D18: N° Conteneur | E18: N° Scellé | F18: Vol
A19: 1 | B19: 46254 | C19: 000310-510-31 | D19: TCNU364693 /6 | E19: 3959 | F19: 40
A20: 2 | B20: 46254 | C20: 00310-510-31 | D20: ECMU806509 /4 | E20: J0533956 | F20: 40
A21: 3 | B21: 46254 | C21: 00053-511-31 | D21: ECMU806813 /3 | E21: J0533908 | F21: 40
A22: 4 | B22: 46254 | C22: 00255-510-31 | D22: ECMU811432 /6 | E22: J0530888 | F22: 40
A23: 5
A24: 6
A25: 7
A26: 8
A27: 9
A28: 10
B30: VISITE
A32: N° | B32: Date V | C32: N° Conteneur | D32: AN° Scellé | E32: NO° Scellé | F32: Vol
A33: 1 | B33: 46253 | C33: TTNU102467 /0 | D33: 3602841 | E33: 3504 | F33: 20
A34: 2
A35: 3
A36: 4
A37: 5
A38: 6
A39: 7
A40: 8

Sheet 23-08
H1: =COUNTIF(C8:C14,"<>") -> 0 | I1: TC
F2: =COUNTIFS(B19:B22,"<>",C19:C22,"VH") -> 0 | G2: VH | H2: =COUNTA(C19:C28)-F2 -> 2 | I2: TC | J2: =COUNTIF(H19:H24,"VIDE") -> 0
A3: FICHE DE MOUVEMENT
B5: RECEPTION | G5: 46257
A7: N° | B7: N° CRN | C7: Date R | D7: N° Conteneur | E7: N° Scellé | F7: Vol
A8: 2
A9: 3
A10: 4
A11: 5
A12: 6
A13: 7
A14: 8
B16: SORTIE
A18: N° | B18: Date S | C18: IMM | D18: N° Conteneur | E18: N° Scellé | F18: Vol
A19: 1 | B19: 46257 | C19: 08436-585-14 | D19: MEDU957207 /8 | E19: 3960 | F19: 45
A20: 2 | B20: 46257 | C20: 002205-509-16 | D20: MSMU925638 /7 | E20: 3905 | F20: 40
A21: 3 | B21: 46257 | D21: MSMU924754 /9 | E21: 3906 | F21: 40
A22: 4
A23: 5
A24: 6
A25: 7
A26: 8
A27: 9
A28: 10
B30: VISITE
A32: N° | B32: Date V | C32: N° Conteneur | D32: AN° Scellé | E32: NO° Scellé | F32: Vol
A33: 1 | B33: 46257 | C33: CAIU818783 /6 | D33: 403430 | E33: 3561 | F33: 20
A34: 2 | B34: 46257 | C34: CAIU819501 /9 | D34: 403420 | E34: 3562 | F34: 20
A35: 3 | B35: 46257 | C35: CAXU959721 /0 | D35: 207502 | E35: 3564 | F35: 20
A36: 4 | B36: 46257 | C36: CRSU928503 /0 | D36: HLD2681836 | E36: 3563 | F36: 20
A37: 5 | B37: 46257 | C37: CXDU134311 /3 | D37: 482341 | E37: 3565 | F37: 20
A38: 6 | B38: 46257 | C38: CXDU168050 /0 | D38: 482345 | E38: 3566 | F38: 20
A39: 7 | B39: 46257 | C39: FCGU198565 /0 | D39: 403418 | E39: 3567 | F39: 20
A40: 8 | B40: 46257 | C40: GESU575475 /4 | E40: 3568 | F40: 20
A41: 9 | B41: 46257 | C41: GESU661177 /9 | D41: 534715 | E41: 3569 | F41: 20
A42: 10 | B42: 46257 | C42: HJMU133346 /2 | D42: 482343 | E42: 3570 | F42: 20
A43: 11 | B43: 46257 | C43: HJMU152689 /9 | D43: 403415 | E43: 3503 | F43: 20
A44: 12 | B44: 46257 | C44: SEGU466432 /6 | D44: 403425 | E44: 3502 | F44: 20
A45: 13 | B45: 46257 | C45: TCNU646691 /7 | D45: 482350 | E45: 3501 | F45: 20
A46: 14 | B46: 46257 | C46: TGHU694661 /0 | D46: 2681587 | E46: 3580 | F46: 20

Sheet 24-08
H1: =COUNTIF(C8:C14,"<>") -> 3 | I1: TC
F2: =COUNTIFS(B19:B22,"<>",C19:C22,"VH") -> 0 | G2: VH | H2: =COUNTA(C19:C28)-F2 -> 1 | I2: TC | J2: =COUNTIF(H19:H24,"VIDE") -> 0
A3: FICHE DE MOUVEMENT
B5: RECEPTION | G5: 46258
A7: N° | B7: N° CRN | C7: Date R | D7: N° Conteneur | E7: N° Scellé | F7: Vol
A8: 2 | B8: 0078ICS0038 | C8: 24/08/2026 | D8: TCKU725483 /6 | E8: BD0235592 | F8: 40
A9: 3 | B9: 0147ICS0013 | C9: 24/08/2026 | D9: OOLU678904 /3 | E9: SYA5003483 | F9: 40
A10: 4 | B10: 0147ICS0033 | C10: 24/08/2026 | D10: ARKU855648 /7 | E10: B1779962 | F10: 40
A11: 5
A12: 6
A13: 7
A14: 8
B16: SORTIE
A18: N° | B18: Date S | C18: IMM | D18: N° Conteneur | E18: N° Scellé | F18: Vol
A19: 1 | B19: 24/08/2026 | C19: 002233-585-31 | D19: TTNU102467 /0 | E19: 3504 | F19: 20
A20: 2
A21: 3
A22: 4
A23: 5
A24: 6
A25: 7
A26: 8
A27: 9
A28: 10
B30: VISITE
A32: N° | B32: Date V | C32: N° Conteneur | D32: AN° Scellé | E32: NO° Scellé | F32: Vol
A33: 1 | B33: 46258 | C33: ECMU512820 /2 | D33: R9410054 | E33: 3579 | F33: 40
A34: 2 | B34: 46258 | C34: TRLU948903 /4 | D34: L7956894 | E34: 3571 | F34: 40
A35: 3
A36: 4
A37: 5
A38: 6
A39: 7
A40: 8
A41: 9
A42: 10
A43: 11
A44: 12
A45: 13
A46: 14

Sheet 26-08
H1: =COUNTIF(C8:C14,"<>") -> 3 | I1: TC
F2: =COUNTIFS(B19:B22,"<>",C19:C22,"VH") -> 0 | G2: VH | H2: =COUNTA(C19:C28)-F2 -> 0 | I2: TC | J2: =COUNTIF(H19:H24,"VIDE") -> 0
A3: FICHE DE MOUVEMENT
B5: RECEPTION | G5: 46260
A7: N° | B7: N° CRN | C7: Date R | D7: N° Conteneur | E7: N° Scellé | F7: Vol
A8: 2 | B8: 0152ICS0044 | C8: 26/08/2026 | D8: BMOU213576 /9 | E8: 2134430 | F8: 20
A9: 3 | B9: 0152ICS0044 | C9: 26/08/2026 | D9: CXSU114000 /6 | E9: 0 | F9: FLAT
A10: 4 | B10: 0152ICS0044 | C10: 26/08/2026 | D10: TCLU600602 /5 | E10: 0 | F10: FLAT
A11: 5
A12: 6
A13: 7
A14: 8
B16: SORTIE
A18: N° | B18: Date S | C18: IMM | D18: N° Conteneur | E18: N° Scellé | F18: Vol
A19: 1
A20: 2
A21: 3
A22: 4
A23: 5
A24: 6
A25: 7
A26: 8
A27: 9
A28: 10
B30: VISITE
A32: N° | B32: Date V | C32: N° Conteneur | D32: AN° Scellé | E32: NO° Scellé | F32: Vol
A33: 1
A34: 2
A35: 3
A36: 4
A37: 5
A38: 6
A39: 7
A40: 8
A41: 9
A42: 10
A43: 11
A44: 12
... A46: 14
