Workbook

Sheet DASHBOARD
A1: Date | B1: TC Réceptionnés | C1: TC Sortis | D1: Total Mouvements | F1: TC Sortis VIDE
A2: 46204 | B2: ='01-07'!H1 -> 0 | C2: ='01-07'!H2 -> 6 | D2: =SUM(B2:C2) -> 6
A3: 46206 | B3: ='03-07'!H1 -> 10 | C3: ='03-07'!H2 -> 0 | D3: =SUM(B3:C3) -> 10
A4: 46209 | B4: ='06-07'!H1 -> 23 | C4: ='06-07'!H2 -> 2 | D4: =SUM(B4:C4) -> 25
A5: 46210 | B5: ='07-07'!H1 -> 2 | C5: ='07-07'!H2 -> 12 | D5: =SUM(B5:C5) -> 14
A6: 46211 | B6: ='08-07'!H1 -> 16 | C6: ='08-07'!H2 -> 7 | D6: =SUM(B6:C6) -> 23
A7: 46212 | B7: ='09-07'!H1 -> 2 | C7: ='09-07'!H2 -> 27 | D7: =SUM(B7:C7) -> 29
A8: 46215 | B8: ='12-07'!H1 -> 15 | C8: ='12-07'!H2 -> 1 | D8: =SUM(B8:C8) -> 16
A9: 46216 | B9: ='13-07'!H1 -> 2 | C9: ='13-07'!H2 -> 3 | D9: =SUM(B9:C9) -> 5
A10: 46217 | B10: ='14-07'!H1 -> 0 | C10: ='14-07'!H2 -> 2 | D10: =SUM(B10:C10) -> 2
A11: 46218 | B11: ='15-07'!H1 -> 0 | C11: ='15-07'!H2 -> 2 | D11: =SUM(B11:C11) -> 2
A12: 46219 | B12: ='16-07'!H1 -> 8 | C12: ='16-07'!H2 -> 3 | D12: =SUM(B12:C12) -> 11
A13: 46222 | B13: ='19-07'!F1 -> 0 | C13: ='19-07'!F2 -> 0 | D13: =SUM(B13:C13) -> 0
A14: 46223 | B14: ='20-07'!H1 -> 10 | C14: ='20-07'!H2 -> 0 | D14: =SUM(B14:C14) -> 10
A15: 46224 | B15: ='21-07'!H1 -> 0 | C15: ='21-07'!H2 -> 5 | D15: =SUM(B15:C15) -> 5
A16: 46225 | B16: ='22-07'!H1 -> 9 | C16: ='22-07'!H2 -> 25 | D16: =SUM(B16:C16) -> 34
A17: 46226 | B17: ='23-07'!H1 -> 0 | C17: ='23-07'!H2 -> 6 | D17: =SUM(B17:C17) -> 6
A18: 46229 | B18: ='26-07'!H1 -> 10 | C18: ='26-07'!H2 -> 19 | D18: =SUM(B18:C18) -> 29
A19: 46230 | B19: ='27-07'!H1 -> 0 | C19: ='27-07'!H2 -> 4 | D19: =SUM(B19:C19) -> 4
A20: 46231 | B20: ='28-07'!H1 -> 0 | C20: ='23-07'!H5 -> 0 | D20: =SUM(B20:C20) -> 0
A21: 46232 | B21: ='29-07'!H1 -> 11 | C21: ='23-07'!H6 -> 0 | D21: =SUM(B21:C21) -> 11
A22: 46233 | B22: ='30-07'!H1 -> 1 | C22: ='23-07'!H7 -> 0 | D22: =SUM(B22:C22) -> 1
A24: Total | B24: =SUM(B2:B22) -> 119 | C24: =SUM(C2:C22) -> 124 | D24: =SUM(D2:D22) -> 243

Sheet 01-07
H1: =COUNTIF(B8:B9,"<>") -> 0 | I1: TC
F2: =COUNTIFS(B14:B23,"<>",C14:C23,"VH") -> 0 | G2: VH | H2: =COUNTA(C14:C20)-F2 -> 6 | I2: TC | J2: =COUNTIF(E14:E19,"VIDE") -> 4
A3: FICHE DE MOUVEMENT
B5: RECEPTION | G5: 46204
A7: N° | B7: N° CRN | C7: Date R | D7: N° Conteneur | E7: N° Scellé | F7: Vol
A8: 1
A9: 8
B11: SORTIE
A13: N° | B13: Date S | C13: IMM | D13: N° Conteneur | E13: N° Scellé | F13: Vol
A14: 1 | B14: 46204 | C14: 00529-508-31 | D14: CMAU877794 /3 | E14: 3887 | F14: 40
A15: 2 | B15: 46060 | C15: 00528-510-31 | D15: FFAU670430 /8 | E15: 3869 | F15: 40
A16: 3 | B16: 46204 | C16: 010724-585-34 | D16: TGBU754937 /0 | E16: VIDE | F16: 40
A17: 4 | B17: 46204 | C17: 00738-589-31 | D17: MSMU666679 /4 | E17: VIDE | F17: 40
A18: 5 | B18: 46204 | C18: 00738-589-31 | D18: MSDU854545 /5 | E18: VIDE | F18: 40
A19: 6 | B19: 46204 | C19: 00176-504-31 | D19: MSNU557983 /1 | E19: VIDE | F19: 40
B21: VISITE
A23: N° | B23: Date V | C23: N° Conteneur | D23: AN° Scellé | E23: NO° Scellé | F23: Vol
A24: 1 | B24: 1072026 | C24: CAXU903878 /3 | D24: LB0266422 | E24: 3845 | F24: 40
A25: 2 | B25: 1072026 | C25: CAXU965894 /8 | D25: LB0266431 | E25: 3913 | F25: 40
A26: 3 | B26: 1072026 | C26: CHSU809431 /6 | D26: LB0266299 | E26: 3843 | F26: 40
A27: 4 | B27: 1072026 | C27: FSCU987305 /7 | D27: LB0266490 | E27: 3899 | F27: 40
A28: 5 | B28: 1072026 | C28: GATU852786 /7 | D28: LB0266438 | E28: 3897 | F28: 40
A29: 6 | B29: 1072026 | C29: GCNU464217 /2 | D29: LB0266485 | E29: 3846 | F29: 40
A30: 7 | B30: 1072026 | C30: GLDU063183 /5 | D30: LB0266421 | E30: 3850 | F30: 40
A31: 8 | B31: 1072026 | C31: HLXU624229 /8 | D31: LB0266478 | E31: 3892 | F31: 40
A32: 9 | B32: 1072026 | C32: HPCU401944 /2 | D32: LB0266437 | E32: 3893 | F32: 40
A33: 10 | B33: 1072026 | C33: INKU228395 /6 | D33: LB0266297 | E33: 3918 | F33: 40
A34: 11 | B34: 1072026 | C34: MOTU040902 /0 | D34: LB0266295 | E34: 3845 | F34: 40
A35: 12 | B35: 1072026 | C35: NYKU553573 /0 | D35: LB0266423 | E35: 3891 | F35: 40
... A50: 27 | B50: 1072026 | C50: YMLU816005 /6 | D50: LB0266432 | E50: 3915 | F50: 40
A51: 28 | B51: 1072026 | C51: TCKU 997977 /6 | D51: 3886 | E51: 3900 | F51: 45
A52: 29 | B52: 1072026 | C52: TDRU461667 /6 | D52: 3889 | E52: 3929 | F52: 45
A53: 30 | B53: 1072026 | C53: MRSU345476 /5 | D53: ML-CN3700789 | E53: 3930 | F53: 40

Sheet 03-07
H1: =COUNTIF(C8:C17,"<>") -> 10 | I1: TC
F2: =COUNTIFS(B25:B35,"<>",C25:C35,"VH") -> 0 | G2: VH | H2: =COUNTA(C25:C32)-F2 -> 0 | I2: TC | J2: =COUNTIF(E25:E30,"VIDE") -> 0
A3: FICHE DE MOUVEMENT
B5: RECEPTION | G5: 46206
A7: N° | B7: N° CRN | C7: Date R | D7: N° Conteneur | E7: N° Scellé | F7: Vol
A8: 1 | B8: 00161ICS0131 | C8: 46206 | D8: CAIU560903 /3 | E8: F118292 | F8: 40
A9: 2 | C9: 46206 | D9: SEGU737247 /8 | E9: F118251 | F9: 40
A10: 3 | C10: 46206 | D10: SEGU737263 /1 | E10: F118296 | F10: 40
A11: 4 | C11: 46206 | D11: SEGU737305 /2 | E11: F118291 | F11: 40
A12: 5 | C12: 46206 | D12: TCLU707021 /9 | E12: F118286 | F12: 40
A13: 6 | C13: 46206 | D13: TCLU713118 /7 | E13: F118262 | F13: 40
A14: 7 | C14: 46206 | D14: TEXU154116 /4 | E14: F118290 | F14: 40
A15: 8 | C15: 46206 | D15: TEXU157181 /0 | E15: F118263 | F15: 40
A16: 9 | C16: 46206 | D16: TLLU126525 /3 | E16: F118269 | F16: 40
A17: 10 | C17: 46206 | D17: TRIU053365 /6 | E17: F118281 | F17: 40
A18: 11
A19: 12
B22: SORTIE
A24: N° | B24: Date S | C24: IMM | D24: N° Conteneur | E24: N° Scellé | F24: Vol
A25: 1
A26: 2
A27: 3
A28: 4
A29: 5
A30: 6
B33: VISITE
A35: N° | B35: Date V | C35: N° Conteneur | D35: AN° Scellé | E35: NO° Scellé | F35: Vol

Sheet 06-07
H1: =COUNTIF(C8:C32,"<>") -> 23 | I1: TC
F2: =COUNTIFS(B38:B48,"<>",C38:C48,"VH") -> 0 | G2: VH | H2: =COUNTA(C38:C45)-F2 -> 2 | I2: TC | J2: =COUNTIF(E38:E43,"VIDE") -> 0
A3: FICHE DE MOUVEMENT
B5: RECEPTION | G5: 46209
A7: N° | B7: N° CRN | C7: Date R | D7: N° Conteneur | E7: N° Scellé | F7: Vol | G7: Depotage
A8: 1 | B8: 00515ICS0081 | C8: 46209 | D8: ECMU266869 /7 | E8: 35596 | F8: 20
A9: 2 | B9: 0105ICS0004 | C9: 46209 | D9: MSBU803451 /9 | E9: 896535 | F9: 40
A10: 3 | C10: 46209 | D10: MSNU733963 /4 | E10: 896540 | F10: 40
A11: 4 | C11: 46209 | D11: TRHU593641 /3 | E11: 896539 | F11: 40
A12: 5
A13: 6 | B13: 00547ICS0093 /4 | C13: 46209 | D13: SEKU600313 /0 | E13: M9738944 | F13: GROUPAGE | G13: 46210
A14: 7 | B14: 00105ICS0019 | C14: 46209 | D14: CAAU865822 /9 | E14: FJ25951744 | F14: 40
A15: 8 | D15: CAAU999511 /6 | E15: FJ25951745
A16: 9 | C16: 46209 | D16: FFAU293917 /7 | E16: FJ25951753 | F16: 40
A17: 10 | C17: 46209 | D17: MEDU938762 /9 | E17: FJ25951747 | F17: 40
A18: 11 | C18: 46209 | D18: MSBU701831 /8 | E18: FJ25951748 | F18: 40
A19: 12 | C19: 46209 | D19: MSDU582015 /2 | E19: FJ25951749 | F19: 40
A20: 13 | C20: 46209 | D20: MSDU643345 /6 | E20: FJ25951750 | F20: 40
A21: 14 | C21: 46209 | D21: MSDU879402 /0 | E21: FJ25951751 | F21: 40
A22: 15 | C22: 46209 | D22: MSMU449068 /5 | E22: FJ25951752 | F22: 40
A23: 16 | C23: 46209 | D23: MSMU526705 /9 | E23: FJ25951746 | F23: 40
A24: 17 | C24: 46209 | D24: MSMU828891 /8 | E24: FJ25951754 | F24: 40 | G24: Scelle
A25: 18 | C25: 46209 | D25: MSNU549749 /8 | E25: FJ25947780 | F25: 40 | G25: 26/0056887
A26: 19 | C26: 46209 | D26: MSNU806904 /5 | E26: FJ25951755 | F26: 40 | G26: 533525
A27: 20 | C27: 46209 | D27: MSNU958094 /9 | E27: FJ25951756 | F27: 40
A28: 21 | C28: 46209 | D28: TIIU412362 /5 | E28: FJ25951757 | F28: 40
A29: 22 | B29: 0104ICS0023 | C29: 46209 | D29: CSGU699239 /4 | E29: 33046002 | F29: 40
A30: 23 | C30: 46209 | D30: CSGU700576 /7 | E30: 32447470 | F30: 40
A31: 24 | B31: 00104ICS0005 | C31: 46209 | D31: ARKU8399710 | E31: B2463499 | F31: 40
A32: 25 | C32: 46209 | D32: TCNU3495125 | E32: B2463310 | F32: 40
A33: 26
B35: SORTIE
A37: N° | B37: Date S | C37: IMM | D37: N° Conteneur | E37: N° Scellé | F37: Vol
A38: 1 | B38: 46209 | C38: 00070-505-31 | D38: FFAU305208 /4 | E38: HB368401 | F38: 40
A39: 2 | B39: 46209 | C39: 00172-516-31 | D39: MSMU625103 /6 | E39: 3885 | F39: 40
A40: 3
A41: 4
A42: 5
A43: 6
B46: VISITE
...

Sheet 07-07
H1: =COUNTIF(C8:C12,"<>") -> 2 | I1: TC
F2: =COUNTIFS(B18:B36,"<>",C18:C36,"VH") -> 0 | G2: VH | H2: =COUNTA(C18:C33)-F2 -> 12 | I2: TC | J2: =COUNTIF(E18:E32,"VIDE") -> 0
A3: FICHE DE MOUVEMENT
B5: RECEPTION | G5: 46210
A7: N° | B7: N° CRN | C7: Date R | D7: N° Conteneur | E7: N° Scellé | F7: Vol
A8: 1 | B8: 0105ICS0004
A9: 2 | C9: 46209 | D9: UETU615930 /5 | E9: 896531 | F9: 40
A10: 3 | B10: 00105ICS0019
A11: 4 | C11: 46209 | D11: CAAU999511 /6 | E11: FJ25951745 | F11: 40
A12: 5
A13: 8
B15: SORTIE
A17: N° | B17: Date S | C17: IMM | D17: N° Conteneur | E17: N° Scellé | F17: Vol
A18: 1 | B18: 46210 | C18: 00037-517-31 | D18: DFSU723583 /9 | E18: 3878 | F18: 40
A19: 2 | B19: 46210 | C19: 00378-516-31 | D19: ECMU809626 /4 | E19: 3884 | F19: 45
A20: 3 | B20: 46210 | C20: 00394-517-31 | D20: TCKU 997977 /6 | E20: 3886 | F20: 45
A21: 4 | B21: 46210 | C21: 00425-505-31 | D21: TDRU461667 /6 | E21: 3889 | F21: 45
A22: 5 | B22: 46210 | C22: 00554-514-31 | D22: TDRU909110 /6 | E22: 3888 | F22: 45
A23: 6 | B23: 46210 | C23: 00133-515-31 | D23: TEMU565544 /9 | E23: CV | F23: 20
A24: 7 | B24: 46210 | C24: 00701-509-31 | D24: TEMU068508 /1 | E24: CV | F24: 20
A25: 8 | B25: 46210 | C25: 00385-516-31 | D25: TEMU252340 /7 | E25: CV | F25: 20
A26: 9 | B26: 46210 | C26: 00385-516-31 | D26: CRSU145321 /9 | E26: CV | F26: 20
A27: 10 | B27: 46210 | C27: 00067-515-31 | D27: SEGU323855 /8 | E27: CV | F27: 20
A28: 11 | B28: 46210 | C28: 00108-515-31 | D28: CMAU011596 /1 | E28: CV | F28: 20
A29: 12 | B29: 46210 | C29: 0068-515-31 | D29: CMAU230176 /0 | E29: CV | F29: 20
A30: 13
A31: 14
B34: VISITE
A36: N° | B36: Date V | C36: N° Conteneur | D36: AN° Scellé | E36: NO° Scellé | F36: Vol
A37: 1 | B37: 46210 | C37: CAJU522157 /1 | D37: 656800 | E37: 3890 | F37: 40
A38: 2 | B38: 46210 | C38: SEKU444471 /1 | D38: ML-CN6393039 | E38: 3927 | F38: 40
A39: 3 | B39: 46210 | C39: MRSU536454 /7 | D39: CN6337817 | E39: 3898 | F39: 40
A40: 4 | B40: 46210 | C40: MRSU687466 /9 | D40: CN3899476 | E40: 3925 | F40: 40

Sheet 08-07
H1: =COUNTIF(C8:C32,"<>") -> 16 | I1: TC
F2: =COUNTIFS(B38:B41,"<>",C38:C41,"VH") -> 0 | G2: VH | H2: =COUNTA(C38:C44)-F2 -> 7 | I2: TC | J2: =COUNTIF(E38:E43,"VIDE") -> 0
A3: FICHE DE MOUVEMENT
B5: RECEPTION | G5: 46211
A7: N° | B7: N° CRN | C7: Date R | D7: N° Conteneur | E7: N° Scellé | F7: Vol | G7: NN° Scellé
A8: 1 | B8: 00111ICS0059 | C8: 8072026 | D8: TEMU359990 /0 | E8: FX46306546 | F8: 20
A9: 2 | B9: 00174ICS0069 | C9: 8072026 | D9: CMAU368040 /0 | E9: A039495 | F9: 40
A10: 3 | C10: 8072026 | D10: ECMU493389 /2 | E10: A039482 | F10: 40 | G10: 0347
A11: 4 | C11: 8072026 | D11: ECMU523561 /7 | E11: A039416 | F11: 40 | G11: 0348
A12: 5 | C12: 8072026 | D12: SEGU440329 /8 | E12: A039403 | F12: 40 | G12: 0541
A13: 6 | C13: 8072026 | D13: SEKU609420 /6 | E13: A039368 | F13: 40
A14: 7 | C14: 8072026 | D14: TCNU351908 /4 | E14: A039485 | F14: 40
A15: 8 | C15: 8072026 | D15: TGBU415699 /6 | E15: A039450 | F15: 40
A16: 9 | D16: TLLU462879 /5 | E16: A039458 | F16: 40 | G16: 0350
A17: 10 | C17: 8072026 | D17: TXGU442737 /0 | E17: A039391 | F17: 40
A18: 11 | C18: 8072026 | D18: TXGU846880 /3 | E18: A039482 | F18: 40
A19: 12 | B19: 00174ICS0282 | D19: ECMU815877 /2 | E19: J0211640 | F19: 45
A20: 13 | B20: 00111ICS0004 | C20: 8072026 | D20: WTLU500362 /4 | E20: W17501 | F20: 40
A21: 14 | B21: 00174ICS0248 | C21: 8072026 | D21: CMAU229574 /9 | E21: M7399417 | F21: 20
A22: 15 | C22: 8072026 | D22: CMAU238193 /4 | E22: M7399419 | F22: 20
A23: 16 | C23: 8072026 | D23: ECMU294199 /1 | E23: M7399384 | F23: 20
A24: 17 | C24: 8072026 | D24: ECMU295618 /4 | E24: M7399466 | F24: 20
A25: 18 | D25: TEMU032969 /2 | E25: M7349446 | F25: 20
A26: 19 | B26: 00174ICS0150 | C26: 8072026 | D26: ECMU741339 /0 | E26: L7840355 | F26: 40
A27: 20
A28: 21
A29: 22
A30: 23
A31: 24
A32: 25
A33: 26
B35: SORTIE
A37: N° | B37: Date S | C37: IMM | D37: N° Conteneur | E37: N° Scellé | F37: Vol
A38: 1 | B38: 8072026 | C38: 00701-509-31 | D38: ECMU282389 /6 | E38: CV | F38: 20
A39: 2 | B39: 8072026 | C39: 00133-515-31 | D39: MAGU252239 /6 | E39: CV | F39: 20
A40: 3 | B40: 8072026 | C40: 00108-516-31 | D40: SEGU186240 /0 | E40: CV | F40: 20
A41: 4 | B41: 8072026 | C41: 00067-515-31 | D41: SEGU189868 /1 | E41: CV | F41: 20
A42: 5 | B42: 8072026 | C42: 00303-517-31 | D42: MRSU426341 /8 | E42: 3883 | F42: 40
A43: 6 | B43: 46211 | C43: 00037-517-31 | D43: FCIU409524 /1 | E43: 3880 | F43: 20
A44: 7 | B44: 46211 | C44: 00037-517-31 | D44: SEKU444471 /1 | E44: 3927 | F44: 40
...

Sheet 09-07
H1: =COUNTIF(C7:C9,"<>") -> 2 | I1: TC
F2: =COUNTIFS(B14:B60,"<>",C14:C60,"VH") -> 13 | G2: VH | H2: =COUNTA(C14:C60)-F2 -> 27 | I2: TC | J2: =COUNTIF(E14:E19,"VIDE") -> 0
A3: FICHE DE MOUVEMENT
B4: RECEPTION | G4: 46212
A6: N° | B6: N° CRN | C6: Date R | D6: N° Conteneur | E6: N° Scellé | F6: Vol
A7: 1 | B7: 00174ICS0069 | C7: 9072026 | D7: TLLU462879 /5 | E7: A039458 | F7: 40
A8: 2 | B8: 00174ICS0248 | C8: 9072026 | D8: TEMU032969 /2 | E8: M7349446 | F8: 20
B11: SORTIE
A13: N° | B13: Date S | C13: IMM | D13: N° Conteneur | E13: N° Scellé | F13: Vol
A14: 1 | B14: 9072026 | C14: 00020-507-31 | D14: MRSU536454 /7 | E14: 3898 | F14: 40
A15: 2 | B15: 9072026 | C15: 00217-507-31 | D15: MRSU687466 /9 | E15: 3925 | F15: 40
A16: 3 | B16: 9072026 | C16: VH | D16: LB37-TX608457 | E16: GELLY COOL
A17: 4 | B17: 9072026 | C17: VH | D17: LB37-TX608458 | E17: GELLY COOL
A18: 5 | B18: 9072026 | C18: VH | D18: LB37-TX608459 | E18: GELLY COOL
A19: 6 | B19: 9072026 | C19: VH | D19: LB37-TX608460 | E19: GELLY COOL
A20: 8 | B20: 9072026 | C20: 5000002-513-48 | D20: APHU738346 /4 | E20: M8314725 | F20: 40
A21: 9 | B21: 9072026 | C21: 00361-515-31 | D21: APZU445159 /4 | E21: M8098826 | F21: 40
A22: 10 | B22: 9072026 | C22: 500002-513-48 | D22: BMOU643970 /7 | E22: M8803623 | F22: 40
A23: 11 | B23: 9072026 | C23: 500067-515-31 | D23: CAAU835917 /2 | E23: M8801870 | F23: 40
A24: 12 | B24: 9072026 | C24: 16513-509-14 | D24: CMAU360083 /1 | E24: M8803451 | F24: 40
A25: 13 | B25: 9072026 | C25: 04157-584-16 | D25: CMAU596402 /5 | E25: M8096127 | F25: 40
A26: 14 | B26: 9072026 | C26: 000574-511-05 | D26: CMAU654785 /4 | E26: M8096110 | F26: 40
A27: 15 | B27: 9072026 | C27: 006898-590-02 | D27: FSCU714396 /0 | E27: M8096204 | F27: 40
A28: 16 | B28: 9072026 | C28: 000989-588-16 | D28: GAOU683187 /2 | E28: M8096072 | F28: 40
A29: 17 | B29: 9072026 | C29: 01076-595-45 | D29: GESU657116 /7 | E29: M8801715 | F29: 40
A30: 18 | B30: 9072026 | C30: 000574-511-05 | D30: HPCU472969 /7 | E30: M8096170 | F30: 40
A31: 19 | B31: 9072026 | C31: 01076-595-45 | D31: SEGU400772 /2 | E31: M8096063 | F31: 40
... A41: 29 | B41: 9072026 | C41: 04157-584-16 | D41: TRHU826611 /0 | E41: M8801885 | F41: 40
A42: 30 | B42: 9072026 | C42: 000009-500-31 | D42: MSBU531205 /1 | E42: 3882 | F42: 40
A43: 31 | B43: 9072026 | C43: 0002007-587-31 | D43: MSBU642243 /0 | E43: 3881 | F43: 40
A44: 32 | B44: 9072026 | C44: 00724-509-31 | D44: CAJU522157 /1 | E44: 3890 | F44: 40
G49: 1/2
A52: 26 | B52: 9072026 | C52: VH | D52: LFV2-S6541882 | E52: AUDI
A53: 27 | B53: 9072026 | C53: VH | D53: LSVF-SN010691 | E53: POLO
A54: 28 | B54: 9072026 | C54: VH | D54: LSVF-SN010762 | E54: POLO
A55: 29 | B55: 9072026 | C55: VH | D55: LSVF-SN010696 | E55: POLO
A56: 30 | B56: 9072026 | C56: VH | D56: LSVF-SN010694 | E56: POLO
A57: 26 | B57: 9072026 | C57: VH | D57: LMGH-T3258192 | E57: GAC GS3
A58: 27 | B58: 9072026 | C58: VH | D58: LMGH-T3258195 | E58: GAC GS3
A59: 28 | B59: 9072026 | C59: VH | D59: LMGH-T3246827 | E59: GAC GS3
...

Sheet 12-07
H1: =COUNTIF(C8:C26,"<>") -> 15 | I1: TC
F2: =COUNTIFS(B32:B35,"<>",C32:C35,"VH") -> 0 | G2: VH | H2: =COUNTA(C32:C38)-F2 -> 1 | I2: TC | J2: =COUNTIF(E32:E37,"VIDE") -> 0
A3: FICHE DE MOUVEMENT
B5: RECEPTION | G5: 46215
A7: N° | B7: N° CRN | C7: Date R | D7: N° Conteneur | E7: N° Scellé | F7: Vol
A8: 1 | B8: 00115ICS0048 | C8: 12072026 | D8: MSNU928137 /8 | E8: FX47338080 | F8: 40
A9: 2 | B9: 00115ICS0149 | C9: 12072026 | D9: MSDU836912 /4 | E9: FX44278929 | F9: 40
A10: 3 | B10: 00115ICS0153 | C10: 12072026 | D10: MSBU107698 /1 | E10: FX44302566 | F10: 20
A11: 4 | C11: 12072026 | D11: MSBU404538 /8 | E11: FX44302565 | F11: 40
A12: 5 | B12: 0059ICS0029 | C12: 12072026 | D12: MRKU581407 /1 | E12: CN3706927 | F12: 40
A13: 6 | B13: 0059ICS0061 | C13: 12072026 | D13: MRSU455055 /2 | E13: CN6250820 | F13: 40
A14: 7 | B14: 0059ICS0070 | C14: 12072026 | D14: TCNU857774 /0 | E14: CN6455438 | F14: 40
A15: 8 | B15: 0059ICS0078 | C15: 12072026 | D15: MRSU675991 /6 | E15: CN3708599 | F15: 40
A16: 9 | B16: 00115ICS0015 | C16: 12072026 | D16: MSNU759748 /0 | E16: FX47336575 | F16: 40
A17: 10 | B17: 00115ICS0006 | C17: 12072026 | D17: MSMU424809 /6 | E17: FX39706315 | F17: 40
A18: 11 | C18: 12072026 | D18: MSMU765166 /0 | E18: FX39706314 | F18: 40
A19: 12 | C19: 12072026 | D19: MSNU605673 /2 | E19: FX39706313 | F19: 40
A20: 13 | C20: 12072026 | D20: MSNU891808 /1 | E20: FX39706312 | F20: 40
A21: 14 | C21: 12072026 | D21: TXGU534053 /1 | E21: FX39706316 | F21: 40
A22: 15 | C22: 12072026 | D22: UETU757271 /4 | E22: FX39706311 | F22: 40
A23: 16
A24: 23
A25: 24
A26: 25
A27: 26
B29: SORTIE
A31: N° | B31: Date S | C31: IMM | D31: N° Conteneur | E31: N° Scellé | F31: Vol
A32: 1 | B32: 12072026 | C32: 00054-511-31 | D32: MRSU345476 /5 | E32: 3930 | F32: 40
A33: 2
A34: 3
A35: 4
A36: 5
A37: 6
A38: 7
B41: VISITE
A43: N° | B43: Date V | C43: N° Conteneur | D43: AN° Scellé | E43: NO° Scellé | F43: Vol
A44: 1 | B44: 12072026 | C44: MSMU709369 /7 | D44: 3924 | E44: 3923
A45: 2

Sheet 13-07
H1: =COUNTIF(C8:C20,"<>") -> 2 | I1: TC
F2: =COUNTIFS(B25:B26,"<>",C25:C26,"VH") -> 0 | G2: VH | H2: =COUNTA(C25:C28)-F2 -> 3 | I2: TC | J2: =COUNTIF(E25:E27,"VIDE") -> 0
A3: FICHE DE MOUVEMENT
B5: RECEPTION | G5: 46216
A7: N° | B7: N° CRN | C7: Date R | D7: N° Conteneur | E7: N° Scellé | F7: Vol
A8: 1 | B8: 00547ICS0002 | D8: CMAU5808193 | E8: K1730386 | F8: 40
A9: 2 | B9: 00116ICS0011 | C9: 13072026 | D9: SEKU6752544 | E9: 917966 | F9: 40
A10: 3 | C10: 13072026 | D10: TCLU1710788 | E10: 917967 | F10: 20
A11: 4 | B11: 00174ICS0282 | D11: ECMU815877 /2 | E11: J0211640 | F11: 45
A12: 5
A13: 6
A14: 7
A15: 8
A16: 9
A17: 10
A18: 11
A19: 12
A20: 13
B22: SORTIE
A24: N° | B24: Date S | C24: IMM | D24: N° Conteneur | E24: N° Scellé | F24: Vol
A25: 1 | B25: 13072026 | C25: 00132-525-31 | D25: MRSU723163 /0 | E25: ML-CN2470218 | F25: 40
A26: 2 | B26: 13072026 | C26: 00066-520-31 | D26: TGHU692335 /8 | E26: ML-CN3206831 | F26: 40
A27: 6 | B27: 46216 | C27: 00371-511-31 | D27: FFAU186123 /8 | E27: 3862 | F27: 40
A28: 7
B31: VISITE
A33: N° | B33: Date V | C33: N° Conteneur | D33: AN° Scellé | E33: NO° Scellé | F33: Vol
A34: 1 | B34: 13072026 | C34: FFAU519002 /0 | D34: 2103860 | E34: 3938 | F34: 40
A35: 2 | B35: 13072026 | C35: MRKU660441 /8 | D35: ML-CN4852480 | E35: 3935 | F35: 20
A36: 3 | B36: 13072026 | C36: MRKU719113 /4 | D36: ML-CN4852491 | E36: 3939 | F36: 20
A37: 4 | B37: 13072026 | C37: MRKU355546 /0 | D37: ML-CN7825456 | E37: 3940 | F37: 40
A38: 5 | B38: 13072026 | C38: MRSU331904 /5 | D38: ML-CN7825573 | E38: 3933 | F38: 40
A39: 6 | B39: 13072026 | C39: MSMU840453 /5 | D39: LG00460566 | E39: 3937 | F39: 40
A40: 7 | B40: 13072026 | C40: MSNU803360 /7 | D40: LG00460591 | E40: 3936 | F40: 40
A41: 8 | B41: 13072026 | C41: TCLU798602 /7 | D41: ML-CN4068822 | E41: 3934 | F41: 40
A42: 9 | B42: 13072026 | C42: MRKU503755 /7 | D42: ML-CN6216316 | E42: 3932 | F42: 40

Sheet 14-07
H1: =COUNTIF(C8:C15,"<>") -> 0 | I1: TC
F2: =COUNTIFS(B20:B21,"<>",C20:C21,"VH") -> 0 | G2: VH | H2: =COUNTA(C20:C23)-F2 -> 2 | I2: TC | J2: =COUNTIF(E20:E22,"VIDE") -> 0
A3: FICHE DE MOUVEMENT
B5: RECEPTION | G5: 46217
A7: N° | B7: N° CRN | C7: Date R | D7: N° Conteneur | E7: N° Scellé | F7: Vol
A8: 1
A9: 2
A10: 3
A11: 9
A12: 10
A13: 11
A14: 12
A15: 13
B17: SORTIE
A19: N° | B19: Date S | C19: IMM | D19: N° Conteneur | E19: N° Scellé | F19: Vol
A20: 1 | B20: 14072026 | C20: 00014-594-31 | D20: MSMU709369 /7 | E20: 3923 | F20: 40
A21: 2 | B21: 14072026 | C21: 00066-520-31 | D21: MSNU770695 /6 | E21: 3921 | F21: 40
A22: 6
A23: 7
B26: VISITE
A28: N° | B28: Date V | C28: N° Conteneur | D28: AN° Scellé | E28: NO° Scellé | F28: Vol
A29: 1 | B29: 14072026 | C29: INKU631078 /8 | D29: CN4478941 | E29: 3922
A30: 2
A31: 3
A32: 4
A33: 5
A34: 6
A35: 7
A36: 8
A37: 9

Sheet 15-07
H1: =COUNTIF(C8:C15,"<>") -> 0 | I1: TC
F2: =COUNTIFS(B20:B32,"<>",C20:C32,"VH") -> 11 | G2: VH | H2: =COUNTA(C20:C32)-F2 -> 2 | I2: TC | J2: =COUNTIF(E20:E32,"VIDE") -> 0
A3: FICHE DE MOUVEMENT
B5: RECEPTION | G5: 46218
A7: N° | B7: N° CRN | C7: Date R | D7: N° Conteneur | E7: N° Scellé | F7: Vol
A8: 1
A9: 2
A10: 3
A11: 9
A12: 10
A13: 11
A14: 12
A15: 13
B17: SORTIE
A19: N° | B19: Date S | C19: IMM | D19: N° Conteneur | E19: N° Scellé | F19: Vol
A20: 1 | B20: 15072026 | C20: 00375-595-31 | D20: MRKU355546 /0 | E20: 3940 | F20: 40
A21: 2 | B21: 15072026 | C21: 00327-510-31 | D21: MRSU331904 /5 | E21: 3933 | F21: 40
A22: 3 | B22: 15072026 | C22: VH | D22: LLV2-T0220609 | E22: LIVAN
A23: 4 | B23: 15072026 | C23: VH | D23: LLV2-T0222940 | E23: LIVAN
A24: 5 | B24: 15072026 | C24: VH | D24: LB37-TX609455 | E24: GELLY BOY
A25: 6 | B25: 15072026 | C25: VH | D25: LLV2-T0220629 | E25: LIVAN
A26: 7 | B26: 15072026 | C26: VH | D26: LLV2-T0215832 | E26: LIVAN
A27: 8 | B27: 15072026 | C27: VH | D27: LLV2-T0215818 | E27: LIVAN
A28: 9 | B28: 15072026 | C28: VH | D28: LLV2-T0216534 | E28: LIVAN
A29: 10 | B29: 15072026 | C29: VH | D29: LLV2-T0215836 | E29: LIVAN
A30: 11 | B30: 15072026 | C30: VH | D30: LMG-T3241545 | E30: GAC GS3
A31: 12 | B31: 15072026 | C31: VH | D31: LMG-T3241501 | E31: GAC GS3
A32: 13 | B32: 15072026 | C32: VH | D32: LMG-T3241474 | E32: GAC GS3
A33: 14
B36: VISITE
A38: N° | B38: Date V | C38: N° Conteneur | D38: AN° Scellé | E38: NO° Scellé | F38: Vol
A39: 1
A40: 2
A41: 3
A42: 4
A43: 5

Sheet 16-07
H1: =COUNTIF(C8:C19,"<>") -> 8 | I1: TC
F2: =COUNTIFS(B24:B24,"<>",C24:C24,"VH") -> 0 | G2: VH | H2: =COUNTA(C24:C26)-F2 -> 3 | I2: TC | J2: =COUNTIF(E24:E25,"VIDE") -> 0
A3: FICHE DE MOUVEMENT
B5: RECEPTION | G5: 46219
A7: N° | B7: N° CRN | C7: Date R | D7: N° Conteneur | E7: N° Scellé | F7: Vol
A8: 1 | B8: 00117ICS0081 | C8: 16072026 | D8: MSBU403770 /0 | E8: KN099983 | F8: 40
A9: 2 | C9: 16072026 | D9: MSDU407254 /4 | E9: DD0032 | F9: 40
A10: 3 | C10: 16072026 | D10: TGHU509513 /5 | E10: DD0031 | F10: 40
A11: 4 | B11: 00117ICS0036 | C11: 16072026 | D11: BMOU595766 /1 | E11: FX44664381 | F11: 40
A12: 5 | B12: 00117ICS0005 | C12: 16072026 | D12: TEXU157949 /4 | E12: B2122952 | F12: 40
A13: 6 | C13: 16072026 | D13: TEXU158364 /2 | E13: B2122970 | F13: 40
A14: 7 | C14: 16072026 | D14: TRLU694920 /2 | E14: 083381 | F14: 40
A15: 8 | B15: 00117ICS0087 | C15: 16072026 | D15: MSDU459782 /5 | E15: 3739580 | F15: 40
A16: 9
A17: 10
A18: 11
A19: 12
B21: SORTIE
A23: N° | B23: Date S | C23: IMM | D23: N° Conteneur | E23: N° Scellé | F23: Vol
A24: 1 | B24: 16072026 | C24: 005400-594-28 | D24: TCLU798602 /7 | E24: 3934 | F24: 40
A25: 2 | B25: 16062026 | C25: 00358-511-31 | D25: INKU631078 /8 | E25: 3922 | F25: 40
A26: 3 | B26: 16062026 | C26: 00375-595-31 | D26: MRKU503755 /7 | E26: 3932 | F26: 40
B29: VISITE
A31: N° | B31: Date V | C31: N° Conteneur | D31: AN° Scellé | E31: NO° Scellé | F31: Vol
A32: 1 | B32: 16062026 | C32: MSDU836912 /4 | D32: FX44278929 | E32: 3971 | F32: 40
A33: 2 | B33: 16062026 | C33: WTLU500362 /4 | D33: W17501 | E33: 3973 | F33: 40
A34: 3 | B34: 16062026 | C34: WTLU500362 /4 | D34: 3973 | E34: 3974 | F34: 40
A35: 4 | B35: 16062026 | C35: MRSU542442 /0 | D35: ML-CN6393033 | E35: 3972 | F35: 40
A36: 5 | B36: 16062026 | C36: CAAU865822 /9 | D36: FJ25951744 | E36: 3852 | F36: 40
A37: 6 | B37: 16062026 | C37: FFAU293917 /7 | D37: FJ25951753 | E37: 3985 | F37: 40
A38: 7 | B38: 16062026 | C38: MEDU938762 /9 | D38: FJ25951747 | E38: 3853 | F38: 40
A39: 8 | B39: 16062026 | C39: MSBU701831 /8 | D39: FJ25951748 | E39: 3857 | F39: 40
A40: 9 | B40: 16062026 | C40: MSDU582015 /2 | D40: FJ25951749 | E40: 3980 | F40: 40
A41: 10 | B41: 16062026 | C41: MSDU643345 /6 | D41: FJ25951750 | E41: 3855 | F41: 40
A42: 11 | B42: 16062026 | C42: MSDU879402 /0 | D42: FJ25951751 | E42: 3977 | F42: 40
A43: 12 | B43: 16062026 | C43: MSMU449068 /5 | D43: FJ25951752 | E43: 3975 | F43: 40
A44: 13 | B44: 16062026 | C44: MSMU526705 /9 | D44: FJ25951746 | E44: 3859 | F44: 40
A45: 14 | B45: 16062026 | C45: MSMU828891 /8 | D45: FJ25951754 | E45: 3856 | F45: 40
A46: 15 | B46: 16062026 | C46: MSNU549749 /8 | D46: 260056887 | E46: 3854 | F46: 40
A47: 16 | B47: 16062026 | C47: MSNU806904 /5 | D47: FJ25951755 | E47: 3860 | F47: 40
...

Sheet 19-07
H1: =COUNTIF(C8:C14,"<>") -> 0 | I1: TC
F2: =COUNTIFS(B19:B19,"<>",C19:C19,"VH") -> 0 | G2: VH | H2: =COUNTA(C19:C23)-F2 -> 5 | I2: TC | J2: =COUNTIF(E19:E20,"VIDE") -> 0
A3: FICHE DE MOUVEMENT
B5: RECEPTION | G5: 46222
A7: N° | B7: N° CRN | C7: Date R | D7: N° Conteneur | E7: N° Scellé | F7: Vol
A8: 1
A9: 2
A10: 3
A11: 4
A12: 5
A13: 6
A14: 7
B16: SORTIE
A18: N° | B18: Date S | C18: IMM | D18: N° Conteneur | E18: N° Scellé | F18: Vol
A19: 1 | B19: 19072026 | C19: 0009-509-31 | D19: MSDU836912 /4 | E19: 3971 | F19: 40
A20: 2 | B20: 19072026 | C20: 01402-590-31 | D20: MRKU660441 /8 | E20: 3935 | F20: 20
A21: 3 | B21: 19072026 | C21: 02055-584-31 | D21: MRKU719113 /4 | E21: 3939 | F21: 20
A22: 4 | B22: 19072026 | C22: 00470-514-31 | D22: MSMU840453 /5 | E22: 3937 | F22: 40
A23: 5 | B23: 19072026 | C23: 00109-513-13 | D23: MSNU803360 /7 | E23: 3936 | F23: 40
B26: VISITE
A28: N° | B28: Date V | C28: N° Conteneur | D28: AN° Scellé | E28: NO° Scellé | F28: Vol
A29: 1 | B29: 19072026 | C29: TCLU197143 /6 | D29: 306831 | E29: 3945 | F29: 20
A30: 2 | B30: 19072026 | C30: CAAU865822 /9 | D30: 3852 | E30: 3981 | F30: 40
A31: 3 | B31: 19072026 | C31: FFAU293917 /7 | D31: 3985 | E31: 3950 | F31: 40
A32: 4 | B32: 19072026 | C32: MEDU938762 /9 | D32: 3853 | E32: 3982 | F32: 40
A33: 5 | B33: 19072026 | C33: MSBU701831 /8 | D33: 3857 | E33: 3949 | F33: 40
A34: 6 | B34: 19072026 | C34: MSDU582015 /2 | D34: 3980 | E34: 3984 | F34: 40
A35: 7 | B35: 19072026 | C35: MSDU643345 /6 | D35: 3855 | E35: 3947 | F35: 40
A36: 8 | B36: 19072026 | C36: MSDU879402 /0 | D36: 3977 | E36: 3987 | F36: 40
A37: 9 | B37: 19072026 | C37: MSMU449068 /5 | D37: 3975 | E37: 3988 | F37: 40
A38: 10 | B38: 19072026 | C38: MSMU526705 /9 | D38: 3859 | E38: 3986 | F38: 40
A39: 11 | B39: 19072026 | C39: MSMU828891 /8 | D39: 3856 | E39: 3948 | F39: 40
A40: 12 | B40: 19072026 | C40: MSNU549749 /8 | D40: 3854 | E40: 3946 | F40: 40
... A44: 16 | B44: 19072026 | C44: CAAU999511 /6 | D44: 3979 | E44: 3983 | F44: 40

Sheet 20-07
H1: =COUNTIF(C8:C19,"<>") -> 10 | I1: TC
F2: =COUNTIFS(B24:B24,"<>",C24:C24,"VH") -> 0 | G2: VH | H2: =COUNTA(C24:C26)-F2 -> 0 | I2: TC | J2: =COUNTIF(E24:E25,"VIDE") -> 0
A3: FICHE DE MOUVEMENT
B5: RECEPTION | G5: 46223
A7: N° | B7: N° CRN | C7: Date R | D7: N° Conteneur | E7: N° Scellé | F7: Vol
A8: 1 | B8: 0566ICS0027 | C8: 20072026 | D8: TRLU948903 /4 | E8: L7956894
A9: 2 | B9: 0186ICS0126 | C9: 20072026 | D9: TGCU546808 /2 | E9: L7859611
A10: 3 | B10: 0186ICS0028 | C10: 20072026 | D10: CMAU225333 /7 | E10: 00168
A11: 4 | C11: 20072026 | D11: CMAU265891 /0 | E11: 00183
A12: 5 | C12: 20072026 | D12: CMAU326542 /0 | E12: 001577
A13: 6 | C13: 20072026 | D13: SEKU160562 /2 | E13: 00163
A14: 7 | C14: 20072026 | D14: TCLU734251 /2 | E14: 005369
A15: 8 | C15: 20072026 | D15: TLLU313561 /8 | E15: 005370
A16: 9 | B16: 0566ICS0050 | C16: 20072026 | D16: APZU482800 /8 | E16: AG565794
A17: 10 | C17: 20072026 | D17: TEMU319824 /0 | E17: AG565795
A18: 11
A19: 12
B21: SORTIE
A23: N° | B23: Date S | C23: IMM | D23: N° Conteneur | E23: N° Scellé | F23: Vol
A24: 1 | B24: 19072026
A25: 2 | B25: 19072026
A26: 3 | B26: 19072026
B32: VISITE
A34: N° | B34: Date V | C34: N° Conteneur | D34: AN° Scellé | E34: NO° Scellé | F34: Vol
A35: 1
A36: 2
A37: 3

Sheet 21-07
H1: =COUNTIF(C8:C12,"<>") -> 0 | I1: TC
F2: =COUNTIFS(B17:B27,"<>",C17:C27,"VH") -> 5 | G2: VH | H2: =COUNTA(C17:C29)-F2 -> 5 | I2: TC | J2: =COUNTIF(E17:E18,"VIDE") -> 0
A3: FICHE DE MOUVEMENT
B5: RECEPTION | G5: 46224
A7: N° | B7: N° CRN | C7: Date R | D7: N° Conteneur | E7: N° Scellé | F7: Vol
B14: SORTIE
A16: N° | B16: Date S | C16: IMM | D16: N° Conteneur | E16: N° Scellé | F16: Vol
A17: 1 | B17: 21072026 | C17: VH | D17: LSV-SN012280 | E17: SKODA
A18: 2 | B18: 21072026 | C18: VH | D18: LSV-SN012164 | E18: SKODA
A19: 3 | B19: 21072026 | C19: VH | D19: LSV-SN216847 | E19: LAVIDA
A20: 4 | B20: 21072026 | C20: VH | D20: LSV-SN213121 | E20: LAVIDA
A21: 5 | B21: 21072026 | C21: VH | D21: LSV-SN213111 | E21: LAVIDA
A22: 6 | B22: 21072026 | C22: 00181-509-22 | D22: CAXU965894 /8 | E22: 3913
A23: 7 | B23: 21072026 | C23: 00067-515-31 | D23: TCNU933139 /2 | E23: 3916
A24: 8 | B24: 21072026 | C24: 00121-517-31 | D24: TRLU667802 /9 | E24: 3896
A25: 9 | B25: 21072026 | C25: 00122-517-31 | D25: TCLU512420 /8 | E25: 3842
A26: 10 | B26: 21072026 | C26: 00118-517-31 | D26: MEDU801919 /7 | E26: 3841
B30: VISITE
A32: N° | B32: Date V | C32: N° Conteneur | D32: AN° Scellé | E32: NO° Scellé | F32: Vol
A33: 1 | B33: 21072026 | C33: HASU148037 /0 | D33: PP1345143 | E33: 3931
A34: 2 | B34: 21072026 | C34: TCLU717677 /2 | D34: PP1345144 | E34: 3851
A35: 3 | B35: 21072026 | C35: ECMU266869 /7 | D35: 35596 | E35: 3943
A36: 4 | B36: 21072026 | C36: MRSU455055 /2 | D36: CN6250820 | E36: 3942
A37: 5 | B37: 21072026 | C37: CAIU763401 /4 | D37: FJ27816923 | E37: 3944
A38: 6 | B38: 21072027 | C38: KOCU444962 /9 | D38: 25H1283786 | E38: 3961
A39: 7
A42: 3

Sheet 22-07
H1: =COUNTIF(C7:C16,"<>") -> 9 | I1: TC
F2: =COUNTIFS(B21:B45,"<>",C21:C45,"VH") -> 0 | G2: VH | H2: =COUNTA(C21:C45)-CF2 -> 25 | I2: TC | J2: =COUNTIF(E21:E27,"VIDE") -> 0
A3: FICHE DE MOUVEMENT
B4: RECEPTION | G4: 46225
A6: N° | B6: N° CRN | C6: Date R | D6: N° Conteneur | E6: N° Scellé | F6: Vol | G6: Depotage
A7: 1 | B7: 00577ICS0004 | C7: 22072026 | D7: TCNU364693 /6 | E7: 0361693 | F7: 40
A8: 2 | B8: 00577ICS0025 | C8: 22072026 | D8: CMAU285639 /3 | E8: B84818 | F8: 20
A9: 3 | B9: 0064ICS0007 | C9: 22072026 | D9: MRKU753756 /7 | E9: ML-IN2987561 | F9: 20
A10: 4 | C10: 22072026 | D10: MRKU772089 /7 | E10: ML-IN2987565 | F10: 20
A11: 5 | C11: 22072026 | D11: MRKU905919 /5 | E11: ML-IN2987562 | F11: 20
A12: 6 | C12: 22072026 | D12: MRSU023326 /7 | E12: ML-IN2987566 | F12: 20
A13: 7 | C13: 22072026 | D13: MSKU704341 /6 | E13: ML-IN2987564 | F13: 20
A14: 8 | C14: 22072026 | D14: MSKU730475 /7 | E14: ML-IN2987563 | F14: 20
A15: 9 | B15: 00519ICS0018/1 | C15: 22072026 | D15: TCLU768371 /4 | E15: 25H1461534 | F15: GROUPAGE | G15: 46232
B18: SORTIE
A20: N° | B20: Date S | C20: IMM | D20: N° Conteneur | E20: N° Scellé | F20: Vol
A21: 1 | B21: 22072026 | C21: 00297-511-31 | D21: CAAU865822 /9 | E21: 3981
A22: 2 | B22: 22072026 | C22: 09889-512-27 | D22: FFAU293917 /7 | E22: 3950
A23: 3 | B23: 22072026 | C23: 00440-504-31 | D23: MEDU938762 /9 | E23: 3982
A24: 4 | B24: 22072026 | C24: 000740-589-35 | D24: MSBU701831 /8 | E24: 3949
A25: 5 | B25: 22072026 | C25: 23089-511-27 | D25: MSDU582015 /2 | E25: 3984
A26: 6 | B26: 22072026 | C26: 01450-590-31 | D26: MSDU643345 /6 | E26: 3947
A27: 7 | B27: 22072026 | C27: 08601-503-27 | D27: MSDU879402 /0 | E27: 3987
A28: 8 | B28: 22072026 | C28: 00073-506-27 | D28: MSMU449068 /5 | E28: 3988
A29: 9 | B29: 22072026 | C29: 00123-51631 | D29: MSMU526705 /9 | E29: 3986
A30: 10 | B30: 22072026 | C30: 00332-513-31 | D30: MSMU828891 /8 | E30: 3948
A31: 11 | B31: 22072026 | C31: 02053-587-31 | D31: MSNU549749 /8 | E31: 3946
A32: 12 | B32: 22072026 | C32: 00001-512-20 | D32: MSNU806904 /5 | E32: 3985
... A35: 15 | B35: 22072026 | C35: 20469-511-27 | D35: CAAU999511 /6 | E35: 3983
A36: 16 | B36: 22072026 | C36: 00125-524-31 | D36: ARKU839971 /0 | E36: B2463499
A37: 17 | B37: 22072026 | C37: 00125-523-31 | D37: TCNU349512 /5 | E37: B2463310
A38: 18 | B38: 22072026 | C38: 00523-592-31 | D38: WTLU500362 /4 | E38: 3973
A39: 19 | B39: 22072026 | C39: 00235-509-31 | D39: MRSU542442 /0 | E39: 3972
A40: 20 | B40: 22072026 | C40: 00161-509-31 | D40: FFAU519002 /0 | E40: 3938
A41: 20 | B41: 22072026 | C41: 00108-515-31 | D41: GCNU464217 /2 | E41: 3846
A42: 20 | B42: 22072026 | C42: 00701-509-31 | D42: MOTU040902 /0 | E42: 3845
A43: 20 | B43: 22072026 | C43: 00385-516-31 | D43: TCKU965219 /2 | E43: 3994
A44: 20 | B44: 22072026 | C44: 00025-509-22 | D44: GAXU903878 /3 | E44: 3845
A45: 20 | B45: 22072026 | C45: 00133-515-31 | D45: CHSU809431 /6 | E45: 3843
B47: VISITE
...

Sheet 23-07
H1: =COUNTIF(C8:C17,"<>") -> 0 | I1: TC
F2: =COUNTIFS(B22:B28,"<>",C22:C28,"VH") -> 0 | G2: VH | H2: =COUNTA(C22:C28)-CE2 -> 6 | I2: TC | J2: =COUNTIF(E22:E27,"VIDE") -> 0
A3: FICHE DE MOUVEMENT
B5: RECEPTION | G5: 46226
A7: N° | B7: N° CRN | C7: Date R | D7: N° Conteneur | E7: N° Scellé | F7: Vol
B19: SORTIE
A21: N° | B21: Date S | C21: IMM | D21: N° Conteneur | E21: N° Scellé | F21: Vol
A22: 1 | B22: 23072026 | C22: 00068-515-31 | D22: FSCU987305 /7 | E22: 3899
A23: 2 | B23: 23072026 | C23: 00121-517-31 | D23: GLDU063183 /5 | E23: 3850
A24: 3 | B24: 23072026 | C24: 00118-517-31 | D24: HPCU401944 /2 | E24: 3893
A25: 4 | B25: 23072026 | C25: 00067-515-31 | D25: SVWU501049 /0 | E25: 3847
A26: 5 | B26: 23072026 | C26: 00115-517-31 | D26: SVWU644047 /5 | E26: 3849
A27: 6 | B27: 23072026 | C27: 00122-517-31 | D27: TCNU901453 /0 | E27: 3848
B31: VISITE
A33: N° | B33: Date V | C33: N° Conteneur | D33: AN° Scellé | E33: NO° Scellé | F33: Vol
A34: 1
A35: 2

Sheet 26-07
H1: =COUNTIF(C8:C17,"<>") -> 10 | I1: TC
F2: =COUNTIFS(B22:B35,"<>",C22:C35,"VH") -> 0 | G2: VH | H2: =COUNTA(C22:C40)-CE2 -> 19 | I2: TC | J2: =COUNTIF(E22:E40,"VIDE") -> 0
A3: FICHE DE MOUVEMENT
B5: RECEPTION | G5: 46229
A7: N° | B7: N° CRN | C7: Date R | D7: N° Conteneur | E7: N° Scellé | F7: Vol
A8: 1 | B8: 00125ICS0131 | C8: 26072026 | D8: MEDU957207 /8 | E8: FX47781171 | F8: 45
A9: 2 | B9: 00125ICS0300 | C9: 26072026 | D9: FTAU146218 /0 | E9: FX46512162 | F9: 20
A10: 3 | C10: 26072026 | D10: HPCU235131 /3 | E10: FX46521110 | F10: 20
A11: 4 | C11: 26072026 | D11: MEDU594756 /1 | E11: FX46518036 | F11: 20
A12: 5 | C12: 26072026 | D12: MSDU122196 /3 | E12: FX46518049 | F12: 20
A13: 6 | C13: 26072026 | D13: MSDU159519 /8 | E13: FX46516991 | F13: 20
A14: 7 | C14: 26072026 | D14: MSDU220311 /5 | E14: FX46519272 | F14: 20
A15: 8 | C15: 26072026 | D15: MSMU363561 /3 | E15: FX46519273 | F15: 20
A16: 9 | C16: 26072026 | D16: TCKU294842 /8 | E16: FX46512125 | F16: 20
A17: 10 | B17: 00125ICS0153 | C17: 26072026 | D17: CAAU584007 /6 | E17: FJ27554603 | F17: 40
B19: SORTIE
A21: N° | B21: Date S | C21: IMM | D21: N° Conteneur | E21: N° Scellé | F21: Vol
A22: 1 | B22: 26072026 | C22: 00133-515-31 | D22: GATU852786 /7 | E22: 3897
A23: 2 | B23: 26072026 | C23: 00068-515-31 | D23: INKU228395 /6 | E23: 3918
A24: 3 | B24: 26072026 | C24: 000363-515-31 | D24: NYKU553573 /0 | E24: 3891
A25: 4 | B25: 26072026 | C25: 00118-517-31 | D25: TCKU965488 /9 | E25: 3895
A26: 5 | B26: 26072026 | C26: 000108-515-31 | D26: TGHU609641 /3 | E26: 3919
A27: 6 | B27: 26072026 | C27: 000701-509-31 | D27: TGHU623035 /3 | E27: 3914
A28: 7 | B28: 26072026 | C28: 00364-515-31 | D28: TGHU845285 /3 | E28: 3920
A29: 8 | B29: 26072026 | C29: 00115-517-31 | D29: TGHU857904 /6 | E29: 3917
A30: 9 | B30: 26072026 | C30: 00121-517-31 | D30: TOPU503238 /9 | E30: 3911
A31: 10 | B31: 26072026 | C31: 00122-517-31 | D31: YMLU816005 /6 | E31: 3915
A32: 11 | B32: 26072026 | C32: 00332-516-31 | D32: MSMU424809 /6 | E32: FX39706315
A33: 12 | B33: 26072026 | C33: 00125-523-31 | D33: MSMU765166 /0 | E33: FX39706314
A34: 13 | B34: 26072026 | C34: 00140-525-31 | D34: MSNU605673 /2 | E34: FX39706313
A35: 14 | B35: 26072026 | C35: 5000016-525-31 | D35: MSNU891808 /1 | E35: FX39706312
A36: 15 | B36: 26072026 | C36: 00296-515-31 | D36: TXGU534053 /1 | E36: FX39706316
A37: 16 | B37: 26072026 | C37: 5000017-525-31 | D37: UETU757271 /4 | E37: FX39706311
A38: 17 | B38: 26072026 | C38: 00124-523-31 | D38: TEXU157949 /4 | E38: B2122952
A39: 18 | B39: 26072026 | C39: 500018-525-31 | D39: TEXU158364 /2 | E39: B2122970
A40: 19 | B40: 26072026 | C40: 00141-525-31 | D40: TRLU694920 /2 | E40: 083381
B42: VISITE
A44: N° | B44: Date V | C44: N° Conteneur | D44: AN° Scellé | E44: NO° Scellé | F44: Vol
A45: 1 | B45: 26072026 | C45: FFAU372824 /5 | E45: 3962
A46: 2 | B46: 26072026 | C46: MSBU733842 /0 | E46: 3941

Sheet 27-07
H1: =COUNTIF(C8:C11,"<>") -> 0 | I1: TC
F2: =COUNTIFS(B16:B22,"<>",C16:C22,"VH") -> 0 | G2: VH | H2: =COUNTA(C16:C22)-CE2 -> 4 | I2: TC | J2: =COUNTIF(E16:E21,"VIDE") -> 0
A3: FICHE DE MOUVEMENT
B5: RECEPTION | G5: 46230
A7: N° | B7: N° CRN | C7: Date R | D7: N° Conteneur | E7: N° Scellé | F7: Vol
B13: SORTIE
A15: N° | B15: Date S | C15: IMM | D15: N° Conteneur | E15: N° Scellé | F15: Vol
A16: 1 | B16: 27072026 | C16: 00385-516-31 | D16: HLXU624229 /8 | E16: 3892
A17: 2 | B17: 27072026 | C17: 00096-511-31 | D17: CAIU763401 /4 | E17: 3944
A18: 3 | B18: 27072026 | C18: 00258-518-31 | D18: FFAU372824 /5 | E18: 3962
A19: 4 | B19: 27072026 | C19: 00109-513-13 | D19: MSBU733842 /0 | E19: 3941
A20: 5
A21: 6
B25: VISITE
A27: N° | B27: Date V | C27: N° Conteneur | D27: AN° Scellé | E27: NO° Scellé | F27: Vol
A28: 1 | B28: 27072026 | C28: MSBU803451 /9 | D28: 896535 | E28: 3963 | F28: 40
A29: 2 | B29: 27072026 | C29: MSNU733963 /4 | D29: 896540 | E29: 3964 | F29: 40
A30: 3 | B30: 27072026 | C30: TRHU593641 /3 | D30: 896539 | E30: 3966 | F30: 40
A31: 4 | B31: 27072026 | C31: UETU615930 /5 | D31: 896531 | E31: 3965 | F31: 40
A32: 5 | B32: 27072026 | C32: MSBU107698 /1 | D32: FX44302566 | E32: 3969 | F32: 20
A33: 6 | B33: 27072026 | C33: MSBU404538 /8 | D33: FX44302565 | E33: 3970 | F33: 40
A34: 7 | B34: 27072026 | C34: SEKU675254 /4 | D34: 917966 | E34: 3968 | F34: 40
A35: 8 | B35: 27072026 | C35: TCLU171078 /8 | D35: 917967 | E35: 3967 | F35: 20
A36: 9 | B36: 27072026 | C36: KOCU444962 /9 | D36: 3961 | E36: 3991 | F36: 40

Sheet 28-07
H1: =COUNTIF(C8:C11,"<>") -> 0 | I1: TC
F2: =COUNTIFS(B16:B21,"<>",C16:C21,"VH") -> 0 | G2: VH | H2: =COUNTA(C16:C21)-CE2 -> 0 | I2: TC | J2: =COUNTIF(E16:E21,"VIDE") -> 0
A3: FICHE DE MOUVEMENT
B5: RECEPTION | G5: 46231
A7: N° | B7: N° CRN | C7: Date R | D7: N° Conteneur | E7: N° Scellé | F7: Vol
B13: SORTIE
A15: N° | B15: Date S | C15: IMM | D15: N° Conteneur | E15: N° Scellé | F15: Vol
A16: 1
A17: 2
A18: 3
A19: 4
A20: 5
A21: 6
B24: VISITE
A26: N° | B26: Date V | C26: N° Conteneur | D26: AN° Scellé | E26: NO° Scellé | F26: Vol
A27: 1 | B27: 27072026 | C27: MRKU581407 /1 | D27: CN3706927 | E27: 3995 | F27: 40
A28: 2 | B28: 27072026 | C28: TCNU262349 /5 | D28: ML-CN3700782 | E28: 3993 | F28: 40
A29: 3 | B29: 27072026 | C29: CAAU623335 /4 | D29: M5176915 | E29: 3992 | F29: 40
A30: 4 | B30: 27072026 | C30: MEDU744845 /3 | D30: FX46376357 | E30: 3994 | F30: 40
A31: 5 | B31: 27072026 | C31: CMAU285639 /3 | D31: B84818 | E31: 3996 | F31: 20
A32: 6
A33: 7
A34: 8
A35: 9

Sheet 29-07
H1: =COUNTIF(C8:C20,"<>") -> 11 | I1: TC
F2: =COUNTIFS(B25:B30,"<>",C25:C30,"VH") -> 0 | G2: VH | H2: =COUNTA(C25:C30)-CE2 -> 6 | I2: TC | J2: =COUNTIF(E25:E30,"VIDE") -> 0
A3: FICHE DE MOUVEMENT
B5: RECEPTION | G5: 46232
A7: N° | B7: N° CRN | C7: Date R | D7: N° Conteneur | E7: N° Scellé | F7: Vol
A8: 1 | B8: 00603ICS0002 | C8: 29072026 | D8: ECMU512820 /2 | E8: R9410054 | F8: 40
A9: 2 | B9: 00603ICS0039 | C9: 29072026 | D9: TLLU468314 /9 | E9: M8351211 | F9: 40
A10: 3 | B10: 00132ICS0057 | D10: MSNU191236 /9 | E10: SK360769 | F10: 20
A11: 4 | B11: 00132ICS0031 | C11: 29072026 | D11: MSMU834901 /6 | E11: B2506030 | F11: 40
A12: 5 | B12: 00138ICS0012 | C12: 29072026 | D12: TRHU875969 /3 | E12: 549293 | F12: 40
A13: 6 | B13: 00603ICS0136 | C13: 29072026 | D13: BMOU661509 /3 | E13: M9771663 | F13: 40
A14: 7 | B14: 00603ICS0150 | C14: 29072026 | D14: CMAU897134 /7 | E14: M8704971 | F14: 40
A15: 8 | C15: 29072026 | D15: TLLU480817 /0 | E15: M8693387 | F15: 40
A16: 9 | B16: 00132ICS0019 | C16: 29072026 | D16: CAIU873171 /8 | E16: 1072594 | F16: 40
A17: 10 | C17: 29072026 | D17: MEDU733219 /1 | E17: 1072595 | F17: 40
A18: 11 | B18: 00132ICS0079 | C18: 29072026 | D18: TTNU102467 /0 | E18: 3602841 | F18: 20
A19: 12 | B19: 00603ICS0107 | C19: 29072026 | D19: TRHU194179 /3 | E19: 4250703 | F19: 20
B22: SORTIE
A24: N° | B24: Date S | C24: IMM | D24: N° Conteneur | E24: N° Scellé | F24: Vol
A25: 1 | B25: 29072026 | C25: 00416-512-31 | D25: MSMU408797 /8 | E25: 3928 | F25: 40
A26: 2 | B26: 29072026 | C26: 02175-588-31 | D26: SEKU675254 /4 | E26: 3968 | F26: 40
A27: 3 | B27: 29072026 | C27: 00758-589-31 | D27: TCLU171078 /8 | E27: 3967 | F27: 40
A28: 4 | B28: 29072026 | C28: 00161-510-31 | D28: MRSU455055 /2 | E28: 3942 | F28: 40
A29: 5 | B29: 29072026 | C29: 00375-588-31 | D29: MRSU675991 /6 | E29: CV | F29: 45
A30: 6 | B30: 29072026 | C30: 00325-510-31 | D30: MSMU922668 /0 | E30: 3800 | F30: 40
B33: VISITE
A35: N° | B35: Date V | C35: N° Conteneur | D35: AN° Scellé | E35: NO° Scellé | F35: Vol
A36: 1 | B36: 29072026 | C36: MSDU459782 /5 | D36: 3739580 | E36: 3998 | F36: 40
A37: 2 | B37: 29072026 | C37: TCLU768371 /4 | D37: 25H1461534 | E37: 3997 | F37: 20
A38: 3 | B38: 29072026 | C38: APZU440364 /1 | D38: 1098005 | E38: 3912 | F38: 40
A39: 4 | B39: 29072026 | C39: WFHU415155 /5 | D39: 1098006 | E39: 4000 | F39: 40
A40: 5 | B40: 29072026 | C40: MSBU679925 /8 | D40: FJ27192156 | E40: 3951 | F40: 40
A41: 6
A42: 7

Sheet 30-07
H1: =COUNTIF(C8:C10,"<>") -> 1 | I1: TC
F2: =COUNTIFS(B15:B20,"<>",C15:C20,"VH") -> 0 | G2: VH | H2: =COUNTA(C15:C24)-CE2 -> 10 | I2: TC | J2: =COUNTIF(E15:E20,"VIDE") -> 0
A3: FICHE DE MOUVEMENT
B5: RECEPTION | G5: 46233
A7: N° | B7: N° CRN | C7: Date R | D7: N° Conteneur | E7: N° Scellé | F7: Vol
A8: 3 | B8: 00132ICS0057 | C8: 30072026 | D8: MSNU191236 /9 | E8: SK360769 | F8: 20
B12: SORTIE
A14: N° | B14: Date S | C14: IMM | D14: N° Conteneur | E14: N° Scellé | F14: Vol
A15: 1 | B15: 30072026 | C15: 000332-513-31 | D15: MSBU803451 /9 | E15: 3963 | F15: 40
A16: 2 | B16: 30072026 | C16: 000256-512-31 | D16: MSNU733963 /4 | E16: 3964 | F16: 40
A17: 3 | B17: 30072026 | C17: 00044-595-31 | D17: TRHU593641 /3 | E17: 3966 | F17: 40
A18: 4 | B18: 30072026 | C18: 000740-589-35 | D18: UETU615930 /5 | E18: 3965 | F18: 40
A19: 5 | B19: 30072026 | C19: 500018-525-31 | D19: CAXU980455 /4 | E19: LB0263348 | F19: 40
A20: 6 | B20: 30072026 | C20: 00362-516-31 | D20: HPCU401947 /9 | E20: LB0263349 | F20: 40
A21: 7 | B21: 30072026 | C21: 000117-523-31 | D21: LCGU800158 /0 | E21: LB0263393 | F21: 40
A22: 8 | B22: 30072026 | C22: 00316-519-31 | D22: CMAU285639 /3 | E22: 3996 | F22: 20
A23: 9 | B23: 30072026 | C23: 00224-596-31 | D23: ECMU741339 /0 | E23: CV | F23: 40
A24: 10 | B24: 30072026 | C24: 00359-515-31 | D24: CAAU623335 /4 | E24: 3992 | F24: 40
B28: VISITE
A30: N° | B30: Date V | C30: N° Conteneur | D30: AN° Scellé | E30: NO° Scellé | F30: Vol
A31: 1 | B31: 30072026 | C31: CMAU368040 /0 | D31: A039495 | E31: 3901 | F31: 40
A32: 2 | B32: 30072026 | C32: ECMU493389 /2 | D32: A039482 | E32: 3902 | F32: 40
A33: 3 | B33: 30072026 | C33: ECMU523561 /7 | D33: A039416 | E33: 3903 | F33: 40
A34: 4 | B34: 30072026 | C34: SEGU440329 /8 | D34: A039403 | E34: 3904 | F34: 40
A35: 5 | B35: 30072026 | C35: SEKU609420 /6 | D35: A039368 | E35: 3905 | F35: 40
A36: 6 | B36: 30072026 | C36: TCNU351908 /4 | D36: A039485 | E36: 3906 | F36: 40
A37: 7 | B37: 30072026 | C37: TGBU415699 /6 | D37: A039450 | E37: 3907 | F37: 40
A38: 8 | B38: 30072026 | C38: TLLU462879 /5 | D38: A039458 | E38: 3908 | F38: 40
A39: 9 | B39: 30072026 | C39: TXGU442737 /0 | D39: A039391 | E39: 3909 | F39: 40
A40: 10 | B40: 30072026 | C40: TXGU846880 /3 | D40: A039482 | E40: 3910 | F40: 40
A41: 11 | B41: 30072026 | C41: APZU482800 /8 | D41: AG565794 | E41: 3952 | F41: 40
A42: 12 | B42: 30072026 | C42: TEMU319824 /0 | D42: AG565795 | E42: 3954 | F42: 40
A43: 13 | B43: 30072026 | C43: SUDU866062 /7 | D43: CN6284860 | E43: 3999 | F43: 40
